Workbook

Sheet Rekap
A1: Neraca Fisik dan Moneter
A2: Sumber Daya Hutan Indonesia
A4: Perincian | B4: 1990 | C4: 1991 | D4: 1992 | E4: 1993 | F4: 1994 | G4: 1995 | H4: 1996 | I4: 1997 | J4: 1998 | K4: 1999 | L4: 2000 | M4: 2001 | N4: 2002 | O4: 2003 | P4: 2004 | Q4: 2005 | R4: 2006 | S4: 2007 | T4: 2008 | U4: 2009 | V4: 2010 | W4: 2011 | X4: 2012 | Y4: 2013 | Z4: 2014 | AA4: 2015 | AB4: 2016 | AC4: 2017 | AD4: 2018 | AE4: 2019 | AF4: 2020 | AG4: 2021 | AH4: 2022 | AI4: 2023 | AJ4: 2024
A6: I. Neraca Fisik (000 M3)
A8: 1. Persediaan awal | B8: 8644424.6 | C8: 8642977.8 | D8: 8640252.7 | E8: 8619007.2 | F8: 8589076 | G8: 8569181.9 | H8: 8548707.6 | I8: 8535616.3 | J8: 8478434.2 | K8: 8418105.1 | L8: 8345375.3 | M8: 8282251.8 | N8: 8191498.9 | O8: 8068944.1 | P8: 7925081.7 | Q8: 7753143.4 | R8: 7515887.8 | S8: 7232311.7 | T8: ='Rekap Transpose'!B3 -> 6941231.3 | U8: =T15 -> 6742572.6 | V8: =U15 -> 6520095.2 | W8: =V15 -> 6271702.1 | X8: =W15 -> 5998732.7 | Y8: =X15 -> 5670001.2 | Z8: =Y15 -> 5606293.1 | AA8: =Z15 -> 5423882.4 | AB8: =AA15 -> 4827604.5 | ... AJ8: =AI15 -> 3525379.2
A9: 2. Penambahan | T9: =SUM(T10:T11) -> 58307.641 | U9: =SUM(U10:U11) -> 57410.291 | V9: =SUM(V10:V11) -> 55446.93 | W9: =SUM(W10:W11) -> 56343.743 | X9: =SUM(X10:X11) -> 59091.588 | Y9: =SUM(Y10:Y11) -> 69758.026 | Z9: =SUM(Z10:Z11) -> 57882.121 | AA9: =SUM(AA10:AA11) -> 62487.426 | ... AJ9: =SUM(AJ10:AJ11) -> 54326.981
A10: Pertumbuhan | B10: 41982.9 | C10: 43088.146 | D10: 44320.021 | E10: 45618.543 | F10: 47003.13 | G10: 48595.51 | H10: 54426.46 | I10: 55032.56 | J10: 56761.47 | K10: 60762.237 | L10: 57911.827 | M10: 57766.75 | N10: 57353.36 | O10: 54498.139 | P10: 58396.028 | Q10: 53842.346 | R10: 52132.491 | S10: 51780.126 | T10: =INDIRECT("'Rekap Transpose'!C"&T32) -> 50170.417 | U10: =INDIRECT("'Rekap Transpose'!C"&U32) -> 51261.334 | V10: =INDIRECT("'Rekap Transpose'!C"&V32) -> 50866.651 | W10: =INDIRECT("'Rekap Transpose'!C"&W32) -> 51448.15 | X10: =INDIRECT("'Rekap Transpose'!C"&X32) -> 52887.133 | Y10: =INDIRECT("'Rekap Transpose'!C"&Y32) -> 58651.075 | Z10: =INDIRECT("'Rekap Transpose'!C"&Z32) -> 46687.165 | AA10: =INDIRECT("'Rekap Transpose'!C"&AA32) -> 46799.571 | ... AJ10: =INDIRECT("'Rekap Transpose'!C"&AJ32) -> 46599.387
A11: Penanaman | B11: 790 | C11: 1152.3 | D11: 1131.2 | E11: 1601.8 | F11: 1367.46 | G11: 1674.2 | H11: 2654.03 | I11: 2266.59 | J11: 1681.49 | K11: 1439.1997 | L11: 3484.9848 | M11: 1406.3486 | N11: 5053.5777 | O11: 5971.3368 | P11: 5670.3173 | Q11: 5580.4384 | R11: 7265.3378 | S11: 6472.9681 | T11: =INDIRECT("'Rekap Transpose'!D"&T32) -> 8137.2246 | U11: =INDIRECT("'Rekap Transpose'!D"&U32) -> 6148.9569 | V11: =INDIRECT("'Rekap Transpose'!D"&V32) -> 4580.2793 | W11: =INDIRECT("'Rekap Transpose'!D"&W32) -> 4895.5931 | X11: =INDIRECT("'Rekap Transpose'!D"&X32) -> 6204.4544 | Y11: =INDIRECT("'Rekap Transpose'!D"&Y32) -> 11106.951 | Z11: =INDIRECT("'Rekap Transpose'!D"&Z32) -> 11194.956 | AA11: =INDIRECT("'Rekap Transpose'!D"&AA32) -> 15687.856 | ... AJ11: =INDIRECT("'Rekap Transpose'!D"&AJ32) -> 7727.594
A12: 3.Pengurangan | T12: =SUM(T13:T14) -> 256966.35 | U12: =SUM(U13:U14) -> 279887.69 | V12: =SUM(V13:V14) -> 303840.08 | W12: =SUM(W13:W14) -> 329313.13 | X12: =SUM(X13:X14) -> 387823.01 | Y12: =SUM(Y13:Y14) -> 133466.13 | Z12: =SUM(Z13:Z14) -> 240292.85 | AA12: =SUM(AA13:AA14) -> 658765.38 | ... AJ12: =SUM(AJ13:AJ14) -> 151611.78
A13: Kerusakan | B13: 15665.8 | C13: 18825.8 | D13: 38007.4 | E13: 47597.7 | F13: 38563.3 | G13: 41077.1 | H13: 40078.83 | I13: 80250.98 | J13: 93239.38 | K13: 109191.15 | L13: 98258.31 | M13: 123847.92 | N13: 159469.84 | O13: 180187.66 | P13: 211464.92 | Q13: 253701.29 | R13: 304112.89 | S13: 293287.97 | T13: =INDIRECT("'Rekap Transpose'!E"&T32) -> 207360.8 | U13: =INDIRECT("'Rekap Transpose'!E"&U32) -> 227997.26 | V13: =INDIRECT("'Rekap Transpose'!E"&V32) -> 249399.69 | W13: =INDIRECT("'Rekap Transpose'!E"&W32) -> 278383.26 | X13: =INDIRECT("'Rekap Transpose'!E"&X32) -> 337879.87 | Y13: =INDIRECT("'Rekap Transpose'!E"&Y32) -> 92474.444 | Z13: =INDIRECT("'Rekap Transpose'!E"&Z32) -> 194261.6 | AA13: =INDIRECT("'Rekap Transpose'!E"&AA32) -> 613364.48 | ... AJ13: =INDIRECT("'Rekap Transpose'!E"&AJ32) -> 96304.46
A14: Penebangan | B14: 28553.9 | C14: 28139.7 | D14: 28689.4 | E14: 29553.8 | F14: 29701.4 | G14: 29666.9 | H14: 30092.97 | I14: 34230.235 | J14: 25532.743 | K14: 25740.012 | L14: 26262.063 | M14: 26078.075 | N14: 25491.862 | O14: 24144.223 | P14: 24539.787 | Q14: 42977.097 | R14: 38860.948 | S14: 56045.558 | T14: =INDIRECT("'Rekap Transpose'!F"&T32) -> 49605.554 | U14: =INDIRECT("'Rekap Transpose'!F"&U32) -> 51890.421 | V14: =INDIRECT("'Rekap Transpose'!F"&V32) -> 54440.397 | W14: =INDIRECT("'Rekap Transpose'!F"&W32) -> 50929.869 | X14: =INDIRECT("'Rekap Transpose'!F"&X32) -> 49943.141 | Y14: =INDIRECT("'Rekap Transpose'!F"&Y32) -> 40991.687 | Z14: =INDIRECT("'Rekap Transpose'!F"&Z32) -> 46031.25 | AA14: =INDIRECT("'Rekap Transpose'!F"&AA32) -> 45400.908 | ... AJ14: =INDIRECT("'Rekap Transpose'!F"&AJ32) -> 55307.319
A15: 4. Persediaan akhir | B15: 8642977.8 | C15: 8640252.7 | D15: 8619007.2 | E15: 8589076 | F15: 8569181.9 | G15: 8548707.6 | H15: 8535616.3 | I15: 8478434.2 | J15: 8418105.1 | K15: 8345375.3 | L15: 8282251.8 | M15: 8191498.9 | N15: 8068944.1 | O15: 7925081.7 | P15: 7753143.4 | Q15: 7515887.8 | R15: 7232311.7 | S15: 6941231.3 | T15: =T8+T9-T12 -> 6742572.6 | U15: =U8+U9-U12 -> 6520095.2 | V15: =V8+V9-V12 -> 6271702.1 | W15: =W8+W9-W12 -> 5998732.7 | X15: =X8+X9-X12 -> 5670001.2 | Y15: =Y8+Y9-Y12 -> 5606293.1 | Z15: =Z8+Z9-Z12 -> 5423882.4 | AA15: =AA8+AA9-AA12 -> 4827604.5 | ... AJ15: =AJ8+AJ9-AJ12 -> 3428094.4
U16: =U8-T15 -> 0 | V16: =V8-U15 -> 0 | W16: =W8-V15 -> 0 | X16: =X8-W15 -> 0 | Y16: =Y8-X15 -> 0 | Z16: =Z8-Y15 -> 0 | AA16: =AA8-Z15 -> 0 | AB16: =AB8-AA15 -> 0 | ... AJ16: =AJ8-AI15 -> 0
A18: III. Neraca Moneter
A19: (Miliar Rp)
A21: 1. Persediaan awal | B21: 74108.902 | C21: 83802.55 | D21: 97018.89 | E21: 92652.724 | F21: 104769.1 | G21: 128642.89 | H21: 138837.71 | I21: 149329.52 | J21: 160216.11 | K21: 197640.93 | L21: 244516.25 | M21: 255163.72 | N21: 245748.71 | O21: 251003.76 | P21: 261590.39 | Q21: 280224.95 | R21: 308313.84 | S21: 423393.61 | U21: ='Rekap Transpose'!B23 -> 6465702.8 | V21: =U29 -> 6835195.2 | W21: =V29 -> 4757481.7 | X21: =W29 -> 1381033.5 | Y21: =X29 -> 924382.72 | Z21: =Y29 -> 701661.76 | AA21: =Z29 -> 719985.09 | AB21: =AA29 -> 628834.11 | AC21: =AB29 -> 681499.89 | ... AJ21: =AI29 -> 1384227.4
A22: 2. Penambahan | U22: =SUM(U23:U24) -> 60348.218 | V22: =SUM(V23:V24) -> 33359.223 | W22: =SUM(W23:W24) -> 9696.0603 | X22: =SUM(X23:X24) -> 7068.9023 | Y22: =SUM(Y23:Y24) -> 5569.0193 | Z22: =SUM(Z23:Z24) -> 5639.768 | AA22: =SUM(AA23:AA24) -> 6211.529 | AB22: =SUM(AB23:AB24) -> 7110.7939 | ... AJ22: =SUM(AJ23:AJ24) -> 15703.442
A23: Pertumbuhan | B23: 689.56159 | C23: 686.14115 | D23: 654.21251 | E23: 1036.6145 | F23: 1466.4377 | G23: 1626.3811 | H23: 2001.1504 | I23: 2825.251 | J23: 3061.3912 | K23: 4046.3159 | L23: 4148.0219 | M23: 3363.0885 | N23: 3470.0661 | O23: 3412.1885 | P23: 3994.6146 | Q23: 3863.6905 | R23: 5493.5606 | S23: 6518.4084 | U23: =INDIRECT("'Rekap Transpose'!C"&U33) -> 53904.98 | V23: =INDIRECT("'Rekap Transpose'!C"&V33) -> 29763.587 | W23: =INDIRECT("'Rekap Transpose'!C"&W33) -> 8498.601 | X23: =INDIRECT("'Rekap Transpose'!C"&X33) -> 5979.9178 | Y23: =INDIRECT("'Rekap Transpose'!C"&Y33) -> 4064.8881 | Z23: =INDIRECT("'Rekap Transpose'!C"&Z33) -> 4013.4808 | AA23: =INDIRECT("'Rekap Transpose'!C"&AA33) -> 3927.0238 | AB23: =INDIRECT("'Rekap Transpose'!C"&AB33) -> 4254.0726 | ... AJ23: =INDIRECT("'Rekap Transpose'!C"&AJ33) -> 11987.894
A24: Penanaman | B24: 9.7480176 | C24: 14.128113 | D24: 12.869787 | E24: 21.547158 | F24: 23.634181 | G24: 30.60233 | H24: 45.795587 | I24: 44.783644 | J24: 41.357379 | K24: 53.677051 | L24: 116.11617 | M24: 53.491456 | N24: 156.99325 | O24: 189.63575 | P24: 195.59029 | Q24: 220.39693 | R24: 399.72037 | S24: 436.70366 | U24: =INDIRECT("'Rekap Transpose'!D"&U33) -> 6443.2381 | V24: =INDIRECT("'Rekap Transpose'!D"&V33) -> 3595.6356 | W24: =INDIRECT("'Rekap Transpose'!D"&W33) -> 1197.4593 | X24: =INDIRECT("'Rekap Transpose'!D"&X33) -> 1088.9846 | Y24: =INDIRECT("'Rekap Transpose'!D"&Y33) -> 1504.1311 | Z24: =INDIRECT("'Rekap Transpose'!D"&Z33) -> 1626.2872 | AA24: =INDIRECT("'Rekap Transpose'!D"&AA33) -> 2284.5052 | AB24: =INDIRECT("'Rekap Transpose'!D"&AB33) -> 2856.7213 | ... AJ24: =INDIRECT("'Rekap Transpose'!D"&AJ33) -> 3715.5482
A25: 3.Pengurangan | U25: =SUM(U26:U27) -> 293282.56 | V25: =SUM(V26:V27) -> 242436.18 | W25: =SUM(W26:W27) -> 80899.769 | X25: =SUM(X26:X27) -> 67797.272 | Y25: =SUM(Y26:Y27) -> 17825.468 | Z25: =SUM(Z26:Z27) -> 34762.947 | AA25: =SUM(AA26:AA27) -> 95890.196 | AB25: =SUM(AB26:AB27) -> 39606.994 | ... AJ25: =SUM(AJ26:AJ27) -> 72238.104
A26: Kerusakan | B26: 157.28271 | C26: 214.51114 | D26: 407.81127 | E26: 579.8117 | F26: 578.67353 | G26: 660.4917 | H26: 693.76421 | I26: 1386.6881 | J26: 2140.4004 | K26: 3061.1596 | L26: 2904.073 | M26: 3510.4357 | N26: 4595.9862 | O26: 5460.4588 | P26: 6918.4262 | Q26: 9443.8928 | R26: 15815.893 | S26: 17965.879 | U26: =INDIRECT("'Rekap Transpose'!E"&U33) -> 238894.12 | V26: =INDIRECT("'Rekap Transpose'!E"&V33) -> 199226.17 | W26: =INDIRECT("'Rekap Transpose'!E"&W33) -> 68481.629 | X26: =INDIRECT("'Rekap Transpose'!E"&X33) -> 59094.5 | Y26: =INDIRECT("'Rekap Transpose'!E"&Y33) -> 12341.657 | Z26: =INDIRECT("'Rekap Transpose'!E"&Z33) -> 28141.491 | AA26: =INDIRECT("'Rekap Transpose'!E"&AA33) -> 89344.514 | AB26: =INDIRECT("'Rekap Transpose'!E"&AB33) -> 32133.043 | ... AJ26: =INDIRECT("'Rekap Transpose'!E"&AJ33) -> 45904.98
A27: Penebangan | B27: 349.11397 | C27: 369.30281 | D27: 347.58733 | E27: 463.06348 | F27: 602.22903 | G27: 649.1225 | H27: 666.73428 | I27: 876.02304 | J27: 804.41131 | K27: 1023.0924 | L27: 1050.241 | M27: 899.14327 | N27: 916.83356 | O27: 839.95021 | P27: 951.20793 | Q27: 1683.74 | R27: 2231.8437 | S27: 3712.0011 | U27: =INDIRECT("'Rekap Transpose'!F"&U33) -> 54388.444 | V27: =INDIRECT("'Rekap Transpose'!F"&V33) -> 43210.017 | W27: =INDIRECT("'Rekap Transpose'!F"&W33) -> 12418.141 | X27: =INDIRECT("'Rekap Transpose'!F"&X33) -> 8702.7714 | Y27: =INDIRECT("'Rekap Transpose'!F"&Y33) -> 5483.811 | Z27: =INDIRECT("'Rekap Transpose'!F"&Z33) -> 6621.4561 | AA27: =INDIRECT("'Rekap Transpose'!F"&AA33) -> 6545.6817 | AB27: =INDIRECT("'Rekap Transpose'!F"&AB33) -> 7473.951 | ... AJ27: =INDIRECT("'Rekap Transpose'!F"&AJ33) -> 26333.124
A28: 4. Revaluasi | B28: 9500.7348 | C28: 13099.885 | D28: -4277.8497 | E28: 12101.093 | F28: 23564.616 | G28: 9847.4491 | H28: 9805.3696 | I28: 10279.262 | J28: 37266.886 | K28: 46859.577 | L28: 10337.648 | M28: -8422.0159 | N28: 7140.8153 | O28: 13285.217 | P28: 22313.988 | Q28: 35132.432 | R28: 127234.22 | S28: 75568.764 | U28: =INDIRECT("'Rekap Transpose'!G"&U33) -> 602426.75 | V28: =INDIRECT("'Rekap Transpose'!G"&V33) -> -1868636.5 | W28: =INDIRECT("'Rekap Transpose'!G"&W33) -> -3305244.6 | X28: =INDIRECT("'Rekap Transpose'!G"&X33) -> -395922.36 | Y28: =INDIRECT("'Rekap Transpose'!G"&Y33) -> -210464.51 | Z28: =INDIRECT("'Rekap Transpose'!G"&Z33) -> 47446.501 | AA28: =INDIRECT("'Rekap Transpose'!G"&AA33) -> -1472.309 | AB28: =INDIRECT("'Rekap Transpose'!G"&AB33) -> 85161.98 | ... AJ28: =INDIRECT("'Rekap Transpose'!G"&AJ33) -> -3776.6979
A29: 5. Persediaan akhir | B29: 83802.55 | C29: 97018.89 | D29: 92652.724 | E29: 104769.1 | F29: 128642.89 | G29: 138837.71 | H29: 149329.52 | I29: 160216.11 | J29: 197640.93 | K29: 244516.25 | L29: 255163.72 | M29: 245748.71 | N29: 251003.76 | O29: 261590.39 | P29: 280224.95 | Q29: 308313.84 | R29: 423393.61 | S29: 484239.6 | U29: =U21+U22-U25+U28 -> 6835195.2 | V29: =V21+V22-V25+V28 -> 4757481.7 | W29: =W21+W22-W25+W28 -> 1381033.5 | X29: =X21+X22-X25+X28 -> 924382.72 | Y29: =Y21+Y22-Y25+Y28 -> 701661.76 | Z29: =Z21+Z22-Z25+Z28 -> 719985.09 | AA29: =AA21+AA22-AA25+AA28 -> 628834.11 | AB29: =AB21+AB22-AB25+AB28 -> 681499.89 | ... AJ29: =AJ21+AJ22-AJ25+AJ28 -> 1323916.1
V30: =U29-V21 -> 0 | W30: =V29-W21 -> 0 | X30: =W29-X21 -> 0 | Y30: =X29-Y21 -> 0 | Z30: =Y29-Z21 -> 0 | AA30: =Z29-AA21 -> 0 | AB30: =AA29-AB21 -> 0 | AC30: =AB29-AC21 -> 0 | ... AJ30: =AI29-AJ21 -> 0
A32: nomor baris neraca fisik | T32: 3 | U32: =T32+1 -> 4 | V32: =U32+1 -> 5 | W32: =V32+1 -> 6 | X32: =W32+1 -> 7 | Y32: =X32+1 -> 8 | Z32: =Y32+1 -> 9 | AA32: =Z32+1 -> 10 | AB32: =AA32+1 -> 11 | ... AJ32: =AI32+1 -> 19
A33: nomor baris neraca moneter | U33: 23 | V33: =U33+1 -> 24 | W33: =V33+1 -> 25 | X33: =W33+1 -> 26 | Y33: =X33+1 -> 27 | Z33: =Y33+1 -> 28 | AA33: =Z33+1 -> 29 | AB33: =AA33+1 -> 30 | AC33: =AB33+1 -> 31 | ... AJ33: =AI33+1 -> 38

Sheet Rekap JJ
A1: Neraca Fisik dan Moneter
A2: Sumber Daya Hutan Jati Jawa
A4: Perincian | B4: 2008 | C4: 2009 | D4: 2010 | E4: 2011 | F4: 2012 | G4: 2013 | H4: 2014 | I4: 2015 | J4: 2016 | K4: 2017 | L4: 2018 | M4: 2019 | N4: 2020 | O4: 2021 | P4: 2022 | Q4: 2023 | R4: 2024
A6: I. Neraca Fisik (000 M3)
A8: 1. Persediaan awal | B8: ='Jati Jawa'!B4 -> 87707.889 | C8: =B15 -> 91665.246 | D8: =C15 -> 95691.987 | E8: =D15 -> 99600.194 | F8: =E15 -> 102983.4 | G8: =F15 -> 104859.17 | H8: =G15 -> 108505.1 | I8: =H15 -> 111792.49 | J8: =I15 -> 114986.68 | ... R8: =Q15 -> 143946.66
A9: 2. Penambahan | B9: =SUM(B10:B11) -> 4764.3122 | C9: =SUM(C10:C11) -> 4775.1077 | D9: =SUM(D10:D11) -> 4799.06 | E9: =SUM(E10:E11) -> 4833.5027 | F9: =SUM(F10:F11) -> 4852.1833 | G9: =SUM(G10:G11) -> 5475.6953 | H9: =SUM(H10:H11) -> 4788.2139 | I9: =SUM(I10:I11) -> 4815.2779 | ... R9: =SUM(R10:R11) -> 5110.829
A10: Pertumbuhan | B10: =INDIRECT("'Jati Jawa'!C"&B32) -> 4732.2962 | C10: =INDIRECT("'Jati Jawa'!C"&C32) -> 4755.9577 | D10: =INDIRECT("'Jati Jawa'!C"&D32) -> 4779.736 | E10: =INDIRECT("'Jati Jawa'!C"&E32) -> 4803.6347 | F10: =INDIRECT("'Jati Jawa'!C"&F32) -> 4827.6543 | G10: =INDIRECT("'Jati Jawa'!C"&G32) -> 5459.4625 | H10: =INDIRECT("'Jati Jawa'!C"&H32) -> 4764.8739 | I10: =INDIRECT("'Jati Jawa'!C"&I32) -> 4794.9495 | ... R10: =INDIRECT("'Jati Jawa'!C"&R32) -> 5096.753
A11: Penanaman | B11: =INDIRECT("'Jati Jawa'!D"&B32) -> 32.016 | C11: =INDIRECT("'Jati Jawa'!D"&C32) -> 19.15 | D11: =INDIRECT("'Jati Jawa'!D"&D32) -> 19.324 | E11: =INDIRECT("'Jati Jawa'!D"&E32) -> 29.868 | F11: =INDIRECT("'Jati Jawa'!D"&F32) -> 24.529 | G11: =INDIRECT("'Jati Jawa'!D"&G32) -> 16.23275 | H11: =INDIRECT("'Jati Jawa'!D"&H32) -> 23.34 | I11: =INDIRECT("'Jati Jawa'!D"&I32) -> 20.32837 | ... R11: =INDIRECT("'Jati Jawa'!D"&R32) -> 14.076
A12: 3.Pengurangan | B12: =SUM(B13:B14) -> 806.95483 | C12: =SUM(C13:C14) -> 748.36735 | D12: =SUM(D13:D14) -> 890.85249 | E12: =SUM(E13:E14) -> 1450.2983 | F12: =SUM(F13:F14) -> 2976.4148 | G12: =SUM(G13:G14) -> 1829.7577 | H12: =SUM(H13:H14) -> 1500.8289 | I12: =SUM(I13:I14) -> 1621.0865 | ... R12: =SUM(R13:R14) -> 1082.2608
A13: Kerusakan | B13: =INDIRECT("'Jati Jawa'!E"&B32) -> 329.24483 | C13: =INDIRECT("'Jati Jawa'!E"&C32) -> 293.16735 | D13: =INDIRECT("'Jati Jawa'!E"&D32) -> 440.82049 | E13: =INDIRECT("'Jati Jawa'!E"&E32) -> 1014.8983 | F13: =INDIRECT("'Jati Jawa'!E"&F32) -> 2572.9828 | G13: =INDIRECT("'Jati Jawa'!E"&G32) -> 1398.2411 | H13: =INDIRECT("'Jati Jawa'!E"&H32) -> 1044.8336 | I13: =INDIRECT("'Jati Jawa'!E"&I32) -> 1228.4299 | ... R13: =INDIRECT("'Jati Jawa'!E"&R32) -> 686.75276
A14: Penebangan | B14: =INDIRECT("'Jati Jawa'!F"&B32) -> 477.71 | C14: =INDIRECT("'Jati Jawa'!F"&C32) -> 455.2 | D14: =INDIRECT("'Jati Jawa'!F"&D32) -> 450.032 | E14: =INDIRECT("'Jati Jawa'!F"&E32) -> 435.4 | F14: =INDIRECT("'Jati Jawa'!F"&F32) -> 403.432 | G14: =INDIRECT("'Jati Jawa'!F"&G32) -> 431.5166 | H14: =INDIRECT("'Jati Jawa'!F"&H32) -> 455.99528 | I14: =INDIRECT("'Jati Jawa'!F"&I32) -> 392.65651 | ... R14: =INDIRECT("'Jati Jawa'!F"&R32) -> 395.508
A15: 4. Persediaan akhir | B15: =B8+B9-B12 -> 91665.246 | C15: =C8+C9-C12 -> 95691.987 | D15: =D8+D9-D12 -> 99600.194 | E15: =E8+E9-E12 -> 102983.4 | F15: =F8+F9-F12 -> 104859.17 | G15: =G8+G9-G12 -> 108505.1 | H15: =H8+H9-H12 -> 111792.49 | I15: =I8+I9-I12 -> 114986.68 | ... R15: =R8+R9-R12 -> 147975.23
C16: =C15-INDIRECT("'Jati Jawa'!G"&C32) -> 0 | D16: =D15-INDIRECT("'Jati Jawa'!G"&D32) -> 0 | E16: =E15-INDIRECT("'Jati Jawa'!G"&E32) -> 0 | F16: =F15-INDIRECT("'Jati Jawa'!G"&F32) -> 0 | G16: =G15-INDIRECT("'Jati Jawa'!G"&G32) -> 0 | H16: =H15-INDIRECT("'Jati Jawa'!G"&H32) -> 0 | I16: =I15-INDIRECT("'Jati Jawa'!G"&I32) -> 0 | J16: =J15-INDIRECT("'Jati Jawa'!G"&J32) -> 0 | ... R16: =R15-INDIRECT("'Jati Jawa'!G"&R32) -> 0
A18: III. Neraca Moneter
A19: (Miliar Rp)
A21: 1. Persediaan awal | C21: ='Jati Jawa'!B47 -> 92293.685 | D21: =C29 -> 104925.04 | E21: =D29 -> 61836.339 | F21: =E29 -> 12389.188 | G21: =F29 -> 7737.4453 | H21: =G29 -> 8404.6549 | I21: =H29 -> 8707.7924 | J21: =I29 -> 7463.7389 | K21: =J29 -> 5461.6171 | ... R21: =Q29 -> 14758.997
A22: 2. Penambahan | C22: =SUM(C23:C24) -> 5235.8445 | D22: =SUM(D23:D24) -> 2979.4751 | E22: =SUM(E23:E24) -> 581.48375 | F22: =SUM(F23:F24) -> 358.0374 | G22: =SUM(G23:G24) -> 424.13976 | H22: =SUM(H23:H24) -> 372.96578 | I22: =SUM(I23:I24) -> 312.55774 | J22: =SUM(J23:J24) -> 200.56968 | ... R22: =SUM(R23:R24) -> 435.17464
A23: Pertumbuhan | C23: =INDIRECT("'Jati Jawa'!C"&C33) -> 5214.8467 | D23: =INDIRECT("'Jati Jawa'!C"&D33) -> 2967.4779 | E23: =INDIRECT("'Jati Jawa'!C"&E33) -> 577.89055 | F23: =INDIRECT("'Jati Jawa'!C"&F33) -> 356.22743 | G23: =INDIRECT("'Jati Jawa'!C"&G33) -> 422.88239 | H23: =INDIRECT("'Jati Jawa'!C"&H33) -> 371.14777 | I23: =INDIRECT("'Jati Jawa'!C"&I33) -> 311.23823 | J23: =INDIRECT("'Jati Jawa'!C"&J33) -> 200.36266 | ... R23: =INDIRECT("'Jati Jawa'!C"&R33) -> 433.97611
A24: Penanaman | C24: =INDIRECT("'Jati Jawa'!D"&C33) -> 20.99773 | D24: =INDIRECT("'Jati Jawa'!D"&D33) -> 11.99722 | E24: =INDIRECT("'Jati Jawa'!D"&E33) -> 3.5932031 | F24: =INDIRECT("'Jati Jawa'!D"&F33) -> 1.8099686 | G24: =INDIRECT("'Jati Jawa'!D"&G33) -> 1.2573663 | H24: =INDIRECT("'Jati Jawa'!D"&H33) -> 1.8180101 | I24: =INDIRECT("'Jati Jawa'!D"&I33) -> 1.3195063 | J24: =INDIRECT("'Jati Jawa'!D"&J33) -> 0.20702234 | ... R24: =INDIRECT("'Jati Jawa'!D"&R33) -> 1.1985371
A25: 3.Pengurangan | C25: =SUM(C26:C27) -> 820.57523 | D25: =SUM(D26:D27) -> 553.08182 | E25: =SUM(E26:E27) -> 174.4749 | F25: =SUM(F26:F27) -> 219.62645 | G25: =SUM(G26:G27) -> 141.73049 | H25: =SUM(H26:H27) -> 116.90326 | I25: =SUM(I26:I27) -> 105.22407 | J25: =SUM(J26:J27) -> 52.526688 | ... R25: =SUM(R26:R27) -> 92.151867
A26: Kerusakan | C26: =INDIRECT("'Jati Jawa'!E"&C33) -> 321.45425 | D26: =INDIRECT("'Jati Jawa'!E"&D33) -> 273.68145 | E26: =INDIRECT("'Jati Jawa'!E"&E33) -> 122.09508 | F26: =INDIRECT("'Jati Jawa'!E"&F33) -> 189.85763 | G26: =INDIRECT("'Jati Jawa'!E"&G33) -> 108.30582 | H26: =INDIRECT("'Jati Jawa'!E"&H33) -> 81.384662 | I26: =INDIRECT("'Jati Jawa'!E"&I33) -> 79.73689 | J26: =INDIRECT("'Jati Jawa'!E"&J33) -> 40.94462 | ... R26: =INDIRECT("'Jati Jawa'!E"&R33) -> 58.475325
A27: Penebangan | C27: =INDIRECT("'Jati Jawa'!F"&C33) -> 499.12098 | D27: =INDIRECT("'Jati Jawa'!F"&D33) -> 279.40037 | E27: =INDIRECT("'Jati Jawa'!F"&E33) -> 52.379825 | F27: =INDIRECT("'Jati Jawa'!F"&F33) -> 29.768814 | G27: =INDIRECT("'Jati Jawa'!F"&G33) -> 33.424677 | H27: =INDIRECT("'Jati Jawa'!F"&H33) -> 35.518595 | I27: =INDIRECT("'Jati Jawa'!F"&I33) -> 25.487175 | J27: =INDIRECT("'Jati Jawa'!F"&J33) -> 11.582068 | ... R27: =INDIRECT("'Jati Jawa'!F"&R33) -> 33.676543
A28: 4. Revaluasi | C28: =INDIRECT("'Jati Jawa'!G"&C33) -> 8216.085 | D28: =INDIRECT("'Jati Jawa'!G"&D33) -> -45515.094 | E28: =INDIRECT("'Jati Jawa'!G"&E33) -> -49854.16 | F28: =INDIRECT("'Jati Jawa'!G"&F33) -> -4790.1535 | G28: =INDIRECT("'Jati Jawa'!G"&G33) -> 384.80033 | H28: =INDIRECT("'Jati Jawa'!G"&H33) -> 47.074999 | I28: =INDIRECT("'Jati Jawa'!G"&I33) -> -1451.3872 | J28: =INDIRECT("'Jati Jawa'!G"&J33) -> -2150.1648 | ... R28: =INDIRECT("'Jati Jawa'!G"&R33) -> -2502.2892
A29: 5. Persediaan akhir | C29: =C21+C22-C25+C28 -> 104925.04 | D29: =D21+D22-D25+D28 -> 61836.339 | E29: =E21+E22-E25+E28 -> 12389.188 | F29: =F21+F22-F25+F28 -> 7737.4453 | G29: =G21+G22-G25+G28 -> 8404.6549 | H29: =H21+H22-H25+H28 -> 8707.7924 | I29: =I21+I22-I25+I28 -> 7463.7389 | J29: =J21+J22-J25+J28 -> 5461.6171 | ... R29: =R21+R22-R25+R28 -> 12599.73
C30: =C29-INDIRECT("'Jati Jawa'!H"&C33) -> 0 | D30: =D29-INDIRECT("'Jati Jawa'!H"&D33) -> 0 | E30: =E29-INDIRECT("'Jati Jawa'!H"&E33) -> 0 | F30: =F29-INDIRECT("'Jati Jawa'!H"&F33) -> 0 | G30: =G29-INDIRECT("'Jati Jawa'!H"&G33) -> 0 | H30: =H29-INDIRECT("'Jati Jawa'!H"&H33) -> 0 | I30: =I29-INDIRECT("'Jati Jawa'!H"&I33) -> -8.1854523e-12 | J30: =J29-INDIRECT("'Jati Jawa'!H"&J33) -> -1.0004442e-11 | ... R30: =R29-INDIRECT("'Jati Jawa'!H"&R33) -> 0
A32: nomor baris neraca fisik | B32: 4 | C32: =B32+1 -> 5 | D32: =C32+1 -> 6 | E32: =D32+1 -> 7 | F32: =E32+1 -> 8 | G32: =F32+1 -> 9 | H32: =G32+1 -> 10 | I32: =H32+1 -> 11 | J32: =I32+1 -> 12 | ... R32: =Q32+1 -> 20
A33: nomor baris neraca moneter | C33: 47 | D33: =C33+1 -> 48 | E33: =D33+1 -> 49 | F33: =E33+1 -> 50 | G33: =F33+1 -> 51 | H33: =G33+1 -> 52 | I33: =H33+1 -> 53 | J33: =I33+1 -> 54 | K33: =J33+1 -> 55 | ... R33: =Q33+1 -> 62

Sheet Rekap RJ
A1: Neraca Fisik dan Moneter
A2: Sumber Daya Hutan Rimba Jawa
A4: Perincian | B4: 2008 | C4: 2009 | D4: 2010 | E4: 2011 | F4: 2012 | G4: 2013 | H4: 2014 | I4: 2015 | J4: 2016 | K4: 2017 | L4: 2018 | M4: 2019 | N4: 2020 | O4: 2021 | P4: 2022 | Q4: 2023 | R4: 2024
A6: I. Neraca Fisik (000 M3)
A8: 1. Persediaan awal | B8: ='Rimba Jawa'!B4 -> 352874.6 | C8: =B15 -> 368802.12 | D8: =C15 -> 385178.91 | E8: =D15 -> 401131.81 | F8: =E15 -> 416754.42 | G8: =F15 -> 432600.57 | H8: =G15 -> 461659.54 | I8: =H15 -> 478966.43 | J8: =I15 -> 496202.79 | ... R8: =Q15 -> 565494.79
A9: 2. Penambahan | B9: =SUM(B10:B11) -> 16820.472 | C9: =SUM(C10:C11) -> 17157.186 | D9: =SUM(D10:D11) -> 16777.587 | E9: =SUM(E10:E11) -> 17043.373 | F9: =SUM(F10:F11) -> 18620.283 | G9: =SUM(G10:G11) -> 30805.018 | H9: =SUM(H10:H11) -> 18682.609 | I9: =SUM(I10:I11) -> 18708.521 | ... R9: =SUM(R10:R11) -> 18219.534
A10: Pertumbuhan | B10: =INDIRECT("'Rimba Jawa'!C"&B32) -> 16669.278 | C10: =INDIRECT("'Rimba Jawa'!C"&C32) -> 17077.825 | D10: =INDIRECT("'Rimba Jawa'!C"&D32) -> 16669.3 | E10: =INDIRECT("'Rimba Jawa'!C"&E32) -> 17002.694 | F10: =INDIRECT("'Rimba Jawa'!C"&F32) -> 18588.711 | G10: =INDIRECT("'Rimba Jawa'!C"&G32) -> 30769.212 | H10: =INDIRECT("'Rimba Jawa'!C"&H32) -> 18645.347 | I10: =INDIRECT("'Rimba Jawa'!C"&I32) -> 18669.687 | ... R10: =INDIRECT("'Rimba Jawa'!C"&R32) -> 18205.292
A11: Penanaman | B11: =INDIRECT("'Rimba Jawa'!D"&B32) -> 151.19423 | C11: =INDIRECT("'Rimba Jawa'!D"&C32) -> 79.3611 | D11: =INDIRECT("'Rimba Jawa'!D"&D32) -> 108.28688 | E11: =INDIRECT("'Rimba Jawa'!D"&E32) -> 40.679275 | F11: =INDIRECT("'Rimba Jawa'!D"&F32) -> 31.57245 | G11: =INDIRECT("'Rimba Jawa'!D"&G32) -> 35.806225 | H11: =INDIRECT("'Rimba Jawa'!D"&H32) -> 37.262225 | I11: =INDIRECT("'Rimba Jawa'!D"&I32) -> 38.834 | ... R11: =INDIRECT("'Rimba Jawa'!D"&R32) -> 14.2415
A12: 3.Pengurangan | B12: =SUM(B13:B14) -> 892.95421 | C12: =SUM(C13:C14) -> 780.40155 | D12: =SUM(D13:D14) -> 824.68098 | E12: =SUM(E13:E14) -> 1420.7633 | F12: =SUM(F13:F14) -> 2774.1302 | G12: =SUM(G13:G14) -> 1746.0507 | H12: =SUM(H13:H14) -> 1375.7167 | I12: =SUM(I13:I14) -> 1472.1614 | ... R12: =SUM(R13:R14) -> 1008.3118
A13: Kerusakan | B13: =INDIRECT("'Rimba Jawa'!E"&B32) -> 287.74121 | C13: =INDIRECT("'Rimba Jawa'!E"&C32) -> 256.21155 | D13: =INDIRECT("'Rimba Jawa'!E"&D32) -> 385.25198 | E13: =INDIRECT("'Rimba Jawa'!E"&E32) -> 886.96329 | F13: =INDIRECT("'Rimba Jawa'!E"&F32) -> 2248.6402 | G13: =INDIRECT("'Rimba Jawa'!E"&G32) -> 1221.983 | H13: =INDIRECT("'Rimba Jawa'!E"&H32) -> 913.12499 | I13: =INDIRECT("'Rimba Jawa'!E"&I32) -> 1073.5777 | ... R13: =INDIRECT("'Rimba Jawa'!E"&R32) -> 600.18276
A14: Penebangan | B14: =INDIRECT("'Rimba Jawa'!F"&B32) -> 605.213 | C14: =INDIRECT("'Rimba Jawa'!F"&C32) -> 524.19 | D14: =INDIRECT("'Rimba Jawa'!F"&D32) -> 439.429 | E14: =INDIRECT("'Rimba Jawa'!F"&E32) -> 533.8 | F14: =INDIRECT("'Rimba Jawa'!F"&F32) -> 525.49 | G14: =INDIRECT("'Rimba Jawa'!F"&G32) -> 524.06771 | H14: =INDIRECT("'Rimba Jawa'!F"&H32) -> 462.59173 | I14: =INDIRECT("'Rimba Jawa'!F"&I32) -> 398.58371 | ... R14: =INDIRECT("'Rimba Jawa'!F"&R32) -> 408.129
A15: 4. Persediaan akhir | B15: =B8+B9-B12 -> 368802.12 | C15: =C8+C9-C12 -> 385178.91 | D15: =D8+D9-D12 -> 401131.81 | E15: =E8+E9-E12 -> 416754.42 | F15: =F8+F9-F12 -> 432600.57 | G15: =G8+G9-G12 -> 461659.54 | H15: =H8+H9-H12 -> 478966.43 | I15: =I8+I9-I12 -> 496202.79 | ... R15: =R8+R9-R12 -> 582706.01
C16: =C15-INDIRECT("'Rimba Jawa'!G"&C32) -> 0 | D16: =D15-INDIRECT("'Rimba Jawa'!G"&D32) -> 0 | E16: =E15-INDIRECT("'Rimba Jawa'!G"&E32) -> 0 | F16: =F15-INDIRECT("'Rimba Jawa'!G"&F32) -> 0 | G16: =G15-INDIRECT("'Rimba Jawa'!G"&G32) -> 0 | H16: =H15-INDIRECT("'Rimba Jawa'!G"&H32) -> 0 | I16: =I15-INDIRECT("'Rimba Jawa'!G"&I32) -> 0 | J16: =J15-INDIRECT("'Rimba Jawa'!G"&J32) -> 0 | ... R16: =R15-INDIRECT("'Rimba Jawa'!G"&R32) -> 0
A18: III. Neraca Moneter
A19: (Miliar Rp)
A21: 1. Persediaan awal | C21: ='Rimba Jawa'!B46 -> 351327.58 | D21: =C29 -> 402773.07 | E21: =D29 -> 78445.539 | F21: =E29 -> 14587.809 | G21: =F29 -> 9679.9898 | H21: =G29 -> 8929.8894 | I21: =H29 -> 6353.4534 | J21: =I29 -> 5513.4571 | K21: =J29 -> 4483.5833 | ... R21: =Q29 -> 11166.037
A22: 2. Penambahan | C22: =SUM(C23:C24) -> 17940.89 | D22: =SUM(D23:D24) -> 3281.0334 | E22: =SUM(E23:E24) -> 596.57547 | F22: =SUM(F23:F24) -> 416.6526 | G22: =SUM(G23:G24) -> 595.86205 | H22: =SUM(H23:H24) -> 247.82339 | I22: =SUM(I23:I24) -> 207.87595 | J22: =SUM(J23:J24) -> 98.523789 | ... R22: =SUM(R23:R24) -> 315.6115
A23: Pertumbuhan | C23: =INDIRECT("'Rimba Jawa'!C"&C33) -> 17857.904 | D23: =INDIRECT("'Rimba Jawa'!C"&D33) -> 3259.8567 | E23: =INDIRECT("'Rimba Jawa'!C"&E33) -> 595.15156 | F23: =INDIRECT("'Rimba Jawa'!C"&F33) -> 415.94613 | G23: =INDIRECT("'Rimba Jawa'!C"&G33) -> 595.16945 | H23: =INDIRECT("'Rimba Jawa'!C"&H33) -> 247.32911 | I23: =INDIRECT("'Rimba Jawa'!C"&I33) -> 207.44445 | J23: =INDIRECT("'Rimba Jawa'!C"&J33) -> 98.439731 | ... R23: =INDIRECT("'Rimba Jawa'!C"&R33) -> 315.3648
A24: Penanaman | C24: =INDIRECT("'Rimba Jawa'!D"&C33) -> 82.986148 | D24: =INDIRECT("'Rimba Jawa'!D"&D33) -> 21.176638 | E24: =INDIRECT("'Rimba Jawa'!D"&E33) -> 1.4239117 | F24: =INDIRECT("'Rimba Jawa'!D"&F33) -> 0.70647385 | G24: =INDIRECT("'Rimba Jawa'!D"&G33) -> 0.6926005 | H24: =INDIRECT("'Rimba Jawa'!D"&H33) -> 0.49428059 | I24: =INDIRECT("'Rimba Jawa'!D"&I33) -> 0.43149614 | J24: =INDIRECT("'Rimba Jawa'!D"&J33) -> 0.084058452 | ... R24: =INDIRECT("'Rimba Jawa'!D"&R33) -> 0.24670122
A25: 3.Pengurangan | C25: =SUM(C26:C27) -> 816.04866 | D25: =SUM(D26:D27) -> 161.27503 | E25: =SUM(E26:E27) -> 49.731502 | F25: =SUM(F26:F27) -> 62.074704 | G25: =SUM(G26:G27) -> 33.773892 | H25: =SUM(H26:H27) -> 18.248778 | I25: =SUM(I26:I27) -> 16.357624 | J25: =SUM(J26:J27) -> 9.4953569 | ... R25: =SUM(R26:R27) -> 17.466681
A26: Kerusakan | C26: =INDIRECT("'Rimba Jawa'!E"&C33) -> 267.91476 | D26: =INDIRECT("'Rimba Jawa'!E"&D33) -> 75.340071 | E26: =INDIRECT("'Rimba Jawa'!E"&E33) -> 31.046703 | F26: =INDIRECT("'Rimba Jawa'!E"&F33) -> 50.316195 | G26: =INDIRECT("'Rimba Jawa'!E"&G33) -> 23.636841 | H26: =INDIRECT("'Rimba Jawa'!E"&H33) -> 12.112534 | I26: =INDIRECT("'Rimba Jawa'!E"&I33) -> 11.928842 | J26: =INDIRECT("'Rimba Jawa'!E"&J33) -> 6.8579834 | ... R26: =INDIRECT("'Rimba Jawa'!E"&R33) -> 10.396785
A27: Penebangan | C27: =INDIRECT("'Rimba Jawa'!F"&C33) -> 548.1339 | D27: =INDIRECT("'Rimba Jawa'!F"&D33) -> 85.934957 | E27: =INDIRECT("'Rimba Jawa'!F"&E33) -> 18.684798 | F27: =INDIRECT("'Rimba Jawa'!F"&F33) -> 11.758509 | G27: =INDIRECT("'Rimba Jawa'!F"&G33) -> 10.137052 | H27: =INDIRECT("'Rimba Jawa'!F"&H33) -> 6.1362442 | I27: =INDIRECT("'Rimba Jawa'!F"&I33) -> 4.4287823 | J27: =INDIRECT("'Rimba Jawa'!F"&J33) -> 2.6373735 | ... R27: =INDIRECT("'Rimba Jawa'!F"&R33) -> 7.0698959
A28: 4. Revaluasi | C28: =INDIRECT("'Rimba Jawa'!G"&C33) -> 34320.643 | D28: =INDIRECT("'Rimba Jawa'!G"&D33) -> -327447.29 | E28: =INDIRECT("'Rimba Jawa'!G"&E33) -> -64404.575 | F28: =INDIRECT("'Rimba Jawa'!G"&F33) -> -5262.3969 | G28: =INDIRECT("'Rimba Jawa'!G"&G33) -> -1312.1886 | H28: =INDIRECT("'Rimba Jawa'!G"&H33) -> -2806.0106 | I28: =INDIRECT("'Rimba Jawa'!G"&I33) -> -1031.5146 | J28: =INDIRECT("'Rimba Jawa'!G"&J33) -> -1118.9022 | ... R28: =INDIRECT("'Rimba Jawa'!G"&R33) -> -1370.1405
A29: 5. Persediaan akhir | C29: =C21+C22-C25+C28 -> 402773.07 | D29: =D21+D22-D25+D28 -> 78445.539 | E29: =E21+E22-E25+E28 -> 14587.809 | F29: =F21+F22-F25+F28 -> 9679.9898 | G29: =G21+G22-G25+G28 -> 8929.8894 | H29: =H21+H22-H25+H28 -> 6353.4534 | I29: =I21+I22-I25+I28 -> 5513.4571 | J29: =J21+J22-J25+J28 -> 4483.5833 | ... R29: =R21+R22-R25+R28 -> 10094.041
D30: =D29-INDIRECT("'Rimba Jawa'!H"&D33) -> 0 | E30: =E29-INDIRECT("'Rimba Jawa'!H"&E33) -> 0 | F30: =F29-INDIRECT("'Rimba Jawa'!H"&F33) -> 0 | G30: =G29-INDIRECT("'Rimba Jawa'!H"&G33) -> 0 | H30: =H29-INDIRECT("'Rimba Jawa'!H"&H33) -> 1.0004442e-11 | I30: =I29-INDIRECT("'Rimba Jawa'!H"&I33) -> 1.0004442e-11 | J30: =J29-INDIRECT("'Rimba Jawa'!H"&J33) -> 1.0004442e-11 | K30: =K29-INDIRECT("'Rimba Jawa'!H"&K33) -> 1.0004442e-11 | ... R30: =R29-INDIRECT("'Rimba Jawa'!H"&R33) -> 0
A32: nomor baris neraca fisik | B32: 4 | C32: =B32+1 -> 5 | D32: =C32+1 -> 6 | E32: =D32+1 -> 7 | F32: =E32+1 -> 8 | G32: =F32+1 -> 9 | H32: =G32+1 -> 10 | I32: =H32+1 -> 11 | J32: =I32+1 -> 12 | ... R32: =Q32+1 -> 20
A33: nomor baris neraca moneter | C33: 46 | D33: =C33+1 -> 47 | E33: =D33+1 -> 48 | F33: =E33+1 -> 49 | G33: =F33+1 -> 50 | H33: =G33+1 -> 51 | I33: =H33+1 -> 52 | J33: =I33+1 -> 53 | K33: =J33+1 -> 54 | ... R33: =Q33+1 -> 61

Sheet Rekap RLJ
A1: Neraca Fisik dan Moneter
A2: Sumber Daya Hutan Rimba Luar Jawa
A4: Perincian | B4: 2008 | C4: 2009 | D4: 2010 | E4: 2011 | F4: 2012 | G4: 2013 | H4: 2014 | I4: 2015 | J4: 2016 | K4: 2017 | L4: 2018 | M4: 2019 | N4: 2020 | O4: 2021 | P4: 2022 | Q4: 2023 | R4: 2024
A6: I. Neraca Fisik (000 M3)
A8: 1. Persediaan awal | B8: ='Rimba Luar Jawa'!B4 -> 6500648.8 | C8: =B15 -> 6282105.2 | D8: =C15 -> 6039224.3 | E8: =D15 -> 5770970.1 | F8: =E15 -> 5478994.8 | G8: =F15 -> 5132541.5 | H8: =G15 -> 5036128.5 | I8: =H15 -> 4833123.5 | J8: =I15 -> 4216415 | ... R8: =Q15 -> 2815937.8
A9: 2. Penambahan | B9: =SUM(B10:B11) -> 36722.857 | C9: =SUM(C10:C11) -> 35477.997 | D9: =SUM(D10:D11) -> 33870.284 | E9: =SUM(E10:E11) -> 34466.867 | F9: =SUM(F10:F11) -> 35619.121 | G9: =SUM(G10:G11) -> 33477.313 | H9: =SUM(H10:H11) -> 34411.298 | I9: =SUM(I10:I11) -> 38963.628 | ... R9: =SUM(R10:R11) -> 30996.618
A10: Pertumbuhan | B10: =INDIRECT("'Rimba Luar Jawa'!C"&B32) -> 28768.843 | C10: =INDIRECT("'Rimba Luar Jawa'!C"&C32) -> 29427.551 | D10: =INDIRECT("'Rimba Luar Jawa'!C"&D32) -> 29417.615 | E10: =INDIRECT("'Rimba Luar Jawa'!C"&E32) -> 29641.821 | F10: =INDIRECT("'Rimba Luar Jawa'!C"&F32) -> 29470.768 | G10: =INDIRECT("'Rimba Luar Jawa'!C"&G32) -> 22422.401 | H10: =INDIRECT("'Rimba Luar Jawa'!C"&H32) -> 23276.945 | I10: =INDIRECT("'Rimba Luar Jawa'!C"&I32) -> 23334.934 | ... R10: =INDIRECT("'Rimba Luar Jawa'!C"&R32) -> 23297.342
A11: Penanaman | B11: =INDIRECT("'Rimba Luar Jawa'!D"&B32) -> 7954.0144 | C11: =INDIRECT("'Rimba Luar Jawa'!D"&C32) -> 6050.4458 | D11: =INDIRECT("'Rimba Luar Jawa'!D"&D32) -> 4452.6684 | E11: =INDIRECT("'Rimba Luar Jawa'!D"&E32) -> 4825.0458 | F11: =INDIRECT("'Rimba Luar Jawa'!D"&F32) -> 6148.3529 | G11: =INDIRECT("'Rimba Luar Jawa'!D"&G32) -> 11054.912 | H11: =INDIRECT("'Rimba Luar Jawa'!D"&H32) -> 11134.353 | I11: =INDIRECT("'Rimba Luar Jawa'!D"&I32) -> 15628.694 | ... R11: =INDIRECT("'Rimba Luar Jawa'!D"&R32) -> 7699.2765
A12: 3.Pengurangan | B12: =SUM(B13:B14) -> 255266.44 | C12: =SUM(C13:C14) -> 278358.92 | D12: =SUM(D13:D14) -> 302124.55 | E12: =SUM(E13:E14) -> 326442.07 | F12: =SUM(F13:F14) -> 382072.47 | G12: =SUM(G13:G14) -> 129890.32 | H12: =SUM(H13:H14) -> 237416.3 | I12: =SUM(I13:I14) -> 655672.14 | ... R12: =SUM(R13:R14) -> 149521.21
A13: Kerusakan | B13: =INDIRECT("'Rimba Luar Jawa'!E"&B32) -> 206743.81 | C13: =INDIRECT("'Rimba Luar Jawa'!E"&C32) -> 227447.89 | D13: =INDIRECT("'Rimba Luar Jawa'!E"&D32) -> 248573.61 | E13: =INDIRECT("'Rimba Luar Jawa'!E"&E32) -> 276481.4 | F13: =INDIRECT("'Rimba Luar Jawa'!E"&F32) -> 333058.25 | G13: =INDIRECT("'Rimba Luar Jawa'!E"&G32) -> 89854.22 | H13: =INDIRECT("'Rimba Luar Jawa'!E"&H32) -> 192303.64 | I13: =INDIRECT("'Rimba Luar Jawa'!E"&I32) -> 611062.47 | ... R13: =INDIRECT("'Rimba Luar Jawa'!E"&R32) -> 95017.524
A14: Penebangan | B14: =INDIRECT("'Rimba Luar Jawa'!F"&B32) -> 48522.631 | C14: =INDIRECT("'Rimba Luar Jawa'!F"&C32) -> 50911.031 | D14: =INDIRECT("'Rimba Luar Jawa'!F"&D32) -> 53550.936 | E14: =INDIRECT("'Rimba Luar Jawa'!F"&E32) -> 49960.669 | F14: =INDIRECT("'Rimba Luar Jawa'!F"&F32) -> 49014.219 | G14: =INDIRECT("'Rimba Luar Jawa'!F"&G32) -> 40036.102 | H14: =INDIRECT("'Rimba Luar Jawa'!F"&H32) -> 45112.663 | I14: =INDIRECT("'Rimba Luar Jawa'!F"&I32) -> 44609.668 | ... R14: =INDIRECT("'Rimba Luar Jawa'!F"&R32) -> 54503.682
A15: 4. Persediaan akhir | B15: =B8+B9-B12 -> 6282105.2 | C15: =C8+C9-C12 -> 6039224.3 | D15: =D8+D9-D12 -> 5770970.1 | E15: =E8+E9-E12 -> 5478994.8 | F15: =F8+F9-F12 -> 5132541.5 | G15: =G8+G9-G12 -> 5036128.5 | H15: =H8+H9-H12 -> 4833123.5 | I15: =I8+I9-I12 -> 4216415 | ... R15: =R8+R9-R12 -> 2697413.2
C16: =C15-INDIRECT("'Rimba Luar Jawa'!G"&C32) -> 0 | D16: =D15-INDIRECT("'Rimba Luar Jawa'!G"&D32) -> 0 | E16: =E15-INDIRECT("'Rimba Luar Jawa'!G"&E32) -> 0 | F16: =F15-INDIRECT("'Rimba Luar Jawa'!G"&F32) -> 0 | G16: =G15-INDIRECT("'Rimba Luar Jawa'!G"&G32) -> 0 | H16: =H15-INDIRECT("'Rimba Luar Jawa'!G"&H32) -> 0 | I16: =I15-INDIRECT("'Rimba Luar Jawa'!G"&I32) -> 0 | J16: =J15-INDIRECT("'Rimba Luar Jawa'!G"&J32) -> 0 | ... R16: =R15-INDIRECT("'Rimba Luar Jawa'!G"&R32) -> 0
A18: III. Neraca Moneter
A19: (Miliar Rp)
A21: 1. Persediaan awal | C21: ='Rimba Luar Jawa'!B46 -> 6022081.5 | D21: =C29 -> 6327497.1 | E21: =D29 -> 4617199.8 | F21: =E29 -> 1354056.5 | G21: =F29 -> 906965.29 | H21: =G29 -> 684327.22 | I21: =H29 -> 704923.84 | J21: =I29 -> 615856.91 | K21: =J29 -> 671554.69 | ... R21: =Q29 -> 1358302.4
A22: 2. Penambahan | C22: =SUM(C23:C24) -> 37171.483 | D22: =SUM(D23:D24) -> 27098.714 | E22: =SUM(E23:E24) -> 8518.001 | F22: =SUM(F23:F24) -> 6294.2124 | G22: =SUM(G23:G24) -> 4549.0174 | H22: =SUM(H23:H24) -> 5018.9788 | I22: =SUM(I23:I24) -> 5691.0954 | J22: =SUM(J23:J24) -> 6811.7005 | ... R22: =SUM(R23:R24) -> 14952.656
A23: Pertumbuhan | C23: =INDIRECT("'Rimba Luar Jawa'!C"&C33) -> 30832.229 | D23: =INDIRECT("'Rimba Luar Jawa'!C"&D33) -> 23536.252 | E23: =INDIRECT("'Rimba Luar Jawa'!C"&E33) -> 7325.5589 | F23: =INDIRECT("'Rimba Luar Jawa'!C"&F33) -> 5207.7442 | G23: =INDIRECT("'Rimba Luar Jawa'!C"&G33) -> 3046.8363 | H23: =INDIRECT("'Rimba Luar Jawa'!C"&H33) -> 3395.0039 | I23: =INDIRECT("'Rimba Luar Jawa'!C"&I33) -> 3408.3412 | J23: =INDIRECT("'Rimba Luar Jawa'!C"&J33) -> 3955.2703 | ... R23: =INDIRECT("'Rimba Luar Jawa'!C"&R33) -> 11238.553
A24: Penanaman | C24: =INDIRECT("'Rimba Luar Jawa'!D"&C33) -> 6339.2542 | D24: =INDIRECT("'Rimba Luar Jawa'!D"&D33) -> 3562.4617 | E24: =INDIRECT("'Rimba Luar Jawa'!D"&E33) -> 1192.4422 | F24: =INDIRECT("'Rimba Luar Jawa'!D"&F33) -> 1086.4681 | G24: =INDIRECT("'Rimba Luar Jawa'!D"&G33) -> 1502.1812 | H24: =INDIRECT("'Rimba Luar Jawa'!D"&H33) -> 1623.9749 | I24: =INDIRECT("'Rimba Luar Jawa'!D"&I33) -> 2282.7542 | J24: =INDIRECT("'Rimba Luar Jawa'!D"&J33) -> 2856.4302 | ... R24: =INDIRECT("'Rimba Luar Jawa'!D"&R33) -> 3714.103
A25: 3.Pengurangan | C25: =SUM(C26:C27) -> 291645.94 | D25: =SUM(D26:D27) -> 241721.83 | E25: =SUM(E26:E27) -> 80675.563 | F25: =SUM(F26:F27) -> 67515.57 | G25: =SUM(G26:G27) -> 17649.963 | H25: =SUM(H26:H27) -> 34627.795 | I25: =SUM(I26:I27) -> 95768.614 | J25: =SUM(J26:J27) -> 39544.972 | ... R25: =SUM(R26:R27) -> 72128.485
A26: Kerusakan | C26: =INDIRECT("'Rimba Luar Jawa'!E"&C33) -> 238304.75 | D26: =INDIRECT("'Rimba Luar Jawa'!E"&D33) -> 198877.15 | E26: =INDIRECT("'Rimba Luar Jawa'!E"&E33) -> 68328.487 | F26: =INDIRECT("'Rimba Luar Jawa'!E"&F33) -> 58854.326 | G26: =INDIRECT("'Rimba Luar Jawa'!E"&G33) -> 12209.714 | H26: =INDIRECT("'Rimba Luar Jawa'!E"&H33) -> 28047.994 | I26: =INDIRECT("'Rimba Luar Jawa'!E"&I33) -> 89252.848 | J26: =INDIRECT("'Rimba Luar Jawa'!E"&J33) -> 32085.24 | ... R26: =INDIRECT("'Rimba Luar Jawa'!E"&R33) -> 45836.107
A27: Penebangan | C27: =INDIRECT("'Rimba Luar Jawa'!F"&C33) -> 53341.189 | D27: =INDIRECT("'Rimba Luar Jawa'!F"&D33) -> 42844.681 | E27: =INDIRECT("'Rimba Luar Jawa'!F"&E33) -> 12347.076 | F27: =INDIRECT("'Rimba Luar Jawa'!F"&F33) -> 8661.2441 | G27: =INDIRECT("'Rimba Luar Jawa'!F"&G33) -> 5440.2493 | H27: =INDIRECT("'Rimba Luar Jawa'!F"&H33) -> 6579.8012 | I27: =INDIRECT("'Rimba Luar Jawa'!F"&I33) -> 6515.7658 | J27: =INDIRECT("'Rimba Luar Jawa'!F"&J33) -> 7459.7316 | ... R27: =INDIRECT("'Rimba Luar Jawa'!F"&R33) -> 26292.378
A28: 4. Revaluasi | C28: =INDIRECT("'Rimba Luar Jawa'!G"&C33) -> 559890.03 | D28: =INDIRECT("'Rimba Luar Jawa'!G"&D33) -> -1495674.2 | E28: =INDIRECT("'Rimba Luar Jawa'!G"&E33) -> -3190985.8 | F28: =INDIRECT("'Rimba Luar Jawa'!G"&F33) -> -385869.81 | G28: =INDIRECT("'Rimba Luar Jawa'!G"&G33) -> -209537.12 | H28: =INDIRECT("'Rimba Luar Jawa'!G"&H33) -> 50205.437 | I28: =INDIRECT("'Rimba Luar Jawa'!G"&I33) -> 1010.5928 | J28: =INDIRECT("'Rimba Luar Jawa'!G"&J33) -> 88431.047 | ... R28: =INDIRECT("'Rimba Luar Jawa'!G"&R33) -> 95.731758
A29: 5. Persediaan akhir | C29: =C21+C22-C25+C28 -> 6327497.1 | D29: =D21+D22-D25+D28 -> 4617199.8 | E29: =E21+E22-E25+E28 -> 1354056.5 | F29: =F21+F22-F25+F28 -> 906965.29 | G29: =G21+G22-G25+G28 -> 684327.22 | H29: =H21+H22-H25+H28 -> 704923.84 | I29: =I21+I22-I25+I28 -> 615856.91 | J29: =J21+J22-J25+J28 -> 671554.69 | ... R29: =R21+R22-R25+R28 -> 1301222.3
D30: =D29-INDIRECT("'Rimba Luar Jawa'!H"&D33) -> 0 | E30: =E29-INDIRECT("'Rimba Luar Jawa'!H"&E33) -> 0 | F30: =F29-INDIRECT("'Rimba Luar Jawa'!H"&F33) -> 0 | G30: =G29-INDIRECT("'Rimba Luar Jawa'!H"&G33) -> 0 | H30: =H29-INDIRECT("'Rimba Luar Jawa'!H"&H33) -> 0 | I30: =I29-INDIRECT("'Rimba Luar Jawa'!H"&I33) -> 0 | J30: =J29-INDIRECT("'Rimba Luar Jawa'!H"&J33) -> 0 | K30: =K29-INDIRECT("'Rimba Luar Jawa'!H"&K33) -> 0 | ... R30: =R29-INDIRECT("'Rimba Luar Jawa'!H"&R33) -> 0
A32: nomor baris neraca fisik | B32: 4 | C32: =B32+1 -> 5 | D32: =C32+1 -> 6 | E32: =D32+1 -> 7 | F32: =E32+1 -> 8 | G32: =F32+1 -> 9 | H32: =G32+1 -> 10 | I32: =H32+1 -> 11 | J32: =I32+1 -> 12 | ... R32: =Q32+1 -> 20
A33: nomor baris neraca moneter | C33: 46 | D33: =C33+1 -> 47 | E33: =D33+1 -> 48 | F33: =E33+1 -> 49 | G33: =F33+1 -> 50 | H33: =G33+1 -> 51 | I33: =H33+1 -> 52 | J33: =I33+1 -> 53 | K33: =J33+1 -> 54 | ... R33: =Q33+1 -> 61

Sheet Rekap Transpose
A1: Neraca Fisik Kayu (000 m3)
A2: Rincian | B2: Persediaan Awal | C2: Pertumbuhan | D2: Penanaman | E2: Konversi & Kerusakan | F2: Penebangan | G2: Persediaan Akhir | H2: Perkiraan Cadangan | I2: Laju Persediaan Akhir | J2: Cek Persediaan Akhir
A3: 2008 | B3: ='Jati Jawa'!B4+'Rimba Jawa'!B4+'Rimba Luar Jawa'!B4 -> 6941231.3 | C3: ='Jati Jawa'!C4+'Rimba Jawa'!C4+'Rimba Luar Jawa'!C4 -> 50170.417 | D3: ='Jati Jawa'!D4+'Rimba Jawa'!D4+'Rimba Luar Jawa'!D4 -> 8137.2246 | E3: ='Jati Jawa'!E4+'Rimba Jawa'!E4+'Rimba Luar Jawa'!E4 -> 207360.8 | F3: ='Jati Jawa'!F4+'Rimba Jawa'!F4+'Rimba Luar Jawa'!F4 -> 49605.554 | G3: ='Jati Jawa'!G4+'Rimba Jawa'!G4+'Rimba Luar Jawa'!G4 -> 6742572.6 | H3: =G3/F3 -> 135.92374 | J3: =B3+C3+D3-E3-F3-G3 -> 0
A4: 2009 | B4: ='Jati Jawa'!B5+'Rimba Jawa'!B5+'Rimba Luar Jawa'!B5 -> 6742572.6 | C4: ='Jati Jawa'!C5+'Rimba Jawa'!C5+'Rimba Luar Jawa'!C5 -> 51261.334 | D4: ='Jati Jawa'!D5+'Rimba Jawa'!D5+'Rimba Luar Jawa'!D5 -> 6148.9569 | E4: ='Jati Jawa'!E5+'Rimba Jawa'!E5+'Rimba Luar Jawa'!E5 -> 227997.26 | F4: ='Jati Jawa'!F5+'Rimba Jawa'!F5+'Rimba Luar Jawa'!F5 -> 51890.421 | G4: ='Jati Jawa'!G5+'Rimba Jawa'!G5+'Rimba Luar Jawa'!G5 -> 6520095.2 | H4: =G4/F4 -> 125.65123 | I4: =G4/G3*100-100 -> -3.2995921 | J4: =B4+C4+D4-E4-F4-G4 -> 0
A5: 2010 | B5: ='Jati Jawa'!B6+'Rimba Jawa'!B6+'Rimba Luar Jawa'!B6 -> 6520095.2 | C5: ='Jati Jawa'!C6+'Rimba Jawa'!C6+'Rimba Luar Jawa'!C6 -> 50866.651 | D5: ='Jati Jawa'!D6+'Rimba Jawa'!D6+'Rimba Luar Jawa'!D6 -> 4580.2793 | E5: ='Jati Jawa'!E6+'Rimba Jawa'!E6+'Rimba Luar Jawa'!E6 -> 249399.69 | F5: ='Jati Jawa'!F6+'Rimba Jawa'!F6+'Rimba Luar Jawa'!F6 -> 54440.397 | G5: ='Jati Jawa'!G6+'Rimba Jawa'!G6+'Rimba Luar Jawa'!G6 -> 6271702.1 | H5: =G5/F5 -> 115.20309 | I5: =G5/G4*100-100 -> -3.8096553 | J5: =B5+C5+D5-E5-F5-G5 -> 0
A6: 2011 | B6: ='Jati Jawa'!B7+'Rimba Jawa'!B7+'Rimba Luar Jawa'!B7 -> 6271702.1 | C6: ='Jati Jawa'!C7+'Rimba Jawa'!C7+'Rimba Luar Jawa'!C7 -> 51448.15 | D6: ='Jati Jawa'!D7+'Rimba Jawa'!D7+'Rimba Luar Jawa'!D7 -> 4895.5931 | E6: ='Jati Jawa'!E7+'Rimba Jawa'!E7+'Rimba Luar Jawa'!E7 -> 278383.26 | F6: ='Jati Jawa'!F7+'Rimba Jawa'!F7+'Rimba Luar Jawa'!F7 -> 50929.869 | G6: ='Jati Jawa'!G7+'Rimba Jawa'!G7+'Rimba Luar Jawa'!G7 -> 5998732.7 | H6: =G6/F6 -> 117.78418 | I6: =G6/G5*100-100 -> -4.3523973 | J6: =B6+C6+D6-E6-F6-G6 -> 0
A7: 2012 | B7: ='Jati Jawa'!B8+'Rimba Jawa'!B8+'Rimba Luar Jawa'!B8 -> 5998732.7 | C7: ='Jati Jawa'!C8+'Rimba Jawa'!C8+'Rimba Luar Jawa'!C8 -> 52887.133 | D7: ='Jati Jawa'!D8+'Rimba Jawa'!D8+'Rimba Luar Jawa'!D8 -> 6204.4544 | E7: ='Jati Jawa'!E8+'Rimba Jawa'!E8+'Rimba Luar Jawa'!E8 -> 337879.87 | F7: ='Jati Jawa'!F8+'Rimba Jawa'!F8+'Rimba Luar Jawa'!F8 -> 49943.141 | G7: ='Jati Jawa'!G8+'Rimba Jawa'!G8+'Rimba Luar Jawa'!G8 -> 5670001.2 | H7: =G7/F7 -> 113.52913 | I7: =G7/G6*100-100 -> -5.4800146 | J7: =B7+C7+D7-E7-F7-G7 -> 0
A8: 2013 | B8: ='Jati Jawa'!B9+'Rimba Jawa'!B9+'Rimba Luar Jawa'!B9 -> 5670001.2 | C8: ='Jati Jawa'!C9+'Rimba Jawa'!C9+'Rimba Luar Jawa'!C9 -> 58651.075 | D8: ='Jati Jawa'!D9+'Rimba Jawa'!D9+'Rimba Luar Jawa'!D9 -> 11106.951 | E8: ='Jati Jawa'!E9+'Rimba Jawa'!E9+'Rimba Luar Jawa'!E9 -> 92474.444 | F8: ='Jati Jawa'!F9+'Rimba Jawa'!F9+'Rimba Luar Jawa'!F9 -> 40991.687 | G8: ='Jati Jawa'!G9+'Rimba Jawa'!G9+'Rimba Luar Jawa'!G9 -> 5606293.1 | H8: =G8/F8 -> 136.76659 | I8: =G8/G7*100-100 -> -1.1235995 | J8: =B8+C8+D8-E8-F8-G8 -> 0 | K8: =G8/G7*100-100 -> -1.1235995
A9: 2014 | B9: ='Jati Jawa'!B10+'Rimba Jawa'!B10+'Rimba Luar Jawa'!B10 -> 5606293.1 | C9: ='Jati Jawa'!C10+'Rimba Jawa'!C10+'Rimba Luar Jawa'!C10 -> 46687.165 | D9: ='Jati Jawa'!D10+'Rimba Jawa'!D10+'Rimba Luar Jawa'!D10 -> 11194.956 | E9: ='Jati Jawa'!E10+'Rimba Jawa'!E10+'Rimba Luar Jawa'!E10 -> 194261.6 | F9: ='Jati Jawa'!F10+'Rimba Jawa'!F10+'Rimba Luar Jawa'!F10 -> 46031.25 | G9: ='Jati Jawa'!G10+'Rimba Jawa'!G10+'Rimba Luar Jawa'!G10 -> 5423882.4 | H9: =G9/F9 -> 117.83044 | I9: =G9/G8*100-100 -> -3.253678 | J9: =B9+C9+D9-E9-F9-G9 -> 0 | K9: =G9/G8*100-100 -> -3.253678
A10: 2015 | B10: ='Jati Jawa'!B11+'Rimba Jawa'!B11+'Rimba Luar Jawa'!B11 -> 5423882.4 | C10: ='Jati Jawa'!C11+'Rimba Jawa'!C11+'Rimba Luar Jawa'!C11 -> 46799.571 | D10: ='Jati Jawa'!D11+'Rimba Jawa'!D11+'Rimba Luar Jawa'!D11 -> 15687.856 | E10: ='Jati Jawa'!E11+'Rimba Jawa'!E11+'Rimba Luar Jawa'!E11 -> 613364.48 | F10: ='Jati Jawa'!F11+'Rimba Jawa'!F11+'Rimba Luar Jawa'!F11 -> 45400.908 | G10: ='Jati Jawa'!G11+'Rimba Jawa'!G11+'Rimba Luar Jawa'!G11 -> 4827604.5 | H10: =G10/F10 -> 106.33277 | I10: =G10/G9*100-100 -> -10.993564 | J10: =B10+C10+D10-E10-F10-G10 -> 0 | K10: =G10/G9*100-100 -> -10.993564
A11: 2016 | B11: ='Jati Jawa'!B12+'Rimba Jawa'!B12+'Rimba Luar Jawa'!B12 -> 4827604.5 | C11: ='Jati Jawa'!C12+'Rimba Jawa'!C12+'Rimba Luar Jawa'!C12 -> 39130.339 | D11: ='Jati Jawa'!D12+'Rimba Jawa'!D12+'Rimba Luar Jawa'!D12 -> 17114.782 | E11: ='Jati Jawa'!E12+'Rimba Jawa'!E12+'Rimba Luar Jawa'!E12 -> 193747.58 | F11: ='Jati Jawa'!F12+'Rimba Jawa'!F12+'Rimba Luar Jawa'!F12 -> 45208.181 | G11: ='Jati Jawa'!G12+'Rimba Jawa'!G12+'Rimba Luar Jawa'!G12 -> 4644893.8 | H11: =G11/F11 -> 102.74454 | I11: =G11/G10*100-100 -> -3.7847062 | J11: =B11+C11+D11-E11-F11-G11 -> 0 | K11: =G11/G10*100-100 -> -3.7847062
A12: 2017 | B12: ='Jati Jawa'!B13+'Rimba Jawa'!B13+'Rimba Luar Jawa'!B13 -> 4644893.8 | C12: ='Jati Jawa'!C13+'Rimba Jawa'!C13+'Rimba Luar Jawa'!C13 -> 39323.955 | D12: ='Jati Jawa'!D13+'Rimba Jawa'!D13+'Rimba Luar Jawa'!D13 -> 7358.6198 | E12: ='Jati Jawa'!E13+'Rimba Jawa'!E13+'Rimba Luar Jawa'!E13 -> 150327.39 | F12: ='Jati Jawa'!F13+'Rimba Jawa'!F13+'Rimba Luar Jawa'!F13 -> 47350.504 | G12: ='Jati Jawa'!G13+'Rimba Jawa'!G13+'Rimba Luar Jawa'!G13 -> 4493898.5 | H12: =G12/F12 -> 94.907088 | I12: =G12/G11*100-100 -> -3.2507808 | J12: =B12+C12+D12-E12-F12-G12 -> 0 | K12: =G12/G11*100-100 -> -3.2507808
A13: 2018 | B13: ='Jati Jawa'!B14+'Rimba Jawa'!B14+'Rimba Luar Jawa'!B14 -> 4493898.5 | C13: ='Jati Jawa'!C14+'Rimba Jawa'!C14+'Rimba Luar Jawa'!C14 -> 39685.752 | D13: ='Jati Jawa'!D14+'Rimba Jawa'!D14+'Rimba Luar Jawa'!D14 -> 9119.8912 | E13: ='Jati Jawa'!E14+'Rimba Jawa'!E14+'Rimba Luar Jawa'!E14 -> 129001.63 | F13: ='Jati Jawa'!F14+'Rimba Jawa'!F14+'Rimba Luar Jawa'!F14 -> 47270.063 | G13: ='Jati Jawa'!G14+'Rimba Jawa'!G14+'Rimba Luar Jawa'!G14 -> 4366432.4 | H13: =G13/F13 -> 92.372046 | I13: =G13/G12*100-100 -> -2.8364248 | J13: =B13+C13+D13-E13-F13-G13 -> 0 | K13: =G13/G12*100-100 -> -2.8364248
A14: 2019 | B14: ='Jati Jawa'!B15+'Rimba Jawa'!B15+'Rimba Luar Jawa'!B15 -> 4366432.4 | C14: ='Jati Jawa'!C15+'Rimba Jawa'!C15+'Rimba Luar Jawa'!C15 -> 39539.545 | D14: ='Jati Jawa'!D15+'Rimba Jawa'!D15+'Rimba Luar Jawa'!D15 -> 13004.311 | E14: ='Jati Jawa'!E15+'Rimba Jawa'!E15+'Rimba Luar Jawa'!E15 -> 325905.34 | F14: ='Jati Jawa'!F15+'Rimba Jawa'!F15+'Rimba Luar Jawa'!F15 -> 49365.234 | G14: ='Jati Jawa'!G15+'Rimba Jawa'!G15+'Rimba Luar Jawa'!G15 -> 4043705.7 | H14: =G14/F14 -> 81.914039 | I14: =G14/G13*100-100 -> -7.3910846 | J14: =B14+C14+D14-E14-F14-G14 -> 0 | K14: =G14/G13*100-100 -> -7.3910846
A15: 2020 | B15: ='Jati Jawa'!B16+'Rimba Jawa'!B16+'Rimba Luar Jawa'!B16 -> 4043705.7 | C15: ='Jati Jawa'!C16+'Rimba Jawa'!C16+'Rimba Luar Jawa'!C16 -> 34282.649 | D15: ='Jati Jawa'!D16+'Rimba Jawa'!D16+'Rimba Luar Jawa'!D16 -> 10760.199 | E15: ='Jati Jawa'!E16+'Rimba Jawa'!E16+'Rimba Luar Jawa'!E16 -> 68470.12 | F15: ='Jati Jawa'!F16+'Rimba Jawa'!F16+'Rimba Luar Jawa'!F16 -> 51980.746 | G15: ='Jati Jawa'!G16+'Rimba Jawa'!G16+'Rimba Luar Jawa'!G16 -> 3968297.7 | H15: =G15/F15 -> 76.341684 | I15: =G15/G14*100-100 -> -1.8648246 | J15: =B15+C15+D15-E15-F15-G15 -> 0 | K15: =G15/G14*100-100 -> -1.8648246
A16: 2021 | B16: ='Jati Jawa'!B17+'Rimba Jawa'!B17+'Rimba Luar Jawa'!B17 -> 3968297.7 | C16: ='Jati Jawa'!C17+'Rimba Jawa'!C17+'Rimba Luar Jawa'!C17 -> 34157.553 | D16: ='Jati Jawa'!D17+'Rimba Jawa'!D17+'Rimba Luar Jawa'!D17 -> 4748.4949 | E16: ='Jati Jawa'!E17+'Rimba Jawa'!E17+'Rimba Luar Jawa'!E17 -> 109629.58 | F16: ='Jati Jawa'!F17+'Rimba Jawa'!F17+'Rimba Luar Jawa'!F17 -> 54813.235 | G16: ='Jati Jawa'!G17+'Rimba Jawa'!G17+'Rimba Luar Jawa'!G17 -> 3842760.9 | H16: =G16/F16 -> 70.106443 | I16: =G16/G15*100-100 -> -3.1634916 | J16: =B16+C16+D16-E16-F16-G16 -> 0 | K16: =G16/G15*100-100 -> -3.1634916
A17: 2022 | B17: ='Jati Jawa'!B18+'Rimba Jawa'!B18+'Rimba Luar Jawa'!B18 -> 3842760.9 | C17: ='Jati Jawa'!C18+'Rimba Jawa'!C18+'Rimba Luar Jawa'!C18 -> 33987.37 | D17: ='Jati Jawa'!D18+'Rimba Jawa'!D18+'Rimba Luar Jawa'!D18 -> 6631.7194 | E17: ='Jati Jawa'!E18+'Rimba Jawa'!E18+'Rimba Luar Jawa'!E18 -> 55997.21 | F17: ='Jati Jawa'!F18+'Rimba Jawa'!F18+'Rimba Luar Jawa'!F18 -> 55055.541 | G17: ='Jati Jawa'!G18+'Rimba Jawa'!G18+'Rimba Luar Jawa'!G18 -> 3772327.3 | H17: =G17/F17 -> 68.518576 | I17: =G17/G16*100-100 -> -1.8328921 | J17: =B17+C17+D17-E17-F17-G17 -> 0 | K17: =G17/G16*100-100 -> -1.8328921
A18: 2023 | B18: ='Jati Jawa'!B19+'Rimba Jawa'!B19+'Rimba Luar Jawa'!B19 -> 3772327.3 | C18: ='Jati Jawa'!C19+'Rimba Jawa'!C19+'Rimba Luar Jawa'!C19 -> 46581.601 | D18: ='Jati Jawa'!D19+'Rimba Jawa'!D19+'Rimba Luar Jawa'!D19 -> 4360.2024 | E18: ='Jati Jawa'!E19+'Rimba Jawa'!E19+'Rimba Luar Jawa'!E19 -> 239754.96 | F18: ='Jati Jawa'!F19+'Rimba Jawa'!F19+'Rimba Luar Jawa'!F19 -> 58134.882 | G18: ='Jati Jawa'!G19+'Rimba Jawa'!G19+'Rimba Luar Jawa'!G19 -> 3525379.2 | H18: =G18/F18 -> 60.641376 | I18: =G18/G17*100-100 -> -6.5463047 | J18: =B18+C18+D18-E18-F18-G18 -> 0 | K18: =G18/G17*100-100 -> -6.5463047
A19: 2024 | B19: ='Jati Jawa'!B20+'Rimba Jawa'!B20+'Rimba Luar Jawa'!B20 -> 3525379.2 | C19: ='Jati Jawa'!C20+'Rimba Jawa'!C20+'Rimba Luar Jawa'!C20 -> 46599.387 | D19: ='Jati Jawa'!D20+'Rimba Jawa'!D20+'Rimba Luar Jawa'!D20 -> 7727.594 | E19: ='Jati Jawa'!E20+'Rimba Jawa'!E20+'Rimba Luar Jawa'!E20 -> 96304.46 | F19: ='Jati Jawa'!F20+'Rimba Jawa'!F20+'Rimba Luar Jawa'!F20 -> 55307.319 | G19: ='Jati Jawa'!G20+'Rimba Jawa'!G20+'Rimba Luar Jawa'!G20 -> 3428094.4 | H19: =G19/F19 -> 61.982654 | I19: =G19/G18*100-100 -> -2.7595555 | J19: =B19+C19+D19-E19-F19-G19 -> 0 | K19: =G19/G18*100-100 -> -2.7595555
F20: =G12/1000 -> 4493.8985 | G20: =(G12-G8)/1000 -> -1112.3946 | I20: =(G10-G9)/1000 -> -596.27796
A21: Neraca Moneter Kayu (miliar Rp) | F21: =F12/1000 -> 47.350504 | G21: =G12/G8*100-100 -> -19.841892
A22: Rincian | B22: Persediaan Awal | C22: Pertumbuhan | D22: Penanaman | E22: Konversi & Kerusakan | F22: Penebangan | G22: Revaluasi | H22: Stok Akhir
A23: 2009 | B23: ='Jati Jawa'!B47+'Rimba Jawa'!B46+'Rimba Luar Jawa'!B46 -> 6465702.8 | C23: ='Jati Jawa'!C47+'Rimba Jawa'!C46+'Rimba Luar Jawa'!C46 -> 53904.98 | D23: ='Jati Jawa'!D47+'Rimba Jawa'!D46+'Rimba Luar Jawa'!D46 -> 6443.2381 | E23: ='Jati Jawa'!E47+'Rimba Jawa'!E46+'Rimba Luar Jawa'!E46 -> 238894.12 | F23: ='Jati Jawa'!F47+'Rimba Jawa'!F46+'Rimba Luar Jawa'!F46 -> 54388.444 | G23: ='Jati Jawa'!G47+'Rimba Jawa'!G46+'Rimba Luar Jawa'!G46 -> 602426.75 | H23: ='Jati Jawa'!H47+'Rimba Jawa'!H46+'Rimba Luar Jawa'!H46 -> 6835195.2
A24: 2010 | B24: ='Jati Jawa'!B48+'Rimba Jawa'!B47+'Rimba Luar Jawa'!B47 -> 6835195.2 | C24: ='Jati Jawa'!C48+'Rimba Jawa'!C47+'Rimba Luar Jawa'!C47 -> 29763.587 | D24: ='Jati Jawa'!D48+'Rimba Jawa'!D47+'Rimba Luar Jawa'!D47 -> 3595.6356 | E24: ='Jati Jawa'!E48+'Rimba Jawa'!E47+'Rimba Luar Jawa'!E47 -> 199226.17 | F24: ='Jati Jawa'!F48+'Rimba Jawa'!F47+'Rimba Luar Jawa'!F47 -> 43210.017 | G24: ='Jati Jawa'!G48+'Rimba Jawa'!G47+'Rimba Luar Jawa'!G47 -> -1868636.5 | H24: ='Jati Jawa'!H48+'Rimba Jawa'!H47+'Rimba Luar Jawa'!H47 -> 4757481.7
A25: 2011 | B25: ='Jati Jawa'!B49+'Rimba Jawa'!B48+'Rimba Luar Jawa'!B48 -> 4757481.7 | C25: ='Jati Jawa'!C49+'Rimba Jawa'!C48+'Rimba Luar Jawa'!C48 -> 8498.601 | D25: ='Jati Jawa'!D49+'Rimba Jawa'!D48+'Rimba Luar Jawa'!D48 -> 1197.4593 | E25: ='Jati Jawa'!E49+'Rimba Jawa'!E48+'Rimba Luar Jawa'!E48 -> 68481.629 | F25: ='Jati Jawa'!F49+'Rimba Jawa'!F48+'Rimba Luar Jawa'!F48 -> 12418.141 | G25: ='Jati Jawa'!G49+'Rimba Jawa'!G48+'Rimba Luar Jawa'!G48 -> -3305244.6 | H25: ='Jati Jawa'!H49+'Rimba Jawa'!H48+'Rimba Luar Jawa'!H48 -> 1381033.5
A26: 2012 | B26: ='Jati Jawa'!B50+'Rimba Jawa'!B49+'Rimba Luar Jawa'!B49 -> 1381033.5 | C26: ='Jati Jawa'!C50+'Rimba Jawa'!C49+'Rimba Luar Jawa'!C49 -> 5979.9178 | D26: ='Jati Jawa'!D50+'Rimba Jawa'!D49+'Rimba Luar Jawa'!D49 -> 1088.9846 | E26: ='Jati Jawa'!E50+'Rimba Jawa'!E49+'Rimba Luar Jawa'!E49 -> 59094.5 | F26: ='Jati Jawa'!F50+'Rimba Jawa'!F49+'Rimba Luar Jawa'!F49 -> 8702.7714 | G26: ='Jati Jawa'!G50+'Rimba Jawa'!G49+'Rimba Luar Jawa'!G49 -> -395922.36 | H26: ='Jati Jawa'!H50+'Rimba Jawa'!H49+'Rimba Luar Jawa'!H49 -> 924382.72 | K26: =B26+C26+D26-E26-F26+G26-H26 -> 0
A27: 2013 | B27: ='Jati Jawa'!B51+'Rimba Jawa'!B50+'Rimba Luar Jawa'!B50 -> 924382.72 | C27: ='Jati Jawa'!C51+'Rimba Jawa'!C50+'Rimba Luar Jawa'!C50 -> 4064.8881 | D27: ='Jati Jawa'!D51+'Rimba Jawa'!D50+'Rimba Luar Jawa'!D50 -> 1504.1311 | E27: ='Jati Jawa'!E51+'Rimba Jawa'!E50+'Rimba Luar Jawa'!E50 -> 12341.657 | F27: ='Jati Jawa'!F51+'Rimba Jawa'!F50+'Rimba Luar Jawa'!F50 -> 5483.811 | G27: ='Jati Jawa'!G51+'Rimba Jawa'!G50+'Rimba Luar Jawa'!G50 -> -210464.51 | H27: ='Jati Jawa'!H51+'Rimba Jawa'!H50+'Rimba Luar Jawa'!H50 -> 701661.76 | K27: =B27+C27+D27-E27-F27+G27-H27 -> 0
A28: 2014 | B28: ='Jati Jawa'!B52+'Rimba Jawa'!B51+'Rimba Luar Jawa'!B51 -> 701661.76 | C28: ='Jati Jawa'!C52+'Rimba Jawa'!C51+'Rimba Luar Jawa'!C51 -> 4013.4808 | D28: ='Jati Jawa'!D52+'Rimba Jawa'!D51+'Rimba Luar Jawa'!D51 -> 1626.2872 | E28: ='Jati Jawa'!E52+'Rimba Jawa'!E51+'Rimba Luar Jawa'!E51 -> 28141.491 | F28: ='Jati Jawa'!F52+'Rimba Jawa'!F51+'Rimba Luar Jawa'!F51 -> 6621.4561 | G28: ='Jati Jawa'!G52+'Rimba Jawa'!G51+'Rimba Luar Jawa'!G51 -> 47446.501 | H28: ='Jati Jawa'!H52+'Rimba Jawa'!H51+'Rimba Luar Jawa'!H51 -> 719985.09 | J28: =H28/H27*100-100 -> 2.611418 | K28: =B28+C28+D28-E28-F28+G28-H28 -> 0
A29: 2015 | B29: ='Jati Jawa'!B53+'Rimba Jawa'!B52+'Rimba Luar Jawa'!B52 -> 719985.09 | C29: ='Jati Jawa'!C53+'Rimba Jawa'!C52+'Rimba Luar Jawa'!C52 -> 3927.0238 | D29: ='Jati Jawa'!D53+'Rimba Jawa'!D52+'Rimba Luar Jawa'!D52 -> 2284.5052 | E29: ='Jati Jawa'!E53+'Rimba Jawa'!E52+'Rimba Luar Jawa'!E52 -> 89344.514 | F29: ='Jati Jawa'!F53+'Rimba Jawa'!F52+'Rimba Luar Jawa'!F52 -> 6545.6817 | G29: ='Jati Jawa'!G53+'Rimba Jawa'!G52+'Rimba Luar Jawa'!G52 -> -1472.309 | H29: ='Jati Jawa'!H53+'Rimba Jawa'!H52+'Rimba Luar Jawa'!H52 -> 628834.11 | J29: =H29/H28*100-100 -> -12.66012 | K29: =B29+C29+D29-E29-F29+G29-H29 -> 0
A30: 2016 | B30: ='Jati Jawa'!B54+'Rimba Jawa'!B53+'Rimba Luar Jawa'!B53 -> 628834.11 | C30: ='Jati Jawa'!C54+'Rimba Jawa'!C53+'Rimba Luar Jawa'!C53 -> 4254.0726 | D30: ='Jati Jawa'!D54+'Rimba Jawa'!D53+'Rimba Luar Jawa'!D53 -> 2856.7213 | E30: ='Jati Jawa'!E54+'Rimba Jawa'!E53+'Rimba Luar Jawa'!E53 -> 32133.043 | F30: ='Jati Jawa'!F54+'Rimba Jawa'!F53+'Rimba Luar Jawa'!F53 -> 7473.951 | G30: ='Jati Jawa'!G54+'Rimba Jawa'!G53+'Rimba Luar Jawa'!G53 -> 85161.98 | H30: ='Jati Jawa'!H54+'Rimba Jawa'!H53+'Rimba Luar Jawa'!H53 -> 681499.89 | J30: =H30/H29*100-100 -> 8.3751469 | K30: =B30+C30+D30-E30-F30+G30-H30 -> 0
A31: 2017 | B31: ='Jati Jawa'!B55+'Rimba Jawa'!B54+'Rimba Luar Jawa'!B54 -> 681499.89 | C31: ='Jati Jawa'!C55+'Rimba Jawa'!C54+'Rimba Luar Jawa'!C54 -> 4901.6472 | D31: ='Jati Jawa'!D55+'Rimba Jawa'!D54+'Rimba Luar Jawa'!D54 -> 1401.2454 | E31: ='Jati Jawa'!E55+'Rimba Jawa'!E54+'Rimba Luar Jawa'!E54 -> 28424.101 | F31: ='Jati Jawa'!F55+'Rimba Jawa'!F54+'Rimba Luar Jawa'!F54 -> 8951.9533 | G31: ='Jati Jawa'!G55+'Rimba Jawa'!G54+'Rimba Luar Jawa'!G54 -> 99106.76 | H31: ='Jati Jawa'!H55+'Rimba Jawa'!H54+'Rimba Luar Jawa'!H54 -> 749533.49 | I31: =H31/H27*100-100 -> 6.8226213 | J31: =H31/H30*100-100 -> 9.9829215 | K31: =B31+C31+D31-E31-F31+G31-H31 -> 0
A32: 2018 | B32: ='Jati Jawa'!B56+'Rimba Jawa'!B55+'Rimba Luar Jawa'!B55 -> 749533.49 | C32: ='Jati Jawa'!C56+'Rimba Jawa'!C55+'Rimba Luar Jawa'!C55 -> 5087.0422 | D32: ='Jati Jawa'!D56+'Rimba Jawa'!D55+'Rimba Luar Jawa'!D55 -> 1773.0106 | E32: ='Jati Jawa'!E56+'Rimba Jawa'!E55+'Rimba Luar Jawa'!E55 -> 24829.202 | F32: ='Jati Jawa'!F56+'Rimba Jawa'!F55+'Rimba Luar Jawa'!F55 -> 9094.5459 | G32: ='Jati Jawa'!G56+'Rimba Jawa'!G55+'Rimba Luar Jawa'!G55 -> 17814.209 | H32: ='Jati Jawa'!H56+'Rimba Jawa'!H55+'Rimba Luar Jawa'!H55 -> 740284 | I32: =H32/H28*100-100 -> 2.8193525 | J32: =H32/H31*100-100 -> -1.2340324 | K32: =B32+C32+D32-E32-F32+G32-H32 -> 0
A33: 2019 | B33: ='Jati Jawa'!B57+'Rimba Jawa'!B56+'Rimba Luar Jawa'!B56 -> 740284 | C33: ='Jati Jawa'!C57+'Rimba Jawa'!C56+'Rimba Luar Jawa'!C56 -> 6109.567 | D33: ='Jati Jawa'!D57+'Rimba Jawa'!D56+'Rimba Luar Jawa'!D56 -> 3075.1912 | E33: ='Jati Jawa'!E57+'Rimba Jawa'!E56+'Rimba Luar Jawa'!E56 -> 76926.656 | F33: ='Jati Jawa'!F57+'Rimba Jawa'!F56+'Rimba Luar Jawa'!F56 -> 11560.738 | G33: ='Jati Jawa'!G57+'Rimba Jawa'!G56+'Rimba Luar Jawa'!G56 -> 157217.01 | H33: ='Jati Jawa'!H57+'Rimba Jawa'!H56+'Rimba Luar Jawa'!H56 -> 818198.38 | I33: =H33/H29*100-100 -> 30.113549 | J33: =H33/H32*100-100 -> 10.52493 | K33: =B33+C33+D33-E33-F33+G33-H33 -> 0
A34: 2020 | B34: ='Jati Jawa'!B58+'Rimba Jawa'!B57+'Rimba Luar Jawa'!B57 -> 818198.38 | C34: ='Jati Jawa'!C58+'Rimba Jawa'!C57+'Rimba Luar Jawa'!C57 -> 7281.4543 | D34: ='Jati Jawa'!D58+'Rimba Jawa'!D57+'Rimba Luar Jawa'!D57 -> 3032.543 | E34: ='Jati Jawa'!E58+'Rimba Jawa'!E57+'Rimba Luar Jawa'!E57 -> 19002.634 | F34: ='Jati Jawa'!F58+'Rimba Jawa'!F57+'Rimba Luar Jawa'!F57 -> 14524.238 | G34: ='Jati Jawa'!G58+'Rimba Jawa'!G57+'Rimba Luar Jawa'!G57 -> 157930.02 | H34: ='Jati Jawa'!H58+'Rimba Jawa'!H57+'Rimba Luar Jawa'!H57 -> 952915.52 | I34: =H34/H30*100-100 -> 39.826217 | J34: =H34/H33*100-100 -> 16.465095 | K34: =B34+C34+D34-E34-F34+G34-H34 -> 0
A35: 2021 | B35: ='Jati Jawa'!B59+'Rimba Jawa'!B58+'Rimba Luar Jawa'!B58 -> 952915.52 | C35: ='Jati Jawa'!C59+'Rimba Jawa'!C58+'Rimba Luar Jawa'!C58 -> 8648.7655 | D35: ='Jati Jawa'!D59+'Rimba Jawa'!D58+'Rimba Luar Jawa'!D58 -> 1586.855 | E35: ='Jati Jawa'!E59+'Rimba Jawa'!E58+'Rimba Luar Jawa'!E58 -> 36818.486 | F35: ='Jati Jawa'!F59+'Rimba Jawa'!F58+'Rimba Luar Jawa'!F58 -> 18268.671 | G35: ='Jati Jawa'!G59+'Rimba Jawa'!G58+'Rimba Luar Jawa'!G58 -> 185909.56 | H35: ='Jati Jawa'!H59+'Rimba Jawa'!H58+'Rimba Luar Jawa'!H58 -> 1093973.5 | I35: =H35/H31*100-100 -> 45.953925 | J35: =H35/H34*100-100 -> 14.802784 | K35: =B35+C35+D35-E35-F35+G35-H35 -> 0
A36: 2022 | B36: ='Jati Jawa'!B60+'Rimba Jawa'!B59+'Rimba Luar Jawa'!B59 -> 1093973.5 | C36: ='Jati Jawa'!C60+'Rimba Jawa'!C59+'Rimba Luar Jawa'!C59 -> 9402.4752 | D36: ='Jati Jawa'!D60+'Rimba Jawa'!D59+'Rimba Luar Jawa'!D59 -> 2447.6811 | E36: ='Jati Jawa'!E60+'Rimba Jawa'!E59+'Rimba Luar Jawa'!E59 -> 20409.484 | F36: ='Jati Jawa'!F60+'Rimba Jawa'!F59+'Rimba Luar Jawa'!F59 -> 20145.685 | G36: ='Jati Jawa'!G60+'Rimba Jawa'!G59+'Rimba Luar Jawa'!G59 -> 102581.11 | H36: ='Jati Jawa'!H60+'Rimba Jawa'!H59+'Rimba Luar Jawa'!H59 -> 1167849.6 | I36: =H36/H32*100-100 -> 57.756974 | J36: =H36/H35*100-100 -> 6.7530059 | K36: =B36+C36+D36-E36-F36+G36-H36 -> 0
A37: 2023 | B37: ='Jati Jawa'!B61+'Rimba Jawa'!B60+'Rimba Luar Jawa'!B60 -> 1167849.6 | C37: ='Jati Jawa'!C61+'Rimba Jawa'!C60+'Rimba Luar Jawa'!C60 -> 12123.111 | D37: ='Jati Jawa'!D61+'Rimba Jawa'!D60+'Rimba Luar Jawa'!D60 -> 2087.1019 | E37: ='Jati Jawa'!E61+'Rimba Jawa'!E60+'Rimba Luar Jawa'!E60 -> 114961.57 | F37: ='Jati Jawa'!F61+'Rimba Jawa'!F60+'Rimba Luar Jawa'!F60 -> 27656.598 | G37: ='Jati Jawa'!G61+'Rimba Jawa'!G60+'Rimba Luar Jawa'!G60 -> 344785.75 | H37: ='Jati Jawa'!H61+'Rimba Jawa'!H60+'Rimba Luar Jawa'!H60 -> 1384227.4 | I37: =H37/H33*100-100 -> 69.179929 | J37: =H37/H36*100-100 -> 18.527881 | K37: =B37+C37+D37-E37-F37+G37-H37 -> 0
A38: 2024 | B38: ='Jati Jawa'!B62+'Rimba Jawa'!B61+'Rimba Luar Jawa'!B61 -> 1384227.4 | C38: ='Jati Jawa'!C62+'Rimba Jawa'!C61+'Rimba Luar Jawa'!C61 -> 11987.894 | D38: ='Jati Jawa'!D62+'Rimba Jawa'!D61+'Rimba Luar Jawa'!D61 -> 3715.5482 | E38: ='Jati Jawa'!E62+'Rimba Jawa'!E61+'Rimba Luar Jawa'!E61 -> 45904.98 | F38: ='Jati Jawa'!F62+'Rimba Jawa'!F61+'Rimba Luar Jawa'!F61 -> 26333.124 | G38: ='Jati Jawa'!G62+'Rimba Jawa'!G61+'Rimba Luar Jawa'!G61 -> -3776.6979 | H38: ='Jati Jawa'!H62+'Rimba Jawa'!H61+'Rimba Luar Jawa'!H61 -> 1323916.1 | I38: =H38/H34*100-100 -> 38.933205 | J38: =H38/H37*100-100 -> -4.3570412 | K38: =B38+C38+D38-E38-F38+G38-H38 -> 0
H39: =H31/1000 -> 749.53349
H40: =H24-B25 -> 0
...

Sheet Jati Jawa
A1: Tabel 1. Neraca Fisik Jati Jawa (000m3)
C2: growth | D2: planting | E2: losses | F2: harvesting
A3: Rincian | B3: Persediaan Awal | C3: Pertumbuhan | D3: Penanaman | E3: Konversi & Kerusakan | F3: Penebangan | G3: Persediaan Akhir | H3: Perkiraan Cadangan | I3: Laju Persediaan Akhir | J3: Cek Persediaan Akhir
A4: 2008 | B4: ='[1]Jati Jawa'!$T$8 -> 87707.889 | C4: ='[1]Jati Jawa'!$T$9 -> 4732.2962 | D4: ='[1]Jati Jawa'!$T$10 -> 32.016 | E4: ='[1]Jati Jawa'!$T$11 -> 329.24483 | F4: ='[1]Jati Jawa'!$T$12 -> 477.71 | G4: ='[1]Jati Jawa'!$T$14 -> 91665.246 | H4: =G4/F4 -> 191.88471 | J4: =B4+C4+D4-E4-F4-G4 -> 0
