Workbook

Sheet Rekap Hutan Indonesia
A1: Neraca Fisik dan Moneter
A2: Sumber Daya Hutan Indonesia
A4: Perincian | B4: 1990 | C4: 1991 | D4: 1992 | E4: 1993 | F4: 1994 | G4: 1995 | H4: 1996 | I4: 1997 | J4: 1998 | K4: 1999 | L4: 2000 | M4: 2001 | N4: 2002 | O4: 2003 | P4: 2004 | Q4: 2005 | R4: 2006 | S4: 2007 | T4: 2008 | U4: 2009 | V4: 2010 | W4: 2011 | X4: 2012 | Y4: 2013 | Z4: 2014 | AA4: 2015 | AB4: 2016 | AF4: 2004 | AG4: 2005 | AH4: 2006 | AI4: 2007 | AJ4: 2008 | AK4: 2009 | AL4: 2010 | AM4: 2011 | AN4: 2012 | AO4: 2013 | AP4: 2014 | AQ4: 2015 | AR4: 2016
A6: I. Neraca Fisik (000 M3) | AF6: Laju Pertumbuhan
A8: 1. Persediaan awal | B8: ='Rimba Luar Jawa'!B8+'Rimba Jawa'!B8+'Jati Jawa'!B8 -> 8644424.6 | C8: ='Rimba Luar Jawa'!C8+'Rimba Jawa'!C8+'Jati Jawa'!C8 -> 8642977.8 | D8: ='Rimba Luar Jawa'!D8+'Rimba Jawa'!D8+'Jati Jawa'!D8 -> 8640252.7 | E8: ='Rimba Luar Jawa'!E8+'Rimba Jawa'!E8+'Jati Jawa'!E8 -> 8619007.2 | F8: ='Rimba Luar Jawa'!F8+'Rimba Jawa'!F8+'Jati Jawa'!F8 -> 8589076 | G8: ='Rimba Luar Jawa'!G8+'Rimba Jawa'!G8+'Jati Jawa'!G8 -> 8569181.9 | H8: ='Rimba Luar Jawa'!H8+'Rimba Jawa'!H8+'Jati Jawa'!H8 -> 8548707.6 | I8: ='Rimba Luar Jawa'!I8+'Rimba Jawa'!I8+'Jati Jawa'!I8 -> 8535616.3 | ... AB8: ='Rimba Luar Jawa'!AB8+'Rimba Jawa'!AB8+'Jati Jawa'!AB8 -> 4827604.5 | AF8: =P8/O8*100-100 -> -1.782915 | AG8: =Q8/P8*100-100 -> -2.1695468 | AH8: =R8/Q8*100-100 -> -3.0601215 | AI8: =S8/R8*100-100 -> -3.7730208 | AJ8: =T8/S8*100-100 -> -4.0247219 | AK8: =U8/T8*100-100 -> -2.8620096 | AL8: =V8/U8*100-100 -> -3.2995921 | AM8: =W8/V8*100-100 -> -3.8096553 | ... AR8: =AB8/AA8*100-100 -> -10.993564
A9: 2. Pertumbuhan | B9: ='Rimba Luar Jawa'!B9+'Rimba Jawa'!B9+'Jati Jawa'!B9 -> 41982.9 | C9: ='Rimba Luar Jawa'!C9+'Rimba Jawa'!C9+'Jati Jawa'!C9 -> 43088.146 | D9: ='Rimba Luar Jawa'!D9+'Rimba Jawa'!D9+'Jati Jawa'!D9 -> 44320.021 | E9: ='Rimba Luar Jawa'!E9+'Rimba Jawa'!E9+'Jati Jawa'!E9 -> 45618.543 | F9: ='Rimba Luar Jawa'!F9+'Rimba Jawa'!F9+'Jati Jawa'!F9 -> 47003.13 | G9: ='Rimba Luar Jawa'!G9+'Rimba Jawa'!G9+'Jati Jawa'!G9 -> 48595.51 | H9: ='Rimba Luar Jawa'!H9+'Rimba Jawa'!H9+'Jati Jawa'!H9 -> 54426.46 | I9: ='Rimba Luar Jawa'!I9+'Rimba Jawa'!I9+'Jati Jawa'!I9 -> 55032.56 | ... AB9: ='Rimba Luar Jawa'!AB9+'Rimba Jawa'!AB9+'Jati Jawa'!AB9 -> 39130.339 | AF9: =P9/O9*100-100 -> 7.1523339 | AG9: =Q9/P9*100-100 -> -7.79793 | AH9: =R9/Q9*100-100 -> -3.1756713 | AI9: =S9/R9*100-100 -> -0.67590124 | AJ9: =T9/S9*100-100 -> -3.1087404 | AK9: =U9/T9*100-100 -> 2.1744234 | AL9: =V9/U9*100-100 -> -0.76994235 | AM9: =W9/V9*100-100 -> 1.143182 | ... AR9: =AB9/AA9*100-100 -> -16.387397
A10: 3. Penanaman | B10: ='Rimba Luar Jawa'!B10+'Rimba Jawa'!B10+'Jati Jawa'!B10 -> 790 | C10: ='Rimba Luar Jawa'!C10+'Rimba Jawa'!C10+'Jati Jawa'!C10 -> 1152.3 | D10: ='Rimba Luar Jawa'!D10+'Rimba Jawa'!D10+'Jati Jawa'!D10 -> 1131.2 | E10: ='Rimba Luar Jawa'!E10+'Rimba Jawa'!E10+'Jati Jawa'!E10 -> 1601.8 | F10: ='Rimba Luar Jawa'!F10+'Rimba Jawa'!F10+'Jati Jawa'!F10 -> 1367.46 | G10: ='Rimba Luar Jawa'!G10+'Rimba Jawa'!G10+'Jati Jawa'!G10 -> 1674.2 | H10: ='Rimba Luar Jawa'!H10+'Rimba Jawa'!H10+'Jati Jawa'!H10 -> 2654.03 | I10: ='Rimba Luar Jawa'!I10+'Rimba Jawa'!I10+'Jati Jawa'!I10 -> 2266.59 | ... AB10: ='Rimba Luar Jawa'!AB10+'Rimba Jawa'!AB10+'Jati Jawa'!AB10 -> 17114.782 | AF10: =P10/O10*100-100 -> -5.0410739 | AG10: =Q10/P10*100-100 -> -1.5850762 | AH10: =R10/Q10*100-100 -> 30.192958 | AI10: =S10/R10*100-100 -> -10.906165 | AJ10: =T10/S10*100-100 -> 25.710872 | AK10: =U10/T10*100-100 -> -24.434225 | AL10: =V10/U10*100-100 -> -25.51128 | AM10: =W10/V10*100-100 -> 6.8841612 | ... AR10: =AB10/AA10*100-100 -> 9.0957365
A11: 4. Konversi & kerusakan | B11: ='Rimba Luar Jawa'!B11+'Rimba Jawa'!B11+'Jati Jawa'!B11 -> 15665.8 | C11: ='Rimba Luar Jawa'!C11+'Rimba Jawa'!C11+'Jati Jawa'!C11 -> 18825.8 | D11: ='Rimba Luar Jawa'!D11+'Rimba Jawa'!D11+'Jati Jawa'!D11 -> 38007.4 | E11: ='Rimba Luar Jawa'!E11+'Rimba Jawa'!E11+'Jati Jawa'!E11 -> 47597.7 | F11: ='Rimba Luar Jawa'!F11+'Rimba Jawa'!F11+'Jati Jawa'!F11 -> 38563.3 | G11: ='Rimba Luar Jawa'!G11+'Rimba Jawa'!G11+'Jati Jawa'!G11 -> 41077.1 | H11: ='Rimba Luar Jawa'!H11+'Rimba Jawa'!H11+'Jati Jawa'!H11 -> 40078.83 | I11: ='Rimba Luar Jawa'!I11+'Rimba Jawa'!I11+'Jati Jawa'!I11 -> 80250.98 | ... AB11: ='Rimba Luar Jawa'!AB11+'Rimba Jawa'!AB11+'Jati Jawa'!AB11 -> 193747.58 | AF11: =P11/O11*100-100 -> 17.358154 | AG11: =Q11/P11*100-100 -> 19.973232 | AH11: =R11/Q11*100-100 -> 19.870452 | AI11: =S11/R11*100-100 -> -3.5595066 | AJ11: =T11/S11*100-100 -> -29.297886 | AK11: =U11/T11*100-100 -> 9.9519626 | AL11: =V11/U11*100-100 -> 9.3871395 | AM11: =W11/V11*100-100 -> 11.621337 | ... AR11: =AB11/AA11*100-100 -> -68.412324
A12: 5. Penebangan | B12: ='Rimba Luar Jawa'!B12+'Rimba Jawa'!B12+'Jati Jawa'!B12 -> 28553.9 | C12: ='Rimba Luar Jawa'!C12+'Rimba Jawa'!C12+'Jati Jawa'!C12 -> 28139.7 | D12: ='Rimba Luar Jawa'!D12+'Rimba Jawa'!D12+'Jati Jawa'!D12 -> 28689.4 | E12: ='Rimba Luar Jawa'!E12+'Rimba Jawa'!E12+'Jati Jawa'!E12 -> 29553.8 | F12: ='Rimba Luar Jawa'!F12+'Rimba Jawa'!F12+'Jati Jawa'!F12 -> 29701.4 | G12: ='Rimba Luar Jawa'!G12+'Rimba Jawa'!G12+'Jati Jawa'!G12 -> 29666.9 | H12: ='Rimba Luar Jawa'!H12+'Rimba Jawa'!H12+'Jati Jawa'!H12 -> 30092.97 | I12: ='Rimba Luar Jawa'!I12+'Rimba Jawa'!I12+'Jati Jawa'!I12 -> 34230.235 | ... AB12: ='Rimba Luar Jawa'!AB12+'Rimba Jawa'!AB12+'Jati Jawa'!AB12 -> 45208.181 | AF12: =P12/O12*100-100 -> 1.6383374 | AG12: =Q12/P12*100-100 -> 75.132315 | AH12: =R12/Q12*100-100 -> -9.5775418 | AI12: =S12/R12*100-100 -> 44.22077 | AJ12: =T12/S12*100-100 -> -11.490658 | AK12: =U12/T12*100-100 -> 4.6060709 | AL12: =V12/U12*100-100 -> 4.9141543 | AM12: =W12/V12*100-100 -> -6.4483877 | ... AR12: =AB12/AA12*100-100 -> -0.42449946
A13: 6. Perubahan Neto | B13: ='Rimba Luar Jawa'!B13+'Rimba Jawa'!B13+'Jati Jawa'!B13 -> -1446.8 | C13: ='Rimba Luar Jawa'!C13+'Rimba Jawa'!C13+'Jati Jawa'!C13 -> -2725.0544 | D13: ='Rimba Luar Jawa'!D13+'Rimba Jawa'!D13+'Jati Jawa'!D13 -> -21245.579 | E13: ='Rimba Luar Jawa'!E13+'Rimba Jawa'!E13+'Jati Jawa'!E13 -> -29931.157 | F13: ='Rimba Luar Jawa'!F13+'Rimba Jawa'!F13+'Jati Jawa'!F13 -> -19894.11 | G13: ='Rimba Luar Jawa'!G13+'Rimba Jawa'!G13+'Jati Jawa'!G13 -> -20474.29 | H13: ='Rimba Luar Jawa'!H13+'Rimba Jawa'!H13+'Jati Jawa'!H13 -> -13091.31 | I13: ='Rimba Luar Jawa'!I13+'Rimba Jawa'!I13+'Jati Jawa'!I13 -> -57182.065 | ... AB13: ='Rimba Luar Jawa'!AB13+'Rimba Jawa'!AB13+'Jati Jawa'!AB13 -> -182710.64 | AF13: =P13/O13*100-100 -> 19.515832 | AG13: =Q13/P13*100-100 -> 37.988758 | AH13: =R13/Q13*100-100 -> 19.523417 | AI13: =S13/R13*100-100 -> 2.6463543 | AJ13: =T13/S13*100-100 -> -31.751267 | AK13: =U13/T13*100-100 -> 11.989752 | AL13: =V13/U13*100-100 -> 11.648715 | AM13: =W13/V13*100-100 -> 9.8940882 | ... AR13: =AB13/AA13*100-100 -> -69.358142
A14: 7. Persediaan akhir | B14: ='Rimba Luar Jawa'!B14+'Rimba Jawa'!B14+'Jati Jawa'!B14 -> 8642977.8 | C14: ='Rimba Luar Jawa'!C14+'Rimba Jawa'!C14+'Jati Jawa'!C14 -> 8640252.7 | D14: ='Rimba Luar Jawa'!D14+'Rimba Jawa'!D14+'Jati Jawa'!D14 -> 8619007.2 | E14: ='Rimba Luar Jawa'!E14+'Rimba Jawa'!E14+'Jati Jawa'!E14 -> 8589076 | F14: ='Rimba Luar Jawa'!F14+'Rimba Jawa'!F14+'Jati Jawa'!F14 -> 8569181.9 | G14: ='Rimba Luar Jawa'!G14+'Rimba Jawa'!G14+'Jati Jawa'!G14 -> 8548707.6 | H14: ='Rimba Luar Jawa'!H14+'Rimba Jawa'!H14+'Jati Jawa'!H14 -> 8535616.3 | I14: ='Rimba Luar Jawa'!I14+'Rimba Jawa'!I14+'Jati Jawa'!I14 -> 8478434.2 | ... AB14: ='Rimba Luar Jawa'!AB14+'Rimba Jawa'!AB14+'Jati Jawa'!AB14 -> 4644893.8 | AF14: =P14/O14*100-100 -> -2.1695468 | AG14: =Q14/P14*100-100 -> -3.0601215 | AH14: =R14/Q14*100-100 -> -3.7730208 | AI14: =S14/R14*100-100 -> -4.0247219 | AJ14: =T14/S14*100-100 -> -2.8620096 | AK14: =U14/T14*100-100 -> -3.2995921 | AL14: =V14/U14*100-100 -> -3.8096553 | AM14: =W14/V14*100-100 -> -4.3523973 | ... AR14: =AB14/AA14*100-100 -> -3.7847062
A16: III. Neraca Moneter
A17: (Miliar Rp)
A19: 1. Persediaan awal | B19: ='Rimba Luar Jawa'!B21+'Rimba Jawa'!B21+'Jati Jawa'!B21 -> 74108.902 | C19: ='Rimba Luar Jawa'!C21+'Rimba Jawa'!C21+'Jati Jawa'!C21 -> 83802.55 | D19: ='Rimba Luar Jawa'!D21+'Rimba Jawa'!D21+'Jati Jawa'!D21 -> 97018.89 | E19: ='Rimba Luar Jawa'!E21+'Rimba Jawa'!E21+'Jati Jawa'!E21 -> 92652.724 | F19: ='Rimba Luar Jawa'!F21+'Rimba Jawa'!F21+'Jati Jawa'!F21 -> 104769.1 | G19: ='Rimba Luar Jawa'!G21+'Rimba Jawa'!G21+'Jati Jawa'!G21 -> 128642.89 | H19: ='Rimba Luar Jawa'!H21+'Rimba Jawa'!H21+'Jati Jawa'!H21 -> 138837.71 | I19: ='Rimba Luar Jawa'!I21+'Rimba Jawa'!I21+'Jati Jawa'!I21 -> 149329.52 | ... AB19: ='Rimba Luar Jawa'!AB21+'Rimba Jawa'!AB21+'Jati Jawa'!AB21 -> 1001943.7 | AF19: =P19/O19*100-100 -> 4.2177187 | AG19: =Q19/P19*100-100 -> 7.123564 | AH19: =R19/Q19*100-100 -> 10.023692 | AI19: =S19/R19*100-100 -> 37.325528 | AJ19: =T19/S19*100-100 -> 14.371024 | AK19: =U19/T19*100-100 -> 7.7994752 | AL19: =V19/U19*100-100 -> 6.1733903 | AM19: =W19/V19*100-100 -> -0.086126526 | ... AR19: =AB19/AA19*100-100 -> -7.3640577
A20: 2. Pertumbuhan | B20: ='Rimba Luar Jawa'!B22+'Rimba Jawa'!B22+'Jati Jawa'!B22 -> 689.56159 | C20: ='Rimba Luar Jawa'!C22+'Rimba Jawa'!C22+'Jati Jawa'!C22 -> 686.14115 | D20: ='Rimba Luar Jawa'!D22+'Rimba Jawa'!D22+'Jati Jawa'!D22 -> 654.21251 | E20: ='Rimba Luar Jawa'!E22+'Rimba Jawa'!E22+'Jati Jawa'!E22 -> 1036.6145 | F20: ='Rimba Luar Jawa'!F22+'Rimba Jawa'!F22+'Jati Jawa'!F22 -> 1466.4377 | G20: ='Rimba Luar Jawa'!G22+'Rimba Jawa'!G22+'Jati Jawa'!G22 -> 1626.3811 | H20: ='Rimba Luar Jawa'!H22+'Rimba Jawa'!H22+'Jati Jawa'!H22 -> 2001.1504 | I20: ='Rimba Luar Jawa'!I22+'Rimba Jawa'!I22+'Jati Jawa'!I22 -> 2825.251 | ... AB20: ='Rimba Luar Jawa'!AB22+'Rimba Jawa'!AB22+'Jati Jawa'!AB22 -> -2525.7221 | AF20: =P20/O20*100-100 -> 17.068992 | AG20: =Q20/P20*100-100 -> -3.2775169 | AH20: =R20/Q20*100-100 -> 42.184283 | AI20: =S20/R20*100-100 -> 18.655438 | AJ20: =T20/S20*100-100 -> -0.79609712 | AK20: =U20/T20*100-100 -> 8.7516055 | AL20: =V20/U20*100-100 -> -0.36677119 | AM20: =W20/V20*100-100 -> -10.265108 | ... AR20: =AB20/AA20*100-100 -> -115.86664
A21: 3. Penanaman | B21: ='Rimba Luar Jawa'!B23+'Rimba Jawa'!B23+'Jati Jawa'!B23 -> 9.7480176 | C21: ='Rimba Luar Jawa'!C23+'Rimba Jawa'!C23+'Jati Jawa'!C23 -> 14.128113 | D21: ='Rimba Luar Jawa'!D23+'Rimba Jawa'!D23+'Jati Jawa'!D23 -> 12.869787 | E21: ='Rimba Luar Jawa'!E23+'Rimba Jawa'!E23+'Jati Jawa'!E23 -> 21.547158 | F21: ='Rimba Luar Jawa'!F23+'Rimba Jawa'!F23+'Jati Jawa'!F23 -> 23.634181 | G21: ='Rimba Luar Jawa'!G23+'Rimba Jawa'!G23+'Jati Jawa'!G23 -> 30.60233 | H21: ='Rimba Luar Jawa'!H23+'Rimba Jawa'!H23+'Jati Jawa'!H23 -> 45.795587 | I21: ='Rimba Luar Jawa'!I23+'Rimba Jawa'!I23+'Jati Jawa'!I23 -> 44.783644 | ... AB21: ='Rimba Luar Jawa'!AB23+'Rimba Jawa'!AB23+'Jati Jawa'!AB23 -> 2839.3617 | AF21: =P21/O21*100-100 -> 3.1399899 | AG21: =Q21/P21*100-100 -> 12.682957 | AH21: =R21/Q21*100-100 -> 81.363859 | AI21: =S21/R21*100-100 -> 9.2522886 | AJ21: =T21/S21*100-100 -> 32.571534 | AK21: =U21/T21*100-100 -> -18.262002 | AL21: =V21/U21*100-100 -> -21.735246 | AM21: =W21/V21*100-100 -> 10.479551 | ... AR21: =AB21/AA21*100-100 -> 9.9110494
A22: 4. Konversi & kerusakan | B22: ='Rimba Luar Jawa'!B24+'Rimba Jawa'!B24+'Jati Jawa'!B24 -> 157.28271 | C22: ='Rimba Luar Jawa'!C24+'Rimba Jawa'!C24+'Jati Jawa'!C24 -> 214.51114 | D22: ='Rimba Luar Jawa'!D24+'Rimba Jawa'!D24+'Jati Jawa'!D24 -> 407.81127 | E22: ='Rimba Luar Jawa'!E24+'Rimba Jawa'!E24+'Jati Jawa'!E24 -> 579.8117 | F22: ='Rimba Luar Jawa'!F24+'Rimba Jawa'!F24+'Jati Jawa'!F24 -> 578.67353 | G22: ='Rimba Luar Jawa'!G24+'Rimba Jawa'!G24+'Jati Jawa'!G24 -> 660.4917 | H22: ='Rimba Luar Jawa'!H24+'Rimba Jawa'!H24+'Jati Jawa'!H24 -> 693.76421 | I22: ='Rimba Luar Jawa'!I24+'Rimba Jawa'!I24+'Jati Jawa'!I24 -> 1386.6881 | ... AB22: ='Rimba Luar Jawa'!AB24+'Rimba Jawa'!AB24+'Jati Jawa'!AB24 -> 31195.557 | AF22: =P22/O22*100-100 -> 26.700455 | AG22: =Q22/P22*100-100 -> 36.503484 | AH22: =R22/Q22*100-100 -> 67.472181 | AI22: =S22/R22*100-100 -> 13.593828 | AJ22: =T22/S22*100-100 -> -20.017502 | AK22: =U22/T22*100-100 -> 19.683742 | AL22: =V22/U22*100-100 -> 13.958352 | AM22: =W22/V22*100-100 -> 17.313094 | ... AR22: =AB22/AA22*100-100 -> -69.136929
A23: 5. Penebangan | B23: ='Rimba Luar Jawa'!B25+'Rimba Jawa'!B25+'Jati Jawa'!B25 -> 349.11397 | C23: ='Rimba Luar Jawa'!C25+'Rimba Jawa'!C25+'Jati Jawa'!C25 -> 369.30281 | D23: ='Rimba Luar Jawa'!D25+'Rimba Jawa'!D25+'Jati Jawa'!D25 -> 347.58733 | E23: ='Rimba Luar Jawa'!E25+'Rimba Jawa'!E25+'Jati Jawa'!E25 -> 463.06348 | F23: ='Rimba Luar Jawa'!F25+'Rimba Jawa'!F25+'Jati Jawa'!F25 -> 602.22903 | G23: ='Rimba Luar Jawa'!G25+'Rimba Jawa'!G25+'Jati Jawa'!G25 -> 649.1225 | H23: ='Rimba Luar Jawa'!H25+'Rimba Jawa'!H25+'Jati Jawa'!H25 -> 666.73428 | I23: ='Rimba Luar Jawa'!I25+'Rimba Jawa'!I25+'Jati Jawa'!I25 -> 876.02304 | ... AB23: ='Rimba Luar Jawa'!AB25+'Rimba Jawa'!AB25+'Jati Jawa'!AB25 -> 7185.0842 | AF23: =P23/O23*100-100 -> 13.245752 | AG23: =Q23/P23*100-100 -> 77.010719 | AH23: =R23/Q23*100-100 -> 32.55275 | AI23: =S23/R23*100-100 -> 66.319942 | AJ23: =T23/S23*100-100 -> -1.4148499 | AK23: =U23/T23*100-100 -> 12.651127 | AL23: =V23/U23*100-100 -> 8.1422955 | AM23: =W23/V23*100-100 -> -3.4715028 | ... AR23: =AB23/AA23*100-100 -> -7.0745472
A24: 6. Perubahan Neto | B24: ='Rimba Luar Jawa'!B26+'Rimba Jawa'!B26+'Jati Jawa'!B26 -> 192.91293 | C24: ='Rimba Luar Jawa'!C26+'Rimba Jawa'!C26+'Jati Jawa'!C26 -> 116.45531 | D24: ='Rimba Luar Jawa'!D26+'Rimba Jawa'!D26+'Jati Jawa'!D26 -> -88.316307 | E24: ='Rimba Luar Jawa'!E26+'Rimba Jawa'!E26+'Jati Jawa'!E26 -> 15.286464 | F24: ='Rimba Luar Jawa'!F26+'Rimba Jawa'!F26+'Jati Jawa'!F26 -> 309.16929 | G24: ='Rimba Luar Jawa'!G26+'Rimba Jawa'!G26+'Jati Jawa'!G26 -> 347.36928 | H24: ='Rimba Luar Jawa'!H26+'Rimba Jawa'!H26+'Jati Jawa'!H26 -> 686.4475 | I24: ='Rimba Luar Jawa'!I26+'Rimba Jawa'!I26+'Jati Jawa'!I26 -> 607.3235 | ... AB24: ='Rimba Luar Jawa'!AB26+'Rimba Jawa'!AB26+'Jati Jawa'!AB26 -> -38067.001 | AF24: =P24/O24*100-100 -> 36.346619 | AG24: =Q24/P24*100-100 -> 91.430382 | AH24: =R24/Q24*100-100 -> 72.561619 | AI24: =S24/R24*100-100 -> 21.130618 | AJ24: =T24/S24*100-100 -> -25.397314 | AK24: =U24/T24*100-100 -> 25.776982 | AL24: =V24/U24*100-100 -> 20.737669 | AM24: =W24/V24*100-100 -> 23.494361 | ... AR24: =AB24/AA24*100-100 -> -57.847409
A25: 7. Revaluasi | B25: ='Rimba Luar Jawa'!B27+'Rimba Jawa'!B27+'Jati Jawa'!B27 -> 9500.7348 | C25: ='Rimba Luar Jawa'!C27+'Rimba Jawa'!C27+'Jati Jawa'!C27 -> 13099.885 | D25: ='Rimba Luar Jawa'!D27+'Rimba Jawa'!D27+'Jati Jawa'!D27 -> -4277.8497 | E25: ='Rimba Luar Jawa'!E27+'Rimba Jawa'!E27+'Jati Jawa'!E27 -> 12101.093 | F25: ='Rimba Luar Jawa'!F27+'Rimba Jawa'!F27+'Jati Jawa'!F27 -> 23564.616 | G25: ='Rimba Luar Jawa'!G27+'Rimba Jawa'!G27+'Jati Jawa'!G27 -> 9847.4491 | H25: ='Rimba Luar Jawa'!H27+'Rimba Jawa'!H27+'Jati Jawa'!H27 -> 9805.3696 | I25: ='Rimba Luar Jawa'!I27+'Rimba Jawa'!I27+'Jati Jawa'!I27 -> 10279.262 | ... AB25: ='Rimba Luar Jawa'!AB27+'Rimba Jawa'!AB27+'Jati Jawa'!AB27 -> -546755.31 | AF25: =P25/O25*100-100 -> 67.961034 | AG25: =Q25/P25*100-100 -> 57.445775 | AH25: =R25/Q25*100-100 -> 262.15604 | AI25: =S25/R25*100-100 -> -40.606574 | AJ25: =T25/S25*100-100 -> -35.486932 | AK25: =U25/T25*100-100 -> -5.5615188 | AL25: =V25/U25*100-100 -> -64.808413 | AM25: =W25/V25*100-100 -> -96.353451 | ... AR25: =AB25/AA25*100-100 -> -5229.7573
A26: 8. Persediaan akhir | B26: ='Rimba Luar Jawa'!B28+'Rimba Jawa'!B28+'Jati Jawa'!B28 -> 83802.55 | C26: ='Rimba Luar Jawa'!C28+'Rimba Jawa'!C28+'Jati Jawa'!C28 -> 97018.89 | D26: ='Rimba Luar Jawa'!D28+'Rimba Jawa'!D28+'Jati Jawa'!D28 -> 92652.724 | E26: ='Rimba Luar Jawa'!E28+'Rimba Jawa'!E28+'Jati Jawa'!E28 -> 104769.1 | F26: ='Rimba Luar Jawa'!F28+'Rimba Jawa'!F28+'Jati Jawa'!F28 -> 128642.89 | G26: ='Rimba Luar Jawa'!G28+'Rimba Jawa'!G28+'Jati Jawa'!G28 -> 138837.71 | H26: ='Rimba Luar Jawa'!H28+'Rimba Jawa'!H28+'Jati Jawa'!H28 -> 149329.52 | I26: ='Rimba Luar Jawa'!I28+'Rimba Jawa'!I28+'Jati Jawa'!I28 -> 160216.11 | ... AB26: ='Rimba Luar Jawa'!AB28+'Rimba Jawa'!AB28+'Jati Jawa'!AB28 -> 417121.36 | AF26: =P26/O26*100-100 -> 7.123564 | AG26: =Q26/P26*100-100 -> 10.023692 | AH26: =R26/Q26*100-100 -> 37.325528 | AI26: =S26/R26*100-100 -> 14.371024 | AJ26: =T26/S26*100-100 -> 7.7994752 | AK26: =U26/T26*100-100 -> 6.1733903 | AL26: =V26/U26*100-100 -> -0.086126526 | AM26: =W26/V26*100-100 -> -3.6130798 | ... AR26: =AB26/AA26*100-100 -> -58.368781
A31: Neraca Fisik dan Moneter Sumber Daya Hutan Indonesia Konstan
A33: Perincian | B33: 1990 | C33: 1991 | D33: 1992 | E33: 1993 | F33: 1994 | G33: 1995 | H33: 1996 | I33: 1997 | J33: 1998 | K33: 1999 | L33: 2000
A35: I. Neraca Fisik (000 m3)
A37: 1. Persediaan awal | B37: ='Kayu Rimba Luar Jawa slh '!B94+'Kayu Rimba Jawa slh '!B59+'Kayu Jati Jawa slh'!B58 -> 8644424.6 | C37: ='Kayu Rimba Luar Jawa slh '!C94+'Kayu Rimba Jawa slh '!C59+'Kayu Jati Jawa slh'!C58 -> 8642977.8 | D37: ='Kayu Rimba Luar Jawa slh '!D94+'Kayu Rimba Jawa slh '!D59+'Kayu Jati Jawa slh'!D58 -> 8640252.7 | E37: ='Kayu Rimba Luar Jawa slh '!E94+'Kayu Rimba Jawa slh '!E59+'Kayu Jati Jawa slh'!E58 -> 8619007.2 | F37: ='Kayu Rimba Luar Jawa slh '!F94+'Kayu Rimba Jawa slh '!F59+'Kayu Jati Jawa slh'!F58 -> 8589076 | G37: ='Kayu Rimba Luar Jawa slh '!G94+'Kayu Rimba Jawa slh '!G59+'Kayu Jati Jawa slh'!G58 -> 8569181.9 | H37: ='Kayu Rimba Luar Jawa slh '!H94+'Kayu Rimba Jawa slh '!H59+'Kayu Jati Jawa slh'!H58 -> 8548707.6 | I37: ='Kayu Rimba Luar Jawa slh '!I94+'Kayu Rimba Jawa slh '!I59+'Kayu Jati Jawa slh'!I58 -> 8535616.3 | ... L37: ='Kayu Rimba Luar Jawa slh '!L94+'Kayu Rimba Jawa slh '!L59+'Kayu Jati Jawa slh'!L58 -> 8345375.3
A38: 2. Pertumbuhan | B38: ='Kayu Rimba Luar Jawa slh '!B95+'Kayu Rimba Jawa slh '!B60+'Kayu Jati Jawa slh'!B59 -> 41982.9 | C38: ='Kayu Rimba Luar Jawa slh '!C95+'Kayu Rimba Jawa slh '!C60+'Kayu Jati Jawa slh'!C59 -> 43088.146 | D38: ='Kayu Rimba Luar Jawa slh '!D95+'Kayu Rimba Jawa slh '!D60+'Kayu Jati Jawa slh'!D59 -> 44320.021 | E38: ='Kayu Rimba Luar Jawa slh '!E95+'Kayu Rimba Jawa slh '!E60+'Kayu Jati Jawa slh'!E59 -> 45618.543 | F38: ='Kayu Rimba Luar Jawa slh '!F95+'Kayu Rimba Jawa slh '!F60+'Kayu Jati Jawa slh'!F59 -> 47003.13 | G38: ='Kayu Rimba Luar Jawa slh '!G95+'Kayu Rimba Jawa slh '!G60+'Kayu Jati Jawa slh'!G59 -> 48595.51 | H38: ='Kayu Rimba Luar Jawa slh '!H95+'Kayu Rimba Jawa slh '!H60+'Kayu Jati Jawa slh'!H59 -> 54426.46 | I38: ='Kayu Rimba Luar Jawa slh '!I95+'Kayu Rimba Jawa slh '!I60+'Kayu Jati Jawa slh'!I59 -> 55032.56 | ... L38: ='Kayu Rimba Luar Jawa slh '!L95+'Kayu Rimba Jawa slh '!L60+'Kayu Jati Jawa slh'!L59 -> 62462.422
A39: 3. Penanaman | B39: ='Kayu Rimba Luar Jawa slh '!B96+'Kayu Rimba Jawa slh '!B61+'Kayu Jati Jawa slh'!B60 -> 790 | C39: ='Kayu Rimba Luar Jawa slh '!C96+'Kayu Rimba Jawa slh '!C61+'Kayu Jati Jawa slh'!C60 -> 1152.3 | D39: ='Kayu Rimba Luar Jawa slh '!D96+'Kayu Rimba Jawa slh '!D61+'Kayu Jati Jawa slh'!D60 -> 1131.2 | E39: ='Kayu Rimba Luar Jawa slh '!E96+'Kayu Rimba Jawa slh '!E61+'Kayu Jati Jawa slh'!E60 -> 1601.8 | F39: ='Kayu Rimba Luar Jawa slh '!F96+'Kayu Rimba Jawa slh '!F61+'Kayu Jati Jawa slh'!F60 -> 1367.46 | G39: ='Kayu Rimba Luar Jawa slh '!G96+'Kayu Rimba Jawa slh '!G61+'Kayu Jati Jawa slh'!G60 -> 1674.2 | H39: ='Kayu Rimba Luar Jawa slh '!H96+'Kayu Rimba Jawa slh '!H61+'Kayu Jati Jawa slh'!H60 -> 2654.03 | I39: ='Kayu Rimba Luar Jawa slh '!I96+'Kayu Rimba Jawa slh '!I61+'Kayu Jati Jawa slh'!I60 -> 2266.59 | ... L39: ='Kayu Rimba Luar Jawa slh '!L96+'Kayu Rimba Jawa slh '!L61+'Kayu Jati Jawa slh'!L60 -> 1486.6887
A40: 4. Konversi & kerusakan | B40: ='Kayu Rimba Luar Jawa slh '!B97+'Kayu Rimba Jawa slh '!B62+'Kayu Jati Jawa slh'!B61 -> 15665.8 | C40: ='Kayu Rimba Luar Jawa slh '!C97+'Kayu Rimba Jawa slh '!C62+'Kayu Jati Jawa slh'!C61 -> 18825.8 | D40: ='Kayu Rimba Luar Jawa slh '!D97+'Kayu Rimba Jawa slh '!D62+'Kayu Jati Jawa slh'!D61 -> 38007.4 | E40: ='Kayu Rimba Luar Jawa slh '!E97+'Kayu Rimba Jawa slh '!E62+'Kayu Jati Jawa slh'!E61 -> 47597.7 | F40: ='Kayu Rimba Luar Jawa slh '!F97+'Kayu Rimba Jawa slh '!F62+'Kayu Jati Jawa slh'!F61 -> 38563.3 | G40: ='Kayu Rimba Luar Jawa slh '!G97+'Kayu Rimba Jawa slh '!G62+'Kayu Jati Jawa slh'!G61 -> 41077.1 | H40: ='Kayu Rimba Luar Jawa slh '!H97+'Kayu Rimba Jawa slh '!H62+'Kayu Jati Jawa slh'!H61 -> 40078.83 | I40: ='Kayu Rimba Luar Jawa slh '!I97+'Kayu Rimba Jawa slh '!I62+'Kayu Jati Jawa slh'!I61 -> 80250.98 | ... L40: ='Kayu Rimba Luar Jawa slh '!L97+'Kayu Rimba Jawa slh '!L62+'Kayu Jati Jawa slh'!L61 -> 100341.42
A41: 5. Penebangan | B41: ='Kayu Rimba Luar Jawa slh '!B98+'Kayu Rimba Jawa slh '!B63+'Kayu Jati Jawa slh'!B62 -> 28553.9 | C41: ='Kayu Rimba Luar Jawa slh '!C98+'Kayu Rimba Jawa slh '!C63+'Kayu Jati Jawa slh'!C62 -> 28139.7 | D41: ='Kayu Rimba Luar Jawa slh '!D98+'Kayu Rimba Jawa slh '!D63+'Kayu Jati Jawa slh'!D62 -> 28689.4 | E41: ='Kayu Rimba Luar Jawa slh '!E98+'Kayu Rimba Jawa slh '!E63+'Kayu Jati Jawa slh'!E62 -> 29553.8 | F41: ='Kayu Rimba Luar Jawa slh '!F98+'Kayu Rimba Jawa slh '!F63+'Kayu Jati Jawa slh'!F62 -> 29701.4 | G41: ='Kayu Rimba Luar Jawa slh '!G98+'Kayu Rimba Jawa slh '!G63+'Kayu Jati Jawa slh'!G62 -> 29666.9 | H41: ='Kayu Rimba Luar Jawa slh '!H98+'Kayu Rimba Jawa slh '!H63+'Kayu Jati Jawa slh'!H62 -> 30092.97 | I41: ='Kayu Rimba Luar Jawa slh '!I98+'Kayu Rimba Jawa slh '!I63+'Kayu Jati Jawa slh'!I62 -> 34230.24 | ... L41: ='Kayu Rimba Luar Jawa slh '!L98+'Kayu Rimba Jawa slh '!L63+'Kayu Jati Jawa slh'!L62 -> 26264.207
A42: 6. Perubahan Neto | B42: ='Kayu Rimba Luar Jawa slh '!B99+'Kayu Rimba Jawa slh '!B64+'Kayu Jati Jawa slh'!B63 -> -1446.8 | C42: ='Kayu Rimba Luar Jawa slh '!C99+'Kayu Rimba Jawa slh '!C64+'Kayu Jati Jawa slh'!C63 -> -2725.0544 | D42: ='Kayu Rimba Luar Jawa slh '!D99+'Kayu Rimba Jawa slh '!D64+'Kayu Jati Jawa slh'!D63 -> -21245.579 | E42: ='Kayu Rimba Luar Jawa slh '!E99+'Kayu Rimba Jawa slh '!E64+'Kayu Jati Jawa slh'!E63 -> -29931.157 | F42: ='Kayu Rimba Luar Jawa slh '!F99+'Kayu Rimba Jawa slh '!F64+'Kayu Jati Jawa slh'!F63 -> -19894.11 | G42: ='Kayu Rimba Luar Jawa slh '!G99+'Kayu Rimba Jawa slh '!G64+'Kayu Jati Jawa slh'!G63 -> -20474.29 | H42: ='Kayu Rimba Luar Jawa slh '!H99+'Kayu Rimba Jawa slh '!H64+'Kayu Jati Jawa slh'!H63 -> -13091.31 | I42: ='Kayu Rimba Luar Jawa slh '!I99+'Kayu Rimba Jawa slh '!I64+'Kayu Jati Jawa slh'!I63 -> -57182.07 | ... L42: ='Kayu Rimba Luar Jawa slh '!L99+'Kayu Rimba Jawa slh '!L64+'Kayu Jati Jawa slh'!L63 -> -62656.517
A43: 7. Persediaan akhir | B43: ='Kayu Rimba Luar Jawa slh '!B100+'Kayu Rimba Jawa slh '!B65+'Kayu Jati Jawa slh'!B64 -> 8642977.8 | C43: ='Kayu Rimba Luar Jawa slh '!C100+'Kayu Rimba Jawa slh '!C65+'Kayu Jati Jawa slh'!C64 -> 8640252.7 | D43: ='Kayu Rimba Luar Jawa slh '!D100+'Kayu Rimba Jawa slh '!D65+'Kayu Jati Jawa slh'!D64 -> 8619007.2 | E43: ='Kayu Rimba Luar Jawa slh '!E100+'Kayu Rimba Jawa slh '!E65+'Kayu Jati Jawa slh'!E64 -> 8589076 | F43: ='Kayu Rimba Luar Jawa slh '!F100+'Kayu Rimba Jawa slh '!F65+'Kayu Jati Jawa slh'!F64 -> 8569181.9 | G43: ='Kayu Rimba Luar Jawa slh '!G100+'Kayu Rimba Jawa slh '!G65+'Kayu Jati Jawa slh'!G64 -> 8548707.6 | H43: ='Kayu Rimba Luar Jawa slh '!H100+'Kayu Rimba Jawa slh '!H65+'Kayu Jati Jawa slh'!H64 -> 8535616.3 | I43: ='Kayu Rimba Luar Jawa slh '!I100+'Kayu Rimba Jawa slh '!I65+'Kayu Jati Jawa slh'!I64 -> 8478434.2 | ... L43: ='Kayu Rimba Luar Jawa slh '!L100+'Kayu Rimba Jawa slh '!L65+'Kayu Jati Jawa slh'!L64 -> 8282718.8
A45: III. Neraca Moneter
A46: (miliar Rp)
A48: 1. Persediaan awal | B48: ='Kayu Rimba Luar Jawa slh '!B107+'Kayu Rimba Jawa slh '!B72+'Kayu Jati Jawa slh'!B71 -> 122116.4 | C48: ='Kayu Rimba Luar Jawa slh '!C107+'Kayu Rimba Jawa slh '!C72+'Kayu Jati Jawa slh'!C71 -> 122375.52 | D48: ='Kayu Rimba Luar Jawa slh '!D107+'Kayu Rimba Jawa slh '!D72+'Kayu Jati Jawa slh'!D71 -> 122643.99 | E48: ='Kayu Rimba Luar Jawa slh '!E107+'Kayu Rimba Jawa slh '!E72+'Kayu Jati Jawa slh'!E71 -> 122691.99 | F48: ='Kayu Rimba Luar Jawa slh '!F107+'Kayu Rimba Jawa slh '!F72+'Kayu Jati Jawa slh'!F71 -> 122616.51 | G48: ='Kayu Rimba Luar Jawa slh '!G107+'Kayu Rimba Jawa slh '!G72+'Kayu Jati Jawa slh'!G71 -> 122703.82 | H48: ='Kayu Rimba Luar Jawa slh '!H107+'Kayu Rimba Jawa slh '!H72+'Kayu Jati Jawa slh'!H71 -> 122811.38 | I48: ='Kayu Rimba Luar Jawa slh '!I107+'Kayu Rimba Jawa slh '!I72+'Kayu Jati Jawa slh'!I71 -> 123249.66 | ... L48: ='Kayu Rimba Luar Jawa slh '!L107+'Kayu Rimba Jawa slh '!L72+'Kayu Jati Jawa slh'!L71 -> 122397.7
A49: 2. Pertumbuhan | B49: ='Kayu Rimba Luar Jawa slh '!B108+'Kayu Rimba Jawa slh '!B73+'Kayu Jati Jawa slh'!B72 -> 972.99424 | C49: ='Kayu Rimba Luar Jawa slh '!C108+'Kayu Rimba Jawa slh '!C73+'Kayu Jati Jawa slh'!C72 -> 1011.8988 | D49: ='Kayu Rimba Luar Jawa slh '!D108+'Kayu Rimba Jawa slh '!D73+'Kayu Jati Jawa slh'!D72 -> 1054.9103 | E49: ='Kayu Rimba Luar Jawa slh '!E108+'Kayu Rimba Jawa slh '!E73+'Kayu Jati Jawa slh'!E72 -> 1101.4978 | F49: ='Kayu Rimba Luar Jawa slh '!F108+'Kayu Rimba Jawa slh '!F73+'Kayu Jati Jawa slh'!F72 -> 1149.003 | G49: ='Kayu Rimba Luar Jawa slh '!G108+'Kayu Rimba Jawa slh '!G73+'Kayu Jati Jawa slh'!G72 -> 1201.7464 | H49: ='Kayu Rimba Luar Jawa slh '!H108+'Kayu Rimba Jawa slh '!H73+'Kayu Jati Jawa slh'!H72 -> 1504.003 | I49: ='Kayu Rimba Luar Jawa slh '!I108+'Kayu Rimba Jawa slh '!I73+'Kayu Jati Jawa slh'!I72 -> 1488.5662 | ... L49: ='Kayu Rimba Luar Jawa slh '!L108+'Kayu Rimba Jawa slh '!L73+'Kayu Jati Jawa slh'!L72 -> 1578.3994
A50: 3. Penanaman | B50: ='Kayu Rimba Luar Jawa slh '!B109+'Kayu Rimba Jawa slh '!B74+'Kayu Jati Jawa slh'!B73 -> 14.075115 | C50: ='Kayu Rimba Luar Jawa slh '!C109+'Kayu Rimba Jawa slh '!C74+'Kayu Jati Jawa slh'!C73 -> 19.592988 | D50: ='Kayu Rimba Luar Jawa slh '!D109+'Kayu Rimba Jawa slh '!D74+'Kayu Jati Jawa slh'!D73 -> 18.59191 | E50: ='Kayu Rimba Luar Jawa slh '!E109+'Kayu Rimba Jawa slh '!E74+'Kayu Jati Jawa slh'!E73 -> 24.626651 | F50: ='Kayu Rimba Luar Jawa slh '!F109+'Kayu Rimba Jawa slh '!F74+'Kayu Jati Jawa slh'!F73 -> 21.394791 | G50: ='Kayu Rimba Luar Jawa slh '!G109+'Kayu Rimba Jawa slh '!G74+'Kayu Jati Jawa slh'!G73 -> 26.030519 | H50: ='Kayu Rimba Luar Jawa slh '!H109+'Kayu Rimba Jawa slh '!H74+'Kayu Jati Jawa slh'!H73 -> 37.901668 | I50: ='Kayu Rimba Luar Jawa slh '!I109+'Kayu Rimba Jawa slh '!I74+'Kayu Jati Jawa slh'!I73 -> 33.511564 | ... L50: ='Kayu Rimba Luar Jawa slh '!L109+'Kayu Rimba Jawa slh '!L74+'Kayu Jati Jawa slh'!L73 -> 26.432726
A51: 4. Konversi & kerusakan | B51: ='Kayu Rimba Luar Jawa slh '!B110+'Kayu Rimba Jawa slh '!B75+'Kayu Jati Jawa slh'!B74 -> 228.81886 | C51: ='Kayu Rimba Luar Jawa slh '!C110+'Kayu Rimba Jawa slh '!C75+'Kayu Jati Jawa slh'!C74 -> 271.91001 | D51: ='Kayu Rimba Luar Jawa slh '!D110+'Kayu Rimba Jawa slh '!D75+'Kayu Jati Jawa slh'!D74 -> 537.46483 | E51: ='Kayu Rimba Luar Jawa slh '!E110+'Kayu Rimba Jawa slh '!E75+'Kayu Jati Jawa slh'!E74 -> 679.50206 | F51: ='Kayu Rimba Luar Jawa slh '!F110+'Kayu Rimba Jawa slh '!F75+'Kayu Jati Jawa slh'!F74 -> 553.13991 | G51: ='Kayu Rimba Luar Jawa slh '!G110+'Kayu Rimba Jawa slh '!G75+'Kayu Jati Jawa slh'!G74 -> 587.06076 | H51: ='Kayu Rimba Luar Jawa slh '!H110+'Kayu Rimba Jawa slh '!H75+'Kayu Jati Jawa slh'!H74 -> 573.51453 | I51: ='Kayu Rimba Luar Jawa slh '!I110+'Kayu Rimba Jawa slh '!I75+'Kayu Jati Jawa slh'!I74 -> 1115.3044 | ... L51: ='Kayu Rimba Luar Jawa slh '!L110+'Kayu Rimba Jawa slh '!L75+'Kayu Jati Jawa slh'!L74 -> 1441.9489
A52: 5. Penebangan | B52: ='Kayu Rimba Luar Jawa slh '!B111+'Kayu Rimba Jawa slh '!B76+'Kayu Jati Jawa slh'!B75 -> 499.12636 | C52: ='Kayu Rimba Luar Jawa slh '!C111+'Kayu Rimba Jawa slh '!C76+'Kayu Jati Jawa slh'!C75 -> 491.11015 | D52: ='Kayu Rimba Luar Jawa slh '!D111+'Kayu Rimba Jawa slh '!D76+'Kayu Jati Jawa slh'!D75 -> 488.04028 | E52: ='Kayu Rimba Luar Jawa slh '!E111+'Kayu Rimba Jawa slh '!E76+'Kayu Jati Jawa slh'!E75 -> 522.10191 | F52: ='Kayu Rimba Luar Jawa slh '!F111+'Kayu Rimba Jawa slh '!F76+'Kayu Jati Jawa slh'!F75 -> 529.94625 | G52: ='Kayu Rimba Luar Jawa slh '!G111+'Kayu Rimba Jawa slh '!G76+'Kayu Jati Jawa slh'!G75 -> 533.16013 | H52: ='Kayu Rimba Luar Jawa slh '!H111+'Kayu Rimba Jawa slh '!H76+'Kayu Jati Jawa slh'!H75 -> 530.11179 | I52: ='Kayu Rimba Luar Jawa slh '!I111+'Kayu Rimba Jawa slh '!I76+'Kayu Jati Jawa slh'!I75 -> 590.86758 | ... L52: ='Kayu Rimba Luar Jawa slh '!L111+'Kayu Rimba Jawa slh '!L76+'Kayu Jati Jawa slh'!L75 -> 457.9535
A53: 6. Perubahan Neto | B53: ='Kayu Rimba Luar Jawa slh '!B112+'Kayu Rimba Jawa slh '!B77+'Kayu Jati Jawa slh'!B76 -> 259.12414 | C53: ='Kayu Rimba Luar Jawa slh '!C112+'Kayu Rimba Jawa slh '!C77+'Kayu Jati Jawa slh'!C76 -> 268.47161 | D53: ='Kayu Rimba Luar Jawa slh '!D112+'Kayu Rimba Jawa slh '!D77+'Kayu Jati Jawa slh'!D76 -> 47.997132 | E53: ='Kayu Rimba Luar Jawa slh '!E112+'Kayu Rimba Jawa slh '!E77+'Kayu Jati Jawa slh'!E76 -> -75.479541 | F53: ='Kayu Rimba Luar Jawa slh '!F112+'Kayu Rimba Jawa slh '!F77+'Kayu Jati Jawa slh'!F76 -> 87.311663 | G53: ='Kayu Rimba Luar Jawa slh '!G112+'Kayu Rimba Jawa slh '!G77+'Kayu Jati Jawa slh'!G76 -> 107.55598 | H53: ='Kayu Rimba Luar Jawa slh '!H112+'Kayu Rimba Jawa slh '!H77+'Kayu Jati Jawa slh'!H76 -> 438.27831 | I53: ='Kayu Rimba Luar Jawa slh '!I112+'Kayu Rimba Jawa slh '!I77+'Kayu Jati Jawa slh'!I76 -> -184.09419 | ... L53: ='Kayu Rimba Luar Jawa slh '!L112+'Kayu Rimba Jawa slh '!L77+'Kayu Jati Jawa slh'!L76 -> -295.07023
A54: 7. Revaluasi | B54: ='Kayu Rimba Luar Jawa slh '!B113+'Kayu Rimba Jawa slh '!B78+'Kayu Jati Jawa slh'!B77 -> 0 | C54: ='Kayu Rimba Luar Jawa slh '!C113+'Kayu Rimba Jawa slh '!C78+'Kayu Jati Jawa slh'!C77 -> 0 | D54: ='Kayu Rimba Luar Jawa slh '!D113+'Kayu Rimba Jawa slh '!D78+'Kayu Jati Jawa slh'!D77 -> 0 | E54: ='Kayu Rimba Luar Jawa slh '!E113+'Kayu Rimba Jawa slh '!E78+'Kayu Jati Jawa slh'!E77 -> 0 | F54: ='Kayu Rimba Luar Jawa slh '!F113+'Kayu Rimba Jawa slh '!F78+'Kayu Jati Jawa slh'!F77 -> 0 | G54: ='Kayu Rimba Luar Jawa slh '!G113+'Kayu Rimba Jawa slh '!G78+'Kayu Jati Jawa slh'!G77 -> 0 | H54: ='Kayu Rimba Luar Jawa slh '!H113+'Kayu Rimba Jawa slh '!H78+'Kayu Jati Jawa slh'!H77 -> 0 | I54: ='Kayu Rimba Luar Jawa slh '!I113+'Kayu Rimba Jawa slh '!I78+'Kayu Jati Jawa slh'!I77 -> 0 | ... L54: ='Kayu Rimba Luar Jawa slh '!L113+'Kayu Rimba Jawa slh '!L78+'Kayu Jati Jawa slh'!L77 -> 0
...

Sheet Data Penunjang
A1: Data Penunjang Penghitungan | C1: estimasi
A2: Sisnerling Hutan | C2: link based on sumber data | D2: estimasi? | AC2: =5307.51+170979.77 -> 176287.28 | AG2: =191633+27479.36+362574.64+784816.57 -> 1366503.6
A3: Tahun 1993 - 2013 | AA3: 7089.58 | AB3: =(100+BF7)/100*AA3 -> 8124.0353 | AC3: 4918.75 | AD3: 1491.6078 | AG3: =13234.28+173.35 -> 13407.63
B4: *Menggunakan data saldo akhir | C4: formula | AF4: 102807.89 | AQ4: Pertumbuhan 2011-2015
A5: No. | B5: Uraian | C5: Sumber Data | D5: Rujukan | E5: Satuan | F5: 1990 | G5: 1991 | H5: 1992 | I5: 1993 | J5: 1994 | K5: 1995 | L5: 1996 | M5: 1997 | N5: 1998 | O5: 1999 | P5: 2000 | Q5: 2001 | R5: 2002 | S5: 2003 | T5: 2004 | U5: 2005 | V5: 2006 | W5: 2007 | X5: 2008 | Y5: 2009 | Z5: 2010 | AA5: 2011 | AB5: 2012 | AC5: 2013 | AD5: 2014 | AE5: 2015 | AF5: 2016 | AG5: 2017 | AH5: 2018 | AI5: 2019 | AJ5: 2020 | AK5: 2021 | AL5: 2022 | AM5: 2023 | AN5: 2024 | AQ5: 2011 | AR5: 2012 | AS5: 2013 | AT5: 2014 | AU5: 2015 | AV5: Rata-rata | AW5: Estimasi 2016 | AY5: 2005 | AZ5: 2006 | BA5: 2007 | BB5: 2008 | BC5: 2009 | BD5: 2010 | BE5: 2011 | BF5: 2012 | BG5: 2013 | BH5: 2014
B6: Nasional | E6: laju kebakaran | AC6: =AC3/AB3*100-100 -> -39.45435 | AD6: =AD7/AC3*100-100 -> 144.95959 | AE6: =AE7/AD7*100-100 -> 9389.7984 | AF6: =AF7/AE7*100-100 -> -83.366492 | AG6: =AG7/AF7*100-100 -> -76.728876 | AH6: =AH7/AG7*100-100 -> 294.32426 | AI6: =AI7/AH7*100-100 -> 222.94589 | AJ6: =AJ7/AI7*100-100 -> -82.067922 | AK6: =AK7/AJ7*100-100 -> 27.461819 | AL6: =AL7/AK7*100-100 -> -41.306722 | ... AN6: =AN7/AM7*100-100 -> -68.153142
A7: 1 | B7: Luas Kebakaran Hutan Indonesia | C7: NSDH | E7: Ha | O7: 44090 | P7: 3016.5 | Q7: 14329.5 | R7: 35496.73 | S7: 3545.45 | T7: 3343.99 | U7: 5502.47 | V7: 4241.59 | W7: 6974.62 | X7: 6793.08 | Y7: 7619.41 | Z7: 3493.12 | AA7: =0+3107.06+0 -> 3107.06 | AB7: =0+1365.3+0 -> 1365.3 | AC7: =0+1723.59+0 -> 1723.59 | AD7: =0+12048.95+0 -> 12048.95 | AE7: =145035.24+734500.52+263885.3 -> 1143421.1 | AF7: =23473.33+96509.7+70208 -> 190191.03 | AG7: =9602.84+16781.88+17874.87 -> 44259.59 | AH7: =33289.79+77416.46+63820.05 -> 174526.3 | AI7: =78516.93+325970.15+159138.44 -> 563625.52 | AJ7: =20358.13+46490.52+34221.12 -> 101069.77 | AK7: =(((AK81/AJ81*100-100)+100)*AJ7)/100 -> 128825.37 | AL7: =(((AL81/AK81*100-100)+100)*AK7)/100 -> 75611.831 | AM7: =(((AM81/AL81*100-100)+100)*AL7)/100 -> 411203.09 | AN7: =(((AN81/AM81*100-100)+100)*AM7)/100 -> 130955.26 | AQ7: =AA3/Z7-1 -> 1.0295839 | AR7: =AB3/AA3-1 -> 0.14591208 | AS7: =AC3/AB3-1 -> -0.3945435 | AT7: =AD7/AC3-1 -> 1.4495959 | AU7: =AE7/AD7-1 -> 93.897984 | AV7: =AVERAGE(AQ7:AU7) -> 19.225706 | AW7: =AVERAGE(AA7:AE7) -> 232333.19 | AX7: =(100+AV7)*AE7/100 -> 1363251.8 | BB7: =X7/W7*100-100 -> -2.6028658 | BC7: =Y7/X7*100-100 -> 12.164291 | BD7: =Z7/Y7*100-100 -> -54.154981 | BE7: =AA3/Z7*100-100 -> 102.95839 | BF7: =AVERAGE(BB7:BE7) -> 14.591208 | BG7: =AVERAGE(BB7:BF7) -> 14.591208 | BH7: =AVERAGE(BB7:BG7) -> 14.591208
A8: 2 | B8: Realisasi Reboisasi (Penanaman) Indonesia | C8: NSDH | E8: Ha | K8: 41762 | L8: 44824 | M8: 35725 | N8: 23615 | O8: 12002 | P8: 8986 | Q8: 7049 | R8: 35433 | S8: 52200 | T8: =T10-T9 -> 332482 | U8: =U10-U9 -> 23709 | V8: =V10-V9 -> 242871 | W8: =W10-W9 -> 74968 | X8: =X10-X9 -> 266721 | Y8: =Y10-Y9 -> 200758 | Z8: =Z10-Z9 -> 142093.75 | AA8: =AA10-AA9 -> 145332.15 | AB8: =AB10-AB9 -> 168787.52 | AC8: 105656 | AD8: =23031.36+258097.65 -> 281129.01 | AE8: =179412.05+343310.13 -> 522722.18 | AF8: =33083.4+361249.7 -> 394333.1 | AG8: =24865+219744.18 -> 244609.18 | AH8: =20864.87+282840.4 -> 303705.27 | AI8: =22723.05+384104.81 -> 406827.86 | AJ8: =15494.77+342787 -> 358281.77 | AK8: ='[1]5. Penanaman'!H89 -> 156257 | AL8: ='[1]5. Penanaman'!I89 -> 220185 | AM8: =(100+[2]StatHut!F15)/100*AL8 -> 143936.82 | AN8: =AVERAGE(AI8:AM8) -> 257097.69 | AQ8: =AA8/Z8-1 -> 0.022790565 | AR8: =AB8/AA8-1 -> 0.16139151 | AS8: =AC8/AB8-1 -> -0.37402955 | AT8: =AD8/AC8-1 -> 1.6607955 | AU8: =AE8/AD8-1 -> 0.85936763 | AV8: =AVERAGE(AQ8:AU8) -> 0.46606313 | AW8: =AVERAGE(AA8:AE8) -> 244725.37 | AX8: =AVERAGE(AA8:AE8) -> 244725.37 | AY8: =(1+AW8)*AE8 -> 1.279239e+11 | BB8: =X8/W8*100-100 -> 255.7798 | BC8: =Y8/X8*100-100 -> -24.731086 | BD8: =Z8/Y8*100-100 -> -29.221376 | BE8: =AA8/Z8*100-100 -> 2.2790565 | BF8: =AB8/AA8*100-100 -> 16.139151 | BG8: =AC8/AB8*100-100 -> -37.402955 | BH8: =AVERAGE(BB8:BG8) -> 30.473765
A9: 3 | B9: Penanaman Hutan Kemasyarakatan Indonesia | C9: NSDH | E9: Ha | K9: 17631 | L9: 11755 | M9: 7990 | N9: 7087 | O9: 850 | P9: 24556 | Q9: 5436 | R9: 13436 | S9: 9597 | T9: 6684 | U9: 3254 | V9: 3171 | W9: 1750 | X9: 200 | Y9: 2283 | Z9: 7329 | AA9: =(1+BE9)/100*Z9 -> 16586.853 | AB9: =(1+BF9)/100*AA9 -> 37539.05 | AC9: 265325 | AD9: =30064.24+42234.37+20219.27 -> 92517.88 | AE9: =127+1086.88+532 -> 1745.88 | AF9: =4+12.75+0+44970+107849.24+26700.31 -> 179536.3 | AG9: =98+55+212+274+230.2+364 -> 1233.2 | AH9: =120+75+645+75+267 -> 1182 | AI9: =75+75+60+12598.15+13201.22+1967 -> 27976.37 | AJ9: =0+82.21+564.51+207.71 -> 854.43 | AK9: =(((AK82/AJ82*100-100)+100)*AJ9)/100 -> 863.17508 | AL9: =(((AL82/AK82*100-100)+100)*AK9)/100 -> 1000.6721 | AM9: =(((AM82/AL82*100-100)+100)*AL9)/100 -> 1114.1367 | AN9: =(((AN82/AM82*100-100)+100)*AM9)/100 -> 1274.8099 | AQ9: =AA9/Z9-1 -> 1.2631809 | AR9: =AB9/AA9-1 -> 1.2631809 | AS9: =AC9/AB9-1 -> 6.0679733 | AT9: =AD9/AC9-1 -> -0.65130357 | AU9: =AE9/AD9-1 -> -0.98112927 | AV9: =AVERAGE(AQ9:AU9) -> 1.3923805 | AW9: =AVERAGE(AA9:AE9) -> 82742.933 | AX9: =AVERAGE(AA9:AE9) -> 82742.933 | AZ9: =V9/U9*100-100 -> -2.5507068 | BA9: =W9/V9*100-100 -> -44.812362 | BB9: =X9/W9*100-100 -> -88.571429 | BC9: =Y9/X9*100-100 -> 1041.5 | BD9: =Z9/Y9*100-100 -> 221.02497 | BE9: =AVERAGE(AZ9:BD9) -> 225.31809 | BF9: =AVERAGE(AZ9:BE9) -> 225.31809 | BG9: =AVERAGE(AZ9:BF9) -> 225.31809 | BH9: =AVERAGE(AZ9:BG9) -> 225.31809
A10: 4 | B10: Luas Reboisasi + Penanaman | C10: NSDH | E10: Ha | K10: 59393 | L10: 56579 | M10: 43715 | N10: 30702 | O10: 12852 | P10: 33542 | Q10: 12485 | R10: 48869 | S10: 61797 | T10: 339166 | U10: 26963 | V10: 246042 | W10: 76718 | X10: 266921 | Y10: =113041+90000 -> 203041 | Z10: =149422.75 -> 149422.75 | AA10: =151498+10421 -> 161919 | AB10: =AA10*(100+BF10)/100 -> 206326.57 | AC10: =AC8+AC9 -> 370981 | AD10: =AD8+AD9 -> 373646.89 | AE10: =AE8+AE9 -> 524468.06 | AF10: =AF8+AF9 -> 573869.4 | AG10: =AG8+AG9 -> 245842.38 | AH10: =AH8+AH9 -> 304887.27 | AI10: =AI8+AI9 -> 434804.23 | AJ10: =AJ8+AJ9 -> 359136.2 | ... AN10: =AN8+AN9 -> 258372.5 | AQ10: =AA10/Z10-1 -> 0.08363017 | AR10: =AB10/AA10-1 -> 0.27425794 | AS10: =AC10/AB10-1 -> 0.79802824 | AT10: =AD10/AC10-1 -> 0.0071860554 | AU10: =AE10/AD10-1 -> 0.40364626 | AV10: =AVERAGE(AQ10:AU10) -> 0.31334973 | AW10: =(1+AV10)*AE10 -> 688809.99 | AY10: =U10/T10*100-100 -> -92.050206 | AZ10: =V10/U10*100-100 -> 812.51715 | BA10: =W10/V10*100-100 -> -68.819145 | BB10: =X10/W10*100-100 -> 247.92487 | BC10: =Y10/X10*100-100 -> -23.932175 | BD10: =Z10/Y10*100-100 -> -26.407597 | BE10: =AA10/Z10*100-100 -> 8.363017 | BF10: =AVERAGE(BA10:BE10) -> 27.425794
A11: 5 | B11: Produksi Kayu Bulat Indonesia | C11: PDB kehutanan | E11: M3 | O11: 20619942 | P11: 13798240 | Q11: 11155400 | R11: 9004105 | S11: 11423501 | T11: 13548938 | U11: 24222638 | V11: 21792144 | W11: 31491584 | X11: 27837337 | Y11: 29207400 | Z11: 30721759 | AA11: 29630421 | AB11: 29047187 | AC11: =23923.3225033*1000 -> 23923323 | AD11: 26798625 | AE11: 26382722 | AF11: 26168644 | AG11: 27435100 | AH11: =[3]Olah!$L$5 -> 27462980 | AI11: =[3]Olah!$M$5 -> 28653668 | AJ11: =[3]Olah!$N$5 -> 30180976 | AK11: =[3]Olah!O$5 -> 31865454 | AL11: =[3]Olah!P$5 -> 31978702 | AM11: =(100+[2]StatHut!F6)/100*AL11 -> 33741127 | AN11: =(100+[2]StatHut!G6)/100*AM11 -> 32071074 | AO11: =(100+[4]StatHut!$G$6)/100*AM11 -> 32071074 | AQ11: =AA11/Z11-1 -> -0.035523299 | AR11: =AB11/AA11-1 -> -0.019683607 | AS11: =AC11/AB11-1 -> -0.17639797 | AT11: =AD11/AC11-1 -> 0.12018825 | AU11: =AE11/AD11-1 -> -0.015519566 | AV11: =AVERAGE(AQ11:AU11) -> -0.025387237 | AW11: =(1+AV11)*AE11 -> 25712937
B12: - Luar Jawa | C12: selisih | E12: M3 | O12: =+O11-O13 -> 20618181 | P12: =+P11-P13 -> 13796633 | Q12: =+Q11-Q13 -> 11153944 | R12: =+R11-R13 -> 9002620.1 | S12: =+S11-S13 -> 11422524 | T12: =+T11-T13 -> 13548014 | U12: =+U11-U13 -> 24221883 | V12: =+V11-V13 -> 21791268 | ... AN12: =+AN11-AN13 -> 31267437 | AO12: =AN12+AN13 -> 32071074 | AQ12: =AA12/Z12-1 -> -0.067043961 | AR12: =AB12/AA12-1 -> -0.018943909 | AS12: =AC12/AB12-1 -> -0.18317371 | AT12: =AD12/AC12-1 -> 0.12679958 | AU12: =AE12/AD12-1 -> -0.011149761 | AV12: =AVERAGE(AQ12:AU12) -> -0.030702352 | AW12: =(1+AV12)*AE12 -> 24805763
B13: - Jawa | C13: Perhutani | E13: M3 | F13: =+F50 -> 1267.733 | G13: =+G50 -> 1328.78 | H13: =+H50 -> 1315.452 | I13: =+I50 -> 1624.791 | J13: =+J50 -> 1711.463 | K13: =+K50 -> 1601.269 | L13: =+L50 -> 0 | M13: =+M50 -> 1861.863 | ... Z13: =+Z50 -> 889.461 | AA13: =+AA50*1000 -> 969200 | AB13: =+AB50*1000 -> 928922 | AC13: =+AC50*1000 -> 955584.31 | AD13: =+AD50*1000 -> 918587.01 | AE13: =+AE50*1000 -> 791240.22 | AF13: =+AF50*1000 -> 548432 | AG13: =+AG50*1000 -> 636292.36 | AH13: =+AH50*1000 -> 809934 | ... AN13: =+AN50*1000 -> 803637 | AQ13: =AA13/Z13-1 -> 1088.6487 | AR13: =AB13/AA13-1 -> -0.041557986 | AS13: =AC13/AB13-1 -> 0.028702419 | AT13: =AD13/AC13-1 -> -0.038716942 | AU13: =AE13/AD13-1 -> -0.13863334 | AV13: =AVERAGE(AQ13:AU13) -> 217.69169 | AW13: =(1+AV13)*AE13 -> 1.7303766e+08
A14: 6 | B14: Luas Hutan Produksi Luar Jawa: | C14: selisih | D14: lamp 5 | E14: Ha | I14: 31387324 | L14: 31570726 | M14: 33134599 | N14: 31366474 | O14: 31366374 | P14: 26262311 | Q14: 26262311 | R14: 26262311 | S14: 35222373 | T14: 34669774 | U14: 34665979 | V14: 34665979 | W14: 34861921 | X14: =X15-X16 -> 33939195 | Y14: =Y15-Y16 -> 34716287 | Z14: =Z15-Z16 -> 34704565 | AA14: =AA15-AA16 -> 34969065 | AB14: =AB15-AB16 -> 34767270 | AC14: =AC15-AC16 -> 26452167 | AD14: =AD15-AD16 -> 27460290 | AE14: =AE15-AE16 -> 27528702 | ... AN14: =AN15-AN16 -> 27484353 | AQ14: =AA14/Z14-1 -> 0.007621491 | AR14: =AB14/AA14-1 -> -0.0057706777 | AS14: =AC14/AB14-1 -> -0.2391647 | AT14: =AD14/AC14-1 -> 0.038111172 | AV14: =AVERAGE(AQ14:AU14) -> -0.049800678 | AW14: =(1+AV14)*AE14 -> 26157754
B15: - Indonesia | C15: NSDH | D15: lamp 6 | E15: Ha | I15: 33401655 | L15: 33203202 | M15: 34765452 | N15: 33238754 | O15: 33238654 | P15: 27823177 | Q15: 27823177 | R15: 27823177 | S15: 36608241 | T15: 36055156 | U15: 36056531 | V15: 36056531 | W15: 36279706 | X15: 35706500 | Y15: 36483592 | Z15: 36471870 | AA15: 36736370 | AB15: =(100+-0.38)/100*AA15 -> 36596772 | AC15: 28897173 | AD15: 29266920 | AE15: 29337690 | AF15: 29339772 | AG15: =29397651.71 -> 29397652 | AH15: 29379517 | AI15: 29400106 | AJ15: 29373977 | AK15: 29193500 | AL15: 29188600 | AM15: =AVERAGE(AH15:AL15) -> 29307140 | AN15: =AVERAGE(AI15:AM15) -> 29292665 | AQ15: =AA15/Z15-1 -> 0.0072521873 | AR15: =AB15/AA15-1 -> -0.0038 | AS15: =AC15/AB15-1 -> -0.21039013 | AT15: =AD15/AC15-1 -> 0.012795268 | AU15: =AE15/AD15-1 -> 0.0024180987 | AV15: =AVERAGE(AQ15:AU15) -> -0.038344915 | AW15: =AVERAGE(AA15:AE15) -> 32166985 | AX15: =AVERAGE(AA15:AE15) -> 32166985 | AY15: =U15/T15*100-100 -> 0.0038124922 | AZ15: =V15/U15*100-100 -> 0 | BA15: =W15/V15*100-100 -> 0.6189593 | BB15: =X15/W15*100-100 -> -1.5799632 | BC15: =Y15/X15*100-100 -> 2.1763312 | BD15: =Z15/Y15*100-100 -> -0.032129759 | BE15: =AA15/Z15*100-100 -> 0.72521873 | BF15: =AVERAGE(BA15:BE15) -> 0.38168325 | BL15: HP | BM15: HPT
B16: - Jawa | C16: Perhutani | D16: lamp 7 | E16: Ha | I16: 2014331.5 | L16: 1632476 | M16: 1630852.9 | N16: 1872280 | O16: 1872280 | P16: 1560866.3 | Q16: 1560866.3 | R16: 1560866.3 | S16: 1385868.3 | T16: 1385382.1 | U16: 1390552.1 | V16: 1390552.1 | W16: 1417785 | X16: =X37+X38 -> 1767305 | Y16: =Y37+Y38 -> 1767305 | Z16: =Z37+Z38 -> 1767304.7 | AA16: =AA37+AA38 -> 1767305 | AB16: =AB37+AB38 -> 1829502 | AC16: =AC37+AC38 -> 2445006 | AD16: =AD37+AD38 -> 1806630 | AE16: =AE37+AE38 -> 1808988.4 | ... AN16: =AN37+AN38 -> 1808312 | AQ16: =AA16/Z16-1 -> 1.6975002e-07 | AR16: =AB16/AA16-1 -> 0.035193133 | AS16: =AC16/AB16-1 -> 0.33643254 | AT16: =AD16/AC16-1 -> -0.26109384 | AU16: =AE16/AD16-1 -> 0.0013054139 | AV16: =AVERAGE(AQ16:AU16) -> 0.022367483 | AW16: =(1+AV16)*AE16 -> 1849450.9 | AY16: =U16/T16*100-100 -> 0.37318226 | AZ16: =V16/U16*100-100 -> 0 | BA16: =W16/V16*100-100 -> 1.9584272 | BB16: =X16/W16*100-100 -> 24.652539 | BC16: =Y16/X16*100-100 -> 0 | BD16: =Z16/Y16*100-100 -> -1.6974999e-05 | BE16: =AA16/Z16*100-100 -> 1.6975002e-05 | BF16: =AB16/AA16*100-100 -> 3.5193133 | BK16: DKI Jakarta | BL16: 158.35 | BM16: 0
A17: 7 | B17: Luas Hutan Produksi Terbatas Luar Jawa: | C17: selisih | D17: lamp 8 | E17: Ha | I17: 29570656 | L17: 29445705 | M17: 23473987 | N17: 29607522 | O17: 28907521 | P17: 15821515 | Q17: 15828380 | R17: 15828380 | S17: 22060329 | T17: 22019690 | U17: 22019690 | V17: 22019690 | W17: 21293788 | X17: 24414500 | Y17: =Y18-Y19 -> 21667857 | Z17: =Z18-Z19 -> 21587880 | AA17: =AA18-AA19 -> 21920298 | AB17: =AB18-AB19 -> 21986429 | AC17: =AC18-AC19 -> 27263154 | AD17: =AD18-AD19 -> 26419582 | AE17: =AE18-AE19 -> 26387880 | AF17: =AF18-AF19 -> 26312927 | ... AN17: =AN18-AN19 -> 26368663 | AQ17: =AA17/Z17-1 -> 0.015398391 | AR17: =AB17/AA17-1 -> 0.0030168636 | AS17: =AC17/AB17-1 -> 0.23999919 | AT17: =AD17/AC17-1 -> -0.030941841 | AV17: =AVERAGE(AQ17:AU17) -> 0.056868152 | AW17: =(1+AV17)*AE17 -> 27888510 | AY17: =U17/T17*100-100 -> 0 | AZ17: =V17/U17*100-100 -> 0 | BA17: =W17/V17*100-100 -> -3.2966052 | BB17: =X17/W17*100-100 -> 14.655504 | BC17: =Y17/X17*100-100 -> -11.250049 | BD17: =Z17/Y17*100-100 -> -0.36910453 | BE17: =AA17/Z17*100-100 -> 1.5398391 | BF17: =AB17/AA17*100-100 -> 0.30168636 | BK17: Jabar | BL17: 202965 | BM17: 190152
B18: - Indonesia | C18: NSDH | D18: lamp 9 | E18: Ha | I18: 29570656 | L18: 29833302 | M18: 23863206 | N18: 29607522 | O18: 28907521 | P18: 16209112 | Q18: 16215977 | R18: 16215977 | S18: 22451468 | T18: 22798381 | U18: 22325383 | V18: 22410793 | W18: 21717309 | X18: 24786100 | Y18: 22036484 | Z18: 21953005 | AA18: 22343819 | AB18: =(100+0.27)/100*AA18 -> 22404148 | AC18: 27686675 | AD18: 26808058 | AE18: 26768748 | AF18: 26694255 | AG18: =26735549.22 -> 26735549 | AH18: 26735850 | AI18: 26723211 | AJ18: 26745961 | AK18: 26791700 | AL18: 26759500 | AM18: =AVERAGE(AH18:AL18) -> 26751244 | AN18: =AVERAGE(AI18:AM18) -> 26754323 | AQ18: =AA18/Z18-1 -> 0.017802318 | AR18: =AB18/AA18-1 -> 0.0027 | AS18: =AC18/AB18-1 -> 0.23578346 | AT18: =AD18/AC18-1 -> -0.031734293 | AU18: =AE18/AD18-1 -> -0.0014663487 | AV18: =AVERAGE(AQ18:AU18) -> 0.044617027 | AW18: =AVERAGE(AA18:AE18) -> 25202290 | AX18: =AVERAGE(AA18:AE18) -> 25202290 | AY18: =U18/T18*100-100 -> -2.0747 | AZ18: =V18/U18*100-100 -> 0.3825688 | BA18: =W18/V18*100-100 -> -3.0944195 | BB18: =X18/W18*100-100 -> 14.130623 | BC18: =Y18/X18*100-100 -> -11.093379 | BD18: =Z18/Y18*100-100 -> -0.37882178 | BE18: =AA18/Z18*100-100 -> 1.7802318 | BF18: =AVERAGE(BA18:BE18) -> 0.26884676 | BK18: Banten | BL18: 26998 | BM18: 49439
B19: - Jawa | C19: Perhutani | D19: lamp 10 | E19: Ha | I19: 0 | L19: 387597 | M19: 389219.25 | N19: 0 | O19: 0 | P19: 387597 | Q19: 387597 | R19: 387597 | S19: 391138.5 | T19: 391102.69 | U19: 391102.69 | V19: 391102.69 | W19: 423521 | X19: 371600 | Y19: =(100-0.8)/100*X19 -> 368627.2 | Z19: =(100-0.95)/100*Y19 -> 365125.24 | AA19: =190152+49439+183930 -> 423521 | AB19: =(100-1.37)/100*AA19 -> 417718.76 | AC19: =SUM(BM16:BM21) -> 423521 | AD19: 388476.1 | AE19: =[2]Rekap!F7 -> 380868 | AF19: =[2]Rekap!G7 -> 381328 | AG19: =[2]Rekap!H7 -> 381242 | AH19: =[2]Rekap!I7 -> 380527 | AI19: =[2]Rekap!J7 -> 394212.1 | AJ19: =[2]Rekap!K7 -> 380931.2 | AK19: =[2]Rekap!L7 -> 380931.2 | AL19: =[2]Rekap!M7 -> 383395.35 | ... AN19: =[2]Rekap!O7 -> 385660.5 | AQ19: =AA19/Z19-1 -> 0.1599335 | AR19: =AB19/AA19-1 -> -0.0137 | AS19: =AC19/AB19-1 -> 0.013890297 | AT19: =AD19/AC19-1 -> -0.082746546 | AU19: =AE19/AD19-1 -> -0.019584474 | AV19: =AVERAGE(AQ19:AU19) -> 0.011558556 | AW19: =(1+AV19)*AE19 -> 385270.28 | AY19: =U19/T19*100-100 -> 0 | AZ19: =V19/U19*100-100 -> 0 | BA19: =W19/V19*100-100 -> 8.2889509 | BB19: =X19/W19*100-100 -> -12.259368 | BC19: =AVERAGE(AV19:BB19) -> 64211.054 | BD19: =AVERAGE(AY19:BC19) -> 12841.417 | BE19: =AVERAGE(AZ19:BD19) -> 15409.7 | BF19: =AVERAGE(BA19:BE19) -> 18491.64 | BK19: Jateng | BL19: 362360 | BM19: 183930
A20: 8 | B20: Luas Hutan Produksi yang Dapat Dikonversi Luar Jawa: | C20: selisih | D20: lamp 11 | E20: Ha | I20: 19039329 | L20: 18461538 | M20: 8350243.4 | N20: 36701812 | O20: 18961249 | P20: 13670535 | Q20: 13670535 | R20: 13670535 | S20: 22792495 | T20: 22730824 | U20: 22683618 | V20: 22551180 | W20: 22795961 | X20: 22351500 | Y20: =Y21-Y22 -> 19603162 | Z20: =Z21-Z22 -> 19665354 | AA20: =AA21-AA22 -> 22744932 | AB20: =AB21-AB22 -> 22872304 | AC20: =AC21-AC22 -> 15525433 | AD20: =AD21-AD22 -> 12561893 | AE20: =AE21-AE22 -> 12228730 | AF20: =AF21-AF22 -> 11980831 | ... AN20: =AN21-AN22 -> 11430295 | AQ20: =AA20/Z20-1 -> 0.15659917 | AR20: =AB20/AA20-1 -> 0.0056 | AS20: =AC20/AB20-1 -> -0.32121255 | AT20: =AD20/AC20-1 -> -0.19088288 | AV20: =AVERAGE(AQ20:AU20) -> -0.087474065 | AW20: =(1+AV20)*AE20 -> 11159034 | AY20: =U20/T20*100-100 -> -0.20767509 | AZ20: =V20/U20*100-100 -> -0.58384924 | BA20: =W20/V20*100-100 -> 1.0854483 | BB20: =X20/W20*100-100 -> -1.9497357 | BC20: =Y20/X20*100-100 -> -12.295989 | BD20: =Z20/Y20*100-100 -> 0.31725504 | BE20: =AA20/Z20*100-100 -> 15.659917 | BF20: =AB20/AA20*100-100 -> 0.56 | BK20: DIY | BL20: 13851.28 | BM20: 0
B21: - Indonesia | C21: NSDH | D21: lamp 12 | E21: Ha | I21: 19039329 | L21: 18461538 | M21: 8350243.4 | N21: 36701812 | O21: 18961249 | P21: 13670535 | Q21: 13670535 | R21: 13670535 | S21: 22792495 | T21: 22730824 | U21: 22683618 | V21: 22551180 | W21: 22795961 | X21: 22351500 | Y21: 19603162 | Z21: 19665354 | AA21: 22744932 | AB21: =(100+0.56)/100*AA21 -> 22872304 | AC21: 15525433 | AD21: 12561893 | AE21: 12228730 | AF21: 11980831 | AG21: =11745407.44 -> 11745407 | AH21: 11693458 | AI21: 11572023 | AJ21: 11554196 | AK21: 11335500 | AL21: 11215600 | AM21: =AVERAGE(AH21:AL21) -> 11474155 | AN21: =AVERAGE(AI21:AM21) -> 11430295 | AQ21: =AA21/Z21-1 -> 0.15659917 | AR21: =AB21/AA21-1 -> 0.0056 | AS21: =AC21/AB21-1 -> -0.32121255 | AT21: =AD21/AC21-1 -> -0.19088288 | AU21: =AE21/AD21-1 -> -0.026521722 | AV21: =AVERAGE(AQ21:AU21) -> -0.075283596 | AW21: =AVERAGE(AA21:AE21) -> 17186658 | AX21: =AVERAGE(AA21:AE21) -> 17186658 | AY21: =U21/T21*100-100 -> -0.20767509 | AZ21: =V21/U21*100-100 -> -0.58384924 | BA21: =W21/V21*100-100 -> 1.0854483 | BB21: =X21/W21*100-100 -> -1.9497357 | BC21: =Y21/X21*100-100 -> -12.295989 | BD21: =Z21/Y21*100-100 -> 0.31725504 | BE21: =AA21/Z21*100-100 -> 15.659917 | BF21: =AVERAGE(BA21:BE21) -> 0.56337898 | BK21: Jatim | BL21: 782772 | BM21: 0
B22: - Jawa | C22: Perhutani | D22: lamp 13 | E22: Ha | I22: 0 | L22: 0 | M22: 0 | N22: 0 | O22: 0 | P22: 0 | Q22: 0 | R22: 0 | S22: 0 | T22: 0 | U22: 0 | V22: 0 | W22: 0 | X22: 0 | Y22: 0 | Z22: 0 | AA22: 0 | AC22: 0 | AD22: 0 | AE22: 0 | AF22: 0 | AW22: =(1+AV22)*AE22 -> 0 | AY22: =U22/T22*100-100 -> #DIV/0! | AZ22: =V22/U22*100-100 -> #DIV/0! | BA22: =W22/V22*100-100 -> #DIV/0! | BB22: =X22/W22*100-100 -> #DIV/0! | BC22: =Y22/X22*100-100 -> #DIV/0! | BD22: =Z22/Y22*100-100 -> #DIV/0! | BE22: =AA22/Z22*100-100 -> #DIV/0! | BF22: =AB22/AA22*100-100 -> #DIV/0! | BK22: JAWA | BL22: =SUM(BL16:BL21) -> 1389104.6 | BM22: =SUM(BM16:BM21) -> 423521
A23: 9 | B23: Luas Hutan Produksi Seluruhnya Luar Jawa: | C23: = jumlah (6)+(7)+(8) | E23: Ha | I23: 79997309 | L23: 79477969 | M23: 64958830 | N23: 97675807 | O23: 79235144 | P23: 55754361 | Q23: 55761226 | R23: 55761226 | S23: 80075197 | T23: 79420288 | U23: 79369287 | V23: =V20+V17+V14 -> 79236849 | W23: =W20+W17+W14 -> 78951670 | X23: =X20+X17+X14 -> 80705195 | Y23: =Y20+Y17+Y14 -> 75987305 | Z23: =Z20+Z17+Z14 -> 75957798 | AA23: =AA20+AA17+AA14 -> 79634296 | AB23: =AB20+AB17+AB14 -> 79626003 | AC23: =AC20+AC17+AC14 -> 69240753 | ... AN23: =AN20+AN17+AN14 -> 65283310 | AQ23: =AA23/Z23-1 -> 0.04840184 | AR23: =AB23/AA23-1 -> -0.00010413904 | AS23: =AC23/AB23-1 -> -0.13042535 | AT23: =AD23/AC23-1 -> -0.040424002 | AV23: =AVERAGE(AQ23:AU23) -> -0.030637913 | AW23: =(1+AV23)*AE23 -> 64118758 | AY23: =U23/T23*100-100 -> -0.06421742 | AZ23: =V23/U23*100-100 -> -0.1668632 | BA23: =W23/V23*100-100 -> -0.3599065 | BB23: =X23/W23*100-100 -> 2.2210107 | BC23: =Y23/X23*100-100 -> -5.8458315 | BD23: =Z23/Y23*100-100 -> -0.038831238 | BE23: =AA23/Z23*100-100 -> 4.840184 | BF23: =AB23/AA23*100-100 -> -0.010413904
B24: - Indonesia | E24: Ha | I24: 82011641 | L24: 81498042 | M24: 66978902 | N24: 99548087 | O24: 81107424 | P24: 57702825 | Q24: 57709690 | R24: 57709690 | S24: 81852204 | T24: 81196773 | U24: 81150941 | V24: 81018503 | W24: =W21+W18+W15 -> 80792976 | X24: =X21+X18+X15 -> 82844100 | Y24: =Y21+Y18+Y15 -> 78123237 | Z24: =Z21+Z18+Z15 -> 78090228 | AA24: =AA21+AA18+AA15 -> 81825122 | AB24: =AB21+AB18+AB15 -> 81873223 | AC24: =AC21+AC18+AC15 -> 72109280 | AD24: =AD21+AD18+AD15 -> 68636871 | ... AN24: =AN21+AN18+AN15 -> 67477283 | AQ24: =AA24/Z24-1 -> 0.047827921 | AR24: =AB24/AA24-1 -> 0.00058786009 | AS24: =AC24/AB24-1 -> -0.11925686 | AT24: =AD24/AC24-1 -> -0.048154818 | AV24: =AVERAGE(AQ24:AU24) -> -0.029748973 | AW24: =(1+AV24)*AE24 -> 66302267 | AY24: =U24/T24*100-100 -> -0.056445174 | AZ24: =V24/U24*100-100 -> -0.16319975 | BA24: =W24/V24*100-100 -> -0.27836519 | BB24: =X24/W24*100-100 -> 2.5387405 | BC24: =Y24/X24*100-100 -> -5.6984897 | BD24: =Z24/Y24*100-100 -> -0.042252563 | BE24: =AA24/Z24*100-100 -> 4.7827921 | BF24: =AB24/AA24*100-100 -> 0.058786009
B25: - Jawa | E25: Ha | I25: 2014331.5 | L25: 2020073 | M25: 2020072.2 | N25: 1872280 | O25: 1872280 | P25: 1948463.3 | Q25: 1948463.3 | R25: 1948463.3 | S25: 1777006.8 | T25: 1776484.7 | U25: 1781654.7 | V25: 1781654.7 | W25: =W22+W19+W16 -> 1841306 | X25: =X22+X19+X16 -> 2138905 | Y25: =Y22+Y19+Y16 -> 2135932.2 | Z25: =Z22+Z19+Z16 -> 2132429.9 | AA25: =AA22+AA19+AA16 -> 2190826 | AB25: =AB22+AB19+AB16 -> 2247220.8 | AC25: =AC22+AC19+AC16 -> 2868527 | AD25: =AD22+AD19+AD16 -> 2195106.1 | ... AN25: =AN22+AN19+AN16 -> 2193972.5 | AQ25: =AA25/Z25-1 -> 0.027384749 | AR25: =AB25/AA25-1 -> 0.025741324 | AS25: =AC25/AB25-1 -> 0.27647762 | AT25: =AD25/AC25-1 -> -0.23476192 | AU25: =AE25/AD25-1 -> -0.0023915473 | AV25: =AVERAGE(AQ25:AU25) -> 0.018490045 | AW25: =(1+AV25)*AE25 -> 2230346.9 | AY25: =U25/T25*100-100 -> 0.29102417 | AZ25: =V25/U25*100-100 -> 0 | BA25: =W25/V25*100-100 -> 3.3480819 | BB25: =X25/W25*100-100 -> 16.162387 | BC25: =Y25/X25*100-100 -> -0.13898701 | BD25: =Z25/Y25*100-100 -> -0.16396861 | BE25: =AA25/Z25*100-100 -> 2.7384749 | BF25: =AB25/AA25*100-100 -> 2.5741324
A26: 10 | B26: Banyaknya kerugian & Kerusakan Hutan (Kayu Bulat) | C26: NSDH | E26: M3 | P26: 42466.6 | Q26: 279014.02 | R26: 233637.23 | S26: 228273.6 | W26: 3650.59 | X26: 14632.36 | AW26: =(1+AV26)*AE26 -> 0 | AY26: =U26/T26*100-100 -> #DIV/0! | AZ26: =V26/U26*100-100 -> #DIV/0! | BA26: =W26/V26*100-100 -> #DIV/0! | BB26: =X26/W26*100-100 -> 300.82178 | BC26: =Y26/X26*100-100 -> -100 | BD26: =Z26/Y26*100-100 -> #DIV/0! | BE26: =AA26/Z26*100-100 -> #DIV/0! | BF26: =AB26/AA26*100-100 -> #DIV/0!
A27: 12 | B27: Luas Hutan yang Rusak | C27: NSDH | E27: Ha | P27: 253740.56 | Q27: 2747678.6 | R27: 2993759.1 | S27: 5384269.3 | AW27: =(1+AV27)*AE27 -> 0 | AY27: =U27/T27*100-100 -> #DIV/0! | AZ27: =V27/U27*100-100 -> #DIV/0! | BA27: =W27/V27*100-100 -> #DIV/0! | BB27: =X27/W27*100-100 -> #DIV/0! | BC27: =Y27/X27*100-100 -> #DIV/0! | BD27: =Z27/Y27*100-100 -> #DIV/0! | BE27: =AA27/Z27*100-100 -> #DIV/0! | BF27: =AB27/AA27*100-100 -> #DIV/0!
A28: 13 | B28: Luas Konversi Hutan untuk Transmigrasi | C28: NSDH | D28: lamp 10 | E28: Ha | X28: 43465 | AA28: 4051.61 | AB28: 6328.13 | AC28: 5307.51 | AD28: =993.25 -> 993.25 | AF28: =3774.43 -> 3774.43 | AG28: 195.76 | AH28: 0 | AI28: 2772.46 | AJ28: 0 | AK28: 0 | AL28: 0 | AM28: 0 | AN28: 0 | AQ28: =AA28/Z28-1 -> #DIV/0! | AR28: =AB28/AA28-1 -> 0.56188034 | AS28: =AC28/AB28-1 -> -0.16128303 | AT28: =AD28/AC28-1 -> -0.81285951 | AU28: =AE29/AD28-1 -> 66.615787 | AV28: =AVERAGE(AQ28:AU28) -> #DIV/0! | AW28: =(1+AV28)*AE29 -> #DIV/0! | AY28: =U28/T28*100-100 -> #DIV/0! | AZ28: =V28/U28*100-100 -> #DIV/0! | BA28: =W28/V28*100-100 -> #DIV/0! | BB28: =X28/W28*100-100 -> #DIV/0! | BC28: =Y28/X28*100-100 -> -100 | BD28: =Z28/Y28*100-100 -> #DIV/0! | BE28: =AA28/Z28*100-100 -> #DIV/0! | BF28: =AB28/AA28*100-100 -> 56.188034 | BN28: buku statistik pktl tabel IV.2 dan IV.3
A29: 14 | B29: Luas Konversi Hutan untuk Budidaya Non Hutan | C29: NSDH | D29: lamp 11 | E29: Ha | P29: 235101.65 | Q29: 13612.3 | R29: 0 | S29: 0 | T29: 0 | U29: 59744.56 | X29: 77216.73 | AA29: 540580.71 | AB29: 652130.77 | AC29: 170979.77 | AD29: 367931.98 | AE29: =67159.38 -> 67159.38 | AF29: 186579.89 | AG29: 249338.92 | AH29: 76719.08 | AI29: 75276.18 | AJ29: 31234.22 | AK29: 86445.7 | AL29: 32943.5 | AM29: =AVERAGE(AH29:AL29) -> 60523.736 | AN29: =AVERAGE(AI29:AM29) -> 57284.667 | AQ29: =AA29/Z29-1 -> #DIV/0! | AR29: =AB29/AA29-1 -> 0.20635228 | AS29: =AC29/AB29-1 -> -0.73781368 | AT29: =AD29/AC29-1 -> 1.1519036 | AU29: =#REF!/AD29-1 -> #REF! | AV29: =AVERAGE(AQ29:AU29) -> #DIV/0! | AW29: =(1+AV29)*#REF! -> #DIV/0! | AY29: =U29/T29*100-100 -> #DIV/0! | AZ29: =V29/U29*100-100 -> -100 | BA29: =W29/V29*100-100 -> #DIV/0! | BB29: =X29/W29*100-100 -> #DIV/0! | BC29: =Y29/X29*100-100 -> -100 | BD29: =Z29/Y29*100-100 -> #DIV/0! | BE29: =AA29/Z29*100-100 -> #DIV/0! | BF29: =AB29/AA29*100-100 -> 20.635228 | BN29: https://pktl.menlhk.go.id/publikasi/buku_statistik
A30: 15 | B30: Luas Hutan (Pinjam Pakai) untuk Pemb. Non Hutan | C30: NSDH | D30: lamp 39 | E30: Ha | P30: 90022.08 | Q30: 44494.37 | R30: 21466.32 | S30: 13294.85 | AA30: 41940.93 | AD30: =11214.82+34521.53+6320.36 -> 52056.71 | AE30: =3159.43+7522.92+1999.29 -> 12681.64 | AQ30: =AA30/Z30-1 -> #DIV/0! | AR30: =AB30/AA30-1 -> -1 | AS30: =AC30/AB30-1 -> #DIV/0! | AT30: =AD30/AC30-1 -> #DIV/0! | AU30: =AE30/AD30-1 -> -0.75638799 | AV30: =AVERAGE(AQ30:AU30) -> #DIV/0! | AW30: =(1+AV30)*AE30 -> #DIV/0! | AY30: =U30/T30*100-100 -> #DIV/0! | AZ30: =V30/U30*100-100 -> #DIV/0! | BA30: =W30/V30*100-100 -> #DIV/0! | BB30: =X30/W30*100-100 -> #DIV/0! | BC30: =Y30/X30*100-100 -> #DIV/0! | BD30: =Z30/Y30*100-100 -> #DIV/0! | BE30: =AA30/Z30*100-100 -> #DIV/0! | BF30: =AB30/AA30*100-100 -> -100
A31: 16 | B31: Luas Konversi Hutan untuk Non Hutan | C31: NSDH | E31: Ha | P31: 325123.73 | Q31: 58106.67 | R31: 21466.32 | S31: 13294.85 | AQ31: =AA31/Z31-1 -> #DIV/0! | AR31: =AB31/AA31-1 -> #DIV/0! | AS31: =AC31/AB31-1 -> #DIV/0! | AT31: =AD31/AC31-1 -> #DIV/0! | AU31: =AE31/AD31-1 -> #DIV/0! | AV31: =AVERAGE(AQ31:AU31) -> #DIV/0! | AW31: =(1+AV31)*AE31 -> #DIV/0! | AY31: =U31/T31*100-100 -> #DIV/0! | AZ31: =V31/U31*100-100 -> #DIV/0! | BA31: =W31/V31*100-100 -> #DIV/0! | BB31: =X31/W31*100-100 -> #DIV/0! | BC31: =Y31/X31*100-100 -> #DIV/0! | BD31: =Z31/Y31*100-100 -> #DIV/0! | BE31: =AA31/Z31*100-100 -> #DIV/0! | BF31: =AB31/AA31*100-100 -> #DIV/0!
A32: 17 | B32: Penanaman Hutan Rakyat/Kebun Rakyat | C32: NSDH | D32: lamp 35 hutan alam | E32: Ha | R32: 38341 | S32: 214296 | T32: 333291 | U32: 32164 | V32: 248133 | W32: =(100-(Y32/X32))/100*X32 -> 56144.322 | X32: =(100-(Z32/Y32))/100*Y32 -> 56713.83 | Y32: 56950.8 | Z32: 23697 | AA32: 51654.44 | AB32: =(100+(AA32/Z32))/100*AA32 -> 52780.397 | AC32: =(100+(AB32/AA32))/100*AB32 -> 53319.706 | AD32: =(100+(AC32/AB32))/100*AC32 -> 53858.352 | AQ32: =AA32/Z32-1 -> 1.1797882 | AR32: =AB32/AA32-1 -> 0.021797882 | AS32: =AC32/AB32-1 -> 0.010217979 | AT32: =AD32/AC32-1 -> 0.01010218 | AU32: =AE32/AD32-1 -> -1 | AV32: =AVERAGE(AQ32:AU32) -> 0.04438124 | AW32: =(1+AV32)*AE32 -> 0 | AY32: =U32/T32*100-100 -> -90.349574 | AZ32: =V32/U32*100-100 -> 671.46188 | BA32: =W32/V32*100-100 -> -77.373295 | BB32: =X32/W32*100-100 -> 1.0143644 | BC32: =Y32/X32*100-100 -> 0.41783459 | BD32: =Z32/Y32*100-100 -> -58.3904 | BE32: =AA32/Z32*100-100 -> 117.97882 | BF32: =AB32/AA32*100-100 -> 2.1797882
A33: 18 | B33: Penanaman/Rehabilitasi Tanaman Bakau | C33: NSDH | D33: lamp 39 | E33: Ha | R33: 4297 | S33: 1655 | T33: 9536 | U33: 2775 | V33: 7952 | W33: =(100-(Y33/X33))/100*X33 -> 78996.485 | X33: 79269 | Y33: 27251.5 | Z33: 69005.42 | AA33: 2920.09 | AB33: =(100+(AA33/Z33))/100*AA33 -> 2921.3257 | AC33: 12403 | AQ33: =AA33/Z33-1 -> -0.95768318 | AR33: =AB33/AA33-1 -> 0.00042316821 | AS33: =AC33/AB33-1 -> 3.2456752 | AT33: =AD33/AC33-1 -> -1 | AU33: =AE33/AD33-1 -> #DIV/0! | AV33: =AVERAGE(AQ33:AU33) -> #DIV/0! | AW33: =(1+AV33)*AE33 -> #DIV/0! | AY33: =U33/T33*100-100 -> -70.899748 | AZ33: =V33/U33*100-100 -> 186.55856 | BA33: =W33/V33*100-100 -> 893.41656 | BB33: =X33/W33*100-100 -> 0.34497105 | BC33: =Y33/X33*100-100 -> -65.621491 | BD33: =Z33/Y33*100-100 -> 153.21696 | BE33: =AA33/Z33*100-100 -> -95.768318 | BF33: =AB33/AA33*100-100 -> 0.042316821
