Workbook

Sheet READ ME
A1: Data yang di-update saat penulisan Publikasi Sisnerling 2020 - 2024 (18 November 2025)
A2: Sheet Penyediaan: mengalami revisi pada Rasio NTB terhadap Output yang dihitung dari tabel SUT menggunakan SUT 2020 untuk Tahun 2020, SUT 2021 untuk 2021 sd sekarang
A3: Sheet Stok Kapital: Data stok kapital hanya dirilis oleh DNPeng setiap 5 tahun sekali. Data terakhir sampai dengan 2022. Untuk 2023 - 2024, estimasi dilakukan sendiri karena dari pihak DNPeng tidak bersedia mengestimasi
A4: Kesimpulan: Neraca Terintegrasi 2020 - 2024 tidak ada angka tetap karena perubahan data produksi neraca aset mineral. Oleh karena itu, dilakukan pula update rasio penyediaan untuk tahun 2020 - 2024 (meskipun ini tidak beda jauh)
A6: PETUNJUK WARNA SHEET
B7: Meminta dengan mengirimkan format ke DNPeng (PDB ADHB dan Penyusutan) atau ke PJ Neraca (Aset Moneter, ingat angka tetap tidak boleh berubah)
B8: Perhitungan dengan Sheet "SUT (Rasio Penyediaan)" sebagai sheet bantu, SUT Nas bisa meminta ke KNPN
B9: Perhitungan dan meminta nilai Stok Akhir tahun berjalan ke DNPeng (Stok Kapital) dan jumlah penduduk ke PJ PDRB DAU
B10: Sheet bantu
B11: Full Perhitungan

Sheet PDB ADHB
B1: =C1-1 -> 2014 | C1: 2015 | D1: =C1+1 -> 2016 | E1: =C1+2 -> 2017 | F1: 2018 | G1: 2019 | H1: 2020 | I1: 2021 | J1: 2022 | K1: 2023* | L1: 2024**
A2: PDB Penggunaan (Seri 2010) | B2: =B1 -> 2014 | C2: =C1 -> 2015 | D2: =D1 -> 2016 | E2: =E1 -> 2017 | F2: =F1 -> 2018 | G2: =G1 -> 2019 | H2: =H1 -> 2020 | I2: =I1 -> 2021 | ... L2: =L1 -> 2024**
A6: 1. Pengeluaran Konsumsi Rumahtangga | B6: 5915194.2 | C6: 6490929.7 | D6: 7027023.5 | E6: 7623056.1 | F6: 8274214.4 | G6: 8965837.4 | H6: 8899917.6 | I6: 9236049.1 | J6: 10161713 | K6: 11109566 | L6: 11964947
A7: a. Makanan dan Minuman, Selain Restoran | B7: 2247450.6 | C7: 2495433.4 | D7: 2759335 | E7: 2986882 | F7: 3255945.9 | G7: 3529891.7 | H7: 3669993.5 | I7: 3803853.4 | J7: 4174005.2 | K7: 4542099.3 | L7: 4925152.2
A8: b. Pakaian, Alas Kaki dan Jasa Perawatannya | B8: 221633.2 | C8: 239644.36 | D8: 256951.35 | E8: 273621.29 | F8: 296092.19 | G8: 321705.24 | H8: 316446.6 | I8: 319886.33 | J8: 339007.54 | K8: 358339.99 | L8: 370749.13
A9: c. Perumahan dan Perlengkapan Rumahtangga | B9: 774867.36 | C9: 849310.41 | D9: 902678.59 | E9: 980387.89 | F9: 1060517 | G9: 1144776.7 | H9: 1186900 | I9: 1223129.7 | J9: 1296548 | K9: 1375977.7 | L9: 1445425.7
A10: d. Kesehatan dan Pendidikan | B10: 394267.5 | C10: 433073.01 | D10: 473136.67 | E10: 515134.08 | F10: 558969.26 | G10: 616504.64 | H10: 652831.63 | I10: 677159.59 | J10: 708941.91 | K10: 755651.11 | L10: 801067.94
A11: e. Transportasi dan Komunikasi | B11: 1420289.1 | C11: 1518754.7 | D11: 1597642.8 | E11: 1748905.2 | F11: 1894012.6 | G11: 2042268.5 | H11: 1796642.8 | I11: 1861337.4 | J11: 2165432.5 | K11: 2469012.4 | L11: 2673353
A12: f. Restoran dan Hotel | B12: 570464.73 | C12: 636959.26 | D12: 695938.8 | E12: 755577.03 | F12: 826225.85 | G12: 903979.63 | H12: 853216.32 | I12: 909182.31 | J12: 1006405.8 | K12: 1104034.4 | L12: 1201577.6
A13: g. Lainnya | B13: 286221.7 | C13: 317754.5 | D13: 341340.32 | E13: 362548.57 | F13: 382451.64 | G13: 406711.02 | H13: 423886.75 | I13: 441500.39 | J13: 471372.49 | K13: 504451.18 | L13: 547621.01
A14: 2. Pengeluaran Konsumsi LNPRT | B14: 124242 | C14: 130950.57 | D14: 144499.38 | E14: 160594.43 | F14: 180893.25 | G14: 206094.49 | H14: 201451.56 | I14: 207916.21 | J14: 228999.01 | K14: 261210.19 | L14: 300080.4
A15: 3. Pengeluaran Konsumsi Pemerintah | B15: 996197.44 | C15: 1123749.9 | D15: 1181613.1 | E15: 1239469.7 | F15: 1338638.6 | G15: 1394615.1 | H15: 1491171.7 | I15: 1569830.3 | J15: 1506284.8 | K15: 1557495.6 | L15: 1711550.8
A16: a. Konsumsi Kolektif | B16: 622774.29 | C16: 691754.84 | D16: 731393.32 | E16: 761297.46 | F16: 821700.18 | G16: 868092.34 | H16: 897223.32 | I16: 902552.44 | J16: 904343.88 | K16: 963842.56 | L16: 1076657.1
A17: b. Konsumsi Individu | B17: 373423.15 | C17: 431995.03 | D17: 450219.82 | E17: 478172.26 | F17: 516938.4 | G17: 526522.72 | H17: 593948.34 | I17: 667277.85 | J17: 601940.9 | K17: 593653.01 | L17: 634893.75
... A37: 8. PRODUK DOMESTIK BRUTO | B37: 10569705 | C37: 11526333 | D37: 12401728 | E37: 13589826 | F37: 14838756 | G37: 15832657 | H37: 15443353 | I37: 16976751 | J37: 19588460 | K37: 20892348 | L37: 22138964

Sheet Penyusutan
A1: National Income (Billion Rp) | B1: PENDAPATAN NASIONAL
A3: English | B3: Indonesia | C3: ='PDB ADHB'!C1-1 -> 2014 | I3: ='PDB ADHB'!C1 -> 2015 | O3: ='PDB ADHB'!D1 -> 2016 | U3: ='PDB ADHB'!E1 -> 2017 | AA3: ='PDB ADHB'!F1 -> 2018 | AG3: ='PDB ADHB'!G1 -> 2019 | AM3: ='PDB ADHB'!H1 -> 2020 | AS3: 2021 | AY3: 2022 | BE3: 2023* | BK3: 2024**
C4: Q1 | D4: Q2 | E4: Q3 | F4: Q4 | G4: Total | I4: Q1 | J4: Q2 | K4: Q3 | L4: Q4 | M4: Total | O4: Q1 | P4: Q2 | Q4: Q3 | R4: Q4 | S4: Total | U4: Q1 | V4: Q2 | W4: Q3 | X4: Q4 | Y4: Total | AA4: Q1 | AB4: Q2 | AC4: Q3 | AD4: Q4 | AE4: Total | AG4: Q1 | AH4: Q2 | AI4: Q3 | AJ4: Q4 | AK4: Total | AM4: Q1 | AN4: Q2 | AO4: Q3 | AP4: Q4 | AQ4: Total | AS4: Q1 | AT4: Q2 | AU4: Q3 | AV4: Q4 | AW4: Total | AY4: Q1 | AZ4: Q2 | BA4: Q3 | BB4: Q4 | BC4: Total | BE4: Q1 | BF4: Q2 | BG4: Q3 | BH4: Q4 | BI4: Total | BK4: Q1 | BL4: Q2 | BM4: Q3 | BN4: Q4 | BO4: Total
A6: GDP | B6: 1. PRODUK DOMESTIK BRUTO | C6: 2506300.2 | D6: 2618947.3 | E6: 2746762.4 | F6: 2697695.4 | G6: 10569705 | I6: 2728180.7 | J6: 2867948.4 | K6: 2990645 | L6: 2939558.7 | M6: 11526333 | O6: 2929269 | P6: 3073536.7 | Q6: 3205019 | R6: 3193903.8 | S6: 12401728 | U6: 3228172.2 | V6: 3366787.3 | W6: 3504138.5 | X6: 3490727.7 | Y6: 13589826 | AA6: 3510363.1 | AB6: 3686836.4 | AC6: 3842343 | AD6: 3799213.5 | AE6: 14838756 | AG6: 3782618.3 | AH6: 3964074.7 | AI6: 4067358 | AJ6: 4018606.2 | AK6: 15832657 | AM6: 3923347.9 | AN6: 3690742.2 | AO6: 3897851.9 | AP6: 3931411.2 | AQ6: 15443353 | AS6: 3972933 | AT6: 4178022 | AU6: 4327383.9 | AV6: 4498412.5 | AW6: =SUM(AS6:AV6) -> 16976751 | AY6: 4508662.5 | AZ6: 4898031.8 | BA6: 5066968.2 | BB6: 5114797.4 | BC6: 19588460 | BE6: 5071497.2 | BF6: 5223290.3 | BG6: 5294903.3 | BH6: 5302657.7 | BI6: 20892348 | BK6: 5288576.6 | BL6: 5536588.5 | BM6: 5638869.1 | BN6: 5674929.8 | BO6: 22138964
A8: Net factor income | B8: 2. Pendapatan Neto Terhadap Luar Negeri
A9: from abroad | B9: Atas Faktor Produksi | C9: -86145.715 | D9: -92461.23 | E9: -86577.572 | F9: -89208.618 | G9: -354393.14 | I9: -91603.357 | J9: -95751.318 | K9: -103974.82 | L9: -91010.272 | M9: -382339.77 | O9: -99190.519 | P9: -106805.68 | Q9: -107404.25 | R9: -83612.608 | S9: -397013.05 | U9: -102445.14 | V9: -109472.77 | W9: -114620.47 | X9: -104067.4 | Y9: -430605.78 | AA9: -100730.17 | AB9: -113256.13 | AC9: -117186.93 | AD9: -111010.51 | AE9: -442183.75 | AG9: -115717.82 | AH9: -127792.47 | AI9: -119846.92 | AJ9: -117963.85 | AK9: -481321.06 | AM9: -113407.13 | AN9: -93393.279 | AO9: -109659.96 | AP9: -107586.99 | AQ9: -424047.35 | AS9: -96526.974 | AT9: -116435.92 | AU9: -119892.38 | AV9: -128041.58 | AW9: =SUM(AS9:AV9) -> -460896.85 | AY9: -111721.79 | AZ9: -132028.69 | BA9: -134333.94 | BB9: -151014.22 | BC9: -529098.63 | BE9: -136751.88 | BF9: -139543.11 | BG9: -132769.2 | BH9: -143253.48 | BI9: -552317.67 | BK9: -141117.02 | BL9: -156980.77 | BM9: -141388.25 | BN9: -144953.23 | BO9: -584439.26
A10: from | B10: a. Pendapatan Dari Luar Negeri | C10: 4604.8268 | D10: 7875.6713 | E10: 7424.1909 | F10: 5161.8559 | G10: 25066.545 | I10: 5958.7541 | J10: 9442.5882 | K10: 9730.7274 | L10: 12695.067 | M10: 37827.136 | O10: 9587.2088 | P10: 11408.314 | Q10: 15377.927 | R10: 17122.502 | S10: 53495.952 | U10: 15681.845 | V10: 18258.631 | W10: 18585.816 | X10: 21321.601 | Y10: 73847.894 | AA10: 27586.277 | AB10: 35214.297 | AC10: 25664.595 | AD10: 43608.678 | AE10: 132073.85 | AG10: 20187.837 | AH10: 32791.125 | AI10: 23347.515 | AJ10: 27521.726 | AK10: 103848.2 | AM10: 14664.763 | AN10: 20952.244 | AO10: 18316.767 | AP10: 21911.369 | AQ10: 75845.143 | AS10: 19071.262 | AT10: 25445.701 | AU10: 25820.734 | AV10: 25677.041 | AW10: =SUM(AS10:AV10) -> 96014.739 | AY10: 22030.733 | AZ10: 29125.885 | BA10: 29614.395 | BB10: 30686.797 | BC10: 111457.81 | BE10: 27174.938 | BF10: 29515.954 | BG10: 29528.135 | BH10: 33067.895 | BI10: 119286.92 | BK10: 35849.136 | BL10: 36286.224 | BM10: 39933.412 | BN10: 35817.653 | BO10: 147886.42
A11: to | B11: b. Pendapatan Ke Luar Negeri | C11: 90750.542 | D11: 100336.9 | E11: 94001.763 | F11: 94370.474 | G11: 379459.68 | I11: 97562.111 | J11: 105193.91 | K11: 113705.55 | L11: 103705.34 | M11: 420166.9 | O11: 108777.73 | P11: 118213.99 | Q11: 122782.17 | R11: 100735.11 | S11: 450509 | U11: 118126.98 | V11: 127731.4 | W11: 133206.28 | X11: 125389 | Y11: 504453.67 | AA11: 128316.44 | AB11: 148470.43 | AC11: 142851.53 | AD11: 154619.19 | AE11: 574257.59 | AG11: 135905.65 | AH11: 160583.59 | AI11: 143194.44 | AJ11: 145485.57 | AK11: 585169.26 | AM11: 128071.89 | AN11: 114345.52 | AO11: 127976.72 | AP11: 129498.36 | AQ11: 499892.5 | AS11: 115598.24 | AT11: 141881.62 | AU11: 145713.11 | AV11: 153718.62 | AW11: =SUM(AS11:AV11) -> 556911.59 | AY11: 133752.52 | AZ11: 161154.58 | BA11: 163948.33 | BB11: 181701.01 | BC11: 640556.44 | BE11: 163926.81 | BF11: 169059.07 | BG11: 162297.34 | BH11: 176321.37 | BI11: 671604.59 | BK11: 176966.15 | BL11: 193266.99 | BM11: 181321.66 | BN11: 180770.88 | BO11: 732325.68
A13: GNP | B13: 3. PRODUK NASIONAL BRUTO | C13: 2420154.5 | D13: 2526486.1 | E13: 2660184.8 | F13: 2608486.8 | G13: 10215312 | I13: 2636577.3 | J13: 2772197.1 | K13: 2886670.2 | L13: 2848548.4 | M13: 11143993 | O13: 2830078.5 | P13: 2966731 | Q13: 3097614.8 | R13: 3110291.2 | S13: 12004715 | U13: 3125727.1 | V13: 3257314.5 | W13: 3389518 | X13: 3386660.3 | Y13: 13159220 | AA13: 3409632.9 | AB13: 3573580.3 | AC13: 3725156.1 | AD13: 3688203 | AE13: 14396572 | AG13: 3666900.5 | AH13: 3836282.2 | AI13: 3947511.1 | AJ13: 3900642.4 | AK13: 15351336 | AM13: 3809940.8 | AN13: 3597348.9 | AO13: 3788191.9 | AP13: 3823824.2 | AQ13: 15019306 | AS13: 3876406 | AT13: 4061586.1 | AU13: 4207491.5 | AV13: 4370370.9 | AW13: =SUM(AS13:AV13) -> 16515855 | AY13: 4396940.7 | AZ13: 4766003.1 | BA13: 4932634.3 | BB13: 4963783.2 | BC13: 19059361 | BE13: 4934745.3 | BF13: 5083747.2 | BG13: 5162134.1 | BH13: 5159404.2 | BI13: 20340031 | BK13: 5147459.6 | BL13: 5379607.7 | BM13: 5497480.9 | BN13: 5529976.6 | BO13: 21554525
A15: Less indirect taxes (nett) | B15: 4. Dikurangi Pajak Tidak Langsung Neto (a-b) | C15: 102291.54 | D15: 30486.585 | E15: 83121.49 | F15: 116960.94 | G15: 332860.55 | I15: 87674.862 | J15: 129367.32 | K15: 145472.35 | L15: 232456.28 | M15: 594970.82 | O15: 88610.864 | P15: 120509.61 | Q15: 163777.57 | R15: 167038.13 | S15: 539936.16 | U15: 110813 | V15: 135702.91 | W15: 176178.35 | X15: 263268.69 | Y15: 685962.96 | AA15: 121744.84 | AB15: 179969.29 | AC15: 191443.81 | AD15: 237495.09 | AE15: 730653.03 | AG15: 134804.3 | AH15: 183741.32 | AI15: 212345.07 | AJ15: 260169.68 | AK15: 791060.36 | AM15: 138860.55 | AN15: 145731.52 | AO15: 153926.77 | AP15: 218501.36 | AQ15: 657020.2 | AS15: 162844.79 | AT15: 183303.47 | AU15: 198876.38 | AV15: 253834.98 | AW15: =SUM(AS15:AV15) -> 798859.62 | AY15: 206463.61 | AZ15: 264152.96 | BA15: 265377.68 | BB15: 243520.28 | BC15: 979514.52 | BE15: 274752.32 | BF15: 237863.59 | BG15: 263335.17 | BH15: 275147.55 | BI15: 1051098.6 | BK15: 242061.23 | BL15: 233823.44 | BM15: 289341.5 | BN15: 263467.92 | BO15: 1028694.1
A16: Indirect taxes | B16: a. Pajak Tidak Langsung | C16: 141907.81 | D16: 166338.54 | E16: 177874.9 | F16: 212593.64 | G16: 698714.88 | I16: 135782.99 | J16: 161525.13 | K16: 194205.36 | L16: 257925.69 | M16: 749439.17 | O16: 109436.5 | P16: 163089.5 | Q16: 188182.12 | R16: 218646.85 | S16: 679354.97 | U16: 124395.43 | V16: 171580.15 | W16: 205100.13 | X16: 318727.77 | Y16: 819803.48 | AA16: 137841.53 | AB16: 216441.44 | AC16: 232450 | AD16: 320995.89 | AE16: 907728.86 | AG16: 155109.49 | AH16: 231657.21 | AI16: 256785.25 | AJ16: 326196.27 | AK16: 969748.22 | AM16: 158451.32 | AN16: 187237.86 | AO16: 187918.26 | AP16: 272304.62 | AQ16: 805912.05 | AS16: 183883.98 | AT16: 223141.84 | AU16: 239722.41 | AV16: 321309.54 | AW16: =SUM(AS16:AV16) -> 968057.77 | AY16: 240691.4 | AZ16: 313744.97 | BA16: 323981.14 | BB16: 315737.33 | BC16: 1194154.8 | BE16: 299666.98 | BF16: 290233.21 | BG16: 307731.95 | BH16: 370981.28 | BI16: 1268613.4 | BK16: 270183.61 | BL16: 286649.14 | BM16: 359032.46 | BN16: 347947.34 | BO16: 1263812.6
A17: Subsidy | B17: b. Subsidi | C17: 39616.27 | D17: 135851.95 | E17: 94753.411 | F17: 95632.699 | G17: 365854.33 | I17: 48108.131 | J17: 32157.807 | K17: 48733.009 | L17: 25469.41 | M17: 154468.36 | O17: 20825.636 | P17: 42579.898 | Q17: 24404.548 | R17: 51608.727 | S17: 139418.81 | U17: 13582.43 | V17: 35877.233 | W17: 28921.773 | X17: 55459.08 | Y17: 133840.52 | AA17: 16096.691 | AB17: 36472.147 | AC17: 41006.189 | AD17: 83500.804 | AE17: 177075.83 | AG17: 20305.194 | AH17: 47915.887 | AI17: 44440.187 | AJ17: 66026.594 | AK17: 178687.86 | AM17: 19590.767 | AN17: 41506.34 | AO17: 33991.485 | AP17: 53803.263 | AQ17: 148891.85 | AS17: 21039.188 | AT17: 39838.373 | AU17: 40846.031 | AV17: 67474.562 | AW17: =SUM(AS17:AV17) -> 169198.15 | AY17: 34227.791 | AZ17: 49592.01 | BA17: 58603.463 | BB17: 72217.059 | BC17: 214640.32 | BE17: 24914.654 | BF17: 52369.627 | BG17: 44396.78 | BH17: 95833.736 | BI17: 217514.8 | BK17: 28122.374 | BL17: 52825.705 | BM17: 69690.962 | BN17: 84479.419 | BO17: 235118.46
A19: Less depreciation | B19: 5. Dikurangi Penyusutan | C19: 492629.85 | D19: 492629.85 | E19: 492629.85 | F19: 492629.85 | G19: 1970519.4 | I19: 532359.55 | J19: 532359.55 | K19: 532359.55 | L19: 532359.55 | M19: 2129438.2 | O19: 537503.12 | P19: 493457.11 | Q19: 508494.71 | R19: 496234.45 | S19: 2035689.4 | U19: 544279.01 | V19: 603991.19 | W19: 631021.23 | X19: 651646 | Y19: 2430937.4 | AA19: 632063.02 | AB19: 680456.15 | AC19: 733280.71 | AD19: 754230.33 | AE19: 2800030.2 | AG19: 755612.38 | AH19: 773271.26 | AI19: 820470.28 | AJ19: 818747.21 | AK19: 3168101.1 | AM19: 847342.33 | AN19: 677857.62 | AO19: 700337.84 | AP19: 718267.21 | AQ19: 2943805 | AS19: 766637.78 | AT19: 758413.02 | AU19: 785163.52 | AV19: 836194.78 | AW19: =SUM(AS19:AV19) -> 3146409.1 | AY19: 884430.52 | AZ19: 900088.01 | BA19: 915489.23 | BB19: 986036.62 | BC19: 3686044.4 | BE19: 1015112.3 | BF19: 1029237.1 | BG19: 1023909.2 | BH19: 1070046.1 | BI19: 4138304.5 | BK19: 1078127.5 | BL19: 1096673.1 | BM19: 1103853.4 | BN19: 1147605.2 | BO19: 4426259.2
A21: National Income | B21: 6. PENDAPATAN NASIONAL | C21: 1825233.1 | D21: 2003369.6 | E21: 2084433.5 | F21: 1998896 | G21: 7911932.2 | I21: 2016542.9 | J21: 2110470.2 | K21: 2208838.3 | L21: 2083732.6 | M21: 8419584 | O21: 2203964.5 | P21: 2352764.3 | Q21: 2425342.5 | R21: 2447018.6 | S21: 9429089.9 | U21: 2470635 | V21: 2517620.4 | W21: 2582318.4 | X21: 2471745.6 | Y21: 10042320 | AA21: 2655825.1 | AB21: 2713154.8 | AC21: 2800431.5 | AD21: 2696477.6 | AE21: 10865889 | AG21: 2776483.8 | AH21: 2879269.7 | AI21: 2914695.7 | AJ21: 2821725.5 | AK21: 11392175 | AM21: 2823737.9 | AN21: 2773759.8 | AO21: 2933927.3 | AP21: 2887055.6 | AQ21: 11418481 | AS21: 2946923.5 | AT21: 3119869.6 | AU21: 3223451.6 | AV21: 3280341.2 | AW21: =SUM(AS21:AV21) -> 12570586 | AY21: 3306046.6 | AZ21: 3601762.1 | BA21: 3751767.4 | BB21: 3734226.3 | BC21: 14393802 | BE21: 3644880.7 | BF21: 3816646.5 | BG21: 3874889.8 | BH21: 3814210.6 | BI21: 15150628 | BK21: 3827270.9 | BL21: 4049111.2 | BM21: 4104286 | BN21: 4118903.5 | BO21: 16099571

Sheet SUT (Rasio Penyediaan)
A1: SUT | B1: 2010 | C1: 2016 | D1: 2019 | E1: 2020 | F1: 2021
A2: PDB (P) -> Total NTB | B2: 6683679717 | C2: 1.2171368e+10 | D2: 1.5346957e+10 | E2: 1.5049222e+10 | F2: 1.6342833e+10
A3: TOP SOP | B3: 180453318 | C3: 4.7445005e+08 | D3: 6.3746209e+08 | E3: 5.7129477e+08 | F3: 7.1906341e+08
A4: Output domestik | B4: 13109120481 | C4: 2.3230338e+10 | D4: 2.9585178e+10 | E4: 2.8700251e+10 | F4: 3.1335746e+10
A5: Rasio Output | B5: =B4/(B2+B3) -> 1.9097999 | C5: =C4/(C2+C3) -> 1.8369977 | D5: =D4/(D2+D3) -> 1.850876 | E5: =E4/(E2+E3) -> 1.8373432 | F5: =F4/(F2+F3) -> 1.8365922

Sheet Penyediaan
A2: Kegiatan Ekonomi | B2: =E2-1 -> 2014 | E2: ='PDB ADHB'!C1 -> 2015 | H2: ='PDB ADHB'!D1 -> 2016 | K2: ='PDB ADHB'!E1 -> 2017 | N2: ='PDB ADHB'!F1 -> 2018 | Q2: ='PDB ADHB'!G1 -> 2019 | T2: ='PDB ADHB'!H1 -> 2020 | W2: ='PDB ADHB'!I1 -> 2021 | Z2: ='PDB ADHB'!J1 -> 2022 | AC2: ='PDB ADHB'!K1 -> 2023* | AF2: ='PDB ADHB'!L1 -> 2024**
B3: Total Penyediaan | C3: Total Penggunaan | D3: Produk Domestik Bruto | E3: Total Penyediaan | F3: Total Penggunaan | G3: Produk Domestik Bruto | H3: Total Penyediaan | I3: Total Penggunaan | J3: Produk Domestik Bruto | K3: Total Penyediaan | L3: Total Penggunaan | M3: Produk Domestik Bruto | N3: Total Penyediaan | O3: Total Penggunaan | P3: Produk Domestik Bruto | Q3: Total Penyediaan | R3: Total Penggunaan | S3: Produk Domestik Bruto | T3: Total Penyediaan | U3: Total Penggunaan | V3: Produk Domestik Bruto | W3: Total Penyediaan | X3: Total Penggunaan | Y3: Produk Domestik Bruto | Z3: Total Penyediaan | AA3: Total Penggunaan | AB3: Produk Domestik Bruto | AC3: Total Penyediaan | AD3: Total Penggunaan | AE3: Produk Domestik Bruto | AF3: Total Penyediaan | AG3: Total Penggunaan | AH3: Produk Domestik Bruto
A4: Industri | B4: ='SUT (Rasio Penyediaan)'!$B$5*D4 -> 20186022 | C4: =B4-D4 -> 9616316.7 | D4: ='PDB ADHB'!B37 -> 10569705 | E4: ='SUT (Rasio Penyediaan)'!$B$5*G4 -> 22012989 | F4: =E4-G4 -> 10486656 | G4: ='PDB ADHB'!C37 -> 11526333 | H4: ='SUT (Rasio Penyediaan)'!$C$5*J4 -> 22781947 | I4: =H4-J4 -> 10380218 | J4: ='PDB ADHB'!D37 -> 12401728 | K4: ='SUT (Rasio Penyediaan)'!$C$5*M4 -> 24964479 | L4: =K4-M4 -> 11374653 | M4: ='PDB ADHB'!E37 -> 13589826 | N4: ='SUT (Rasio Penyediaan)'!$C$5*P4 -> 27258761 | O4: =N4-P4 -> 12420005 | P4: ='PDB ADHB'!F37 -> 14838756 | Q4: ='SUT (Rasio Penyediaan)'!$D$5*S4 -> 29304285 | R4: =Q4-S4 -> 13471628 | S4: ='PDB ADHB'!G37 -> 15832657 | T4: ='SUT (Rasio Penyediaan)'!$E$5*V4 -> 28374740 | U4: =T4-V4 -> 12931387 | V4: ='PDB ADHB'!H37 -> 15443353 | W4: ='SUT (Rasio Penyediaan)'!$F$5*Y4 -> 31179368 | X4: =W4-Y4 -> 14202617 | Y4: ='PDB ADHB'!I37 -> 16976751 | Z4: ='SUT (Rasio Penyediaan)'!$F$5*AB4 -> 35976012 | AA4: =Z4-AB4 -> 16387552 | AB4: ='PDB ADHB'!J37 -> 19588460 | AC4: ='SUT (Rasio Penyediaan)'!$F$5*AE4 -> 38370723 | AD4: =AC4-AE4 -> 17478375 | AE4: ='PDB ADHB'!K37 -> 20892348 | AF4: ='SUT (Rasio Penyediaan)'!$F$5*AH4 -> 40660248 | AG4: =AF4-AH4 -> 18521284 | AH4: ='PDB ADHB'!L37 -> 22138964
A5: Konsumsi Akhir | C5: ='PDB ADHB'!B6+'PDB ADHB'!B14+'PDB ADHB'!B15 -> 7035633.7 | F5: ='PDB ADHB'!C6+'PDB ADHB'!C14+'PDB ADHB'!C15 -> 7745630.1 | I5: ='PDB ADHB'!D6+'PDB ADHB'!D14+'PDB ADHB'!D15 -> 8353136 | L5: ='PDB ADHB'!E6+'PDB ADHB'!E14+'PDB ADHB'!E15 -> 9023120.3 | O5: ='PDB ADHB'!F6+'PDB ADHB'!F14+'PDB ADHB'!F15 -> 9793746.3 | R5: ='PDB ADHB'!G6+'PDB ADHB'!G14+'PDB ADHB'!G15 -> 10566547 | U5: ='PDB ADHB'!H6+'PDB ADHB'!H14+'PDB ADHB'!H15 -> 10592541 | X5: ='PDB ADHB'!I6+'PDB ADHB'!I14+'PDB ADHB'!I15 -> 11013796 | AA5: ='PDB ADHB'!J6+'PDB ADHB'!J14+'PDB ADHB'!J15 -> 11896997 | AD5: ='PDB ADHB'!K6+'PDB ADHB'!K14+'PDB ADHB'!K15 -> 12928272 | AG5: ='PDB ADHB'!L6+'PDB ADHB'!L14+'PDB ADHB'!L15 -> 13976578
A6: Akumulasi | C6: ='PDB ADHB'!B18+'PDB ADHB'!B25+'PDB ADHB'!B36 -> 3613154.8 | F6: ='PDB ADHB'!C18+'PDB ADHB'!C25+'PDB ADHB'!C36 -> 3736589.3 | I6: ='PDB ADHB'!D18+'PDB ADHB'!D25+'PDB ADHB'!D36 -> 3954755.4 | L6: ='PDB ADHB'!E18+'PDB ADHB'!E25+'PDB ADHB'!E36 -> 4430927.9 | O6: ='PDB ADHB'!F18+'PDB ADHB'!F25+'PDB ADHB'!F36 -> 5203608.7 | R6: ='PDB ADHB'!G18+'PDB ADHB'!G25+'PDB ADHB'!G36 -> 5336521.6 | U6: ='PDB ADHB'!H18+'PDB ADHB'!H25+'PDB ADHB'!H36 -> 4589794.8 | X6: ='PDB ADHB'!I18+'PDB ADHB'!I25+'PDB ADHB'!I36 -> 5516746.8 | AA6: ='PDB ADHB'!J18+'PDB ADHB'!J25+'PDB ADHB'!J36 -> 6997805.3 | AD6: ='PDB ADHB'!K18+'PDB ADHB'!K25+'PDB ADHB'!K36 -> 7510418.7 | AG6: ='PDB ADHB'!L18+'PDB ADHB'!L25+'PDB ADHB'!L36 -> 7765217.9
A7: Luar Negeri | B7: ='PDB ADHB'!B31 -> 2580508 | C7: ='PDB ADHB'!B26 -> 2501424.8 | E7: ='PDB ADHB'!C31 -> 2394879.3 | F7: ='PDB ADHB'!C26 -> 2438992.7 | H7: ='PDB ADHB'!D31 -> 2273528 | I7: ='PDB ADHB'!D26 -> 2367365.2 | K7: ='PDB ADHB'!E31 -> 2606283 | L7: ='PDB ADHB'!E26 -> 2742060.5 | N7: ='PDB ADHB'!F31 -> 3275145.3 | O7: ='PDB ADHB'!F26 -> 3116546.3 | Q7: ='PDB ADHB'!G31 -> 3013944.2 | R7: ='PDB ADHB'!G26 -> 2943532.9 | T7: ='PDB ADHB'!H31 -> 2415496 | U7: ='PDB ADHB'!H26 -> 2676513.5 | W7: ='PDB ADHB'!I31 -> 3189626.5 | X7: ='PDB ADHB'!I26 -> 3635835.4 | Z7: ='PDB ADHB'!J31 -> 4106085.7 | AA7: ='PDB ADHB'!J26 -> 4799743 | AC7: ='PDB ADHB'!K31 -> 4091231.5 | AD7: ='PDB ADHB'!K26 -> 4544889.6 | AF7: ='PDB ADHB'!L31 -> 4513987.4 | AG7: ='PDB ADHB'!L26 -> 4911155.7
A8: Total | B8: =SUM(B4:B7) -> 22766530 | C8: =SUM(C4:C7) -> 22766530 | E8: =SUM(E4:E7) -> 24407868 | F8: =SUM(F4:F7) -> 24407868 | H8: =SUM(H4:H7) -> 25055475 | I8: =SUM(I4:I7) -> 25055475 | K8: =SUM(K4:K7) -> 27570762 | L8: =SUM(L4:L7) -> 27570762 | N8: =SUM(N4:N7) -> 30533906 | O8: =SUM(O4:O7) -> 30533906 | Q8: =SUM(Q4:Q7) -> 32318229 | R8: =SUM(R4:R7) -> 32318229 | T8: =SUM(T4:T7) -> 30790236 | U8: =SUM(U4:U7) -> 30790236 | W8: =SUM(W4:W7) -> 34368995 | X8: =SUM(X4:X7) -> 34368995 | Z8: =SUM(Z4:Z7) -> 40082097 | AA8: =SUM(AA4:AA7) -> 40082097 | AC8: =SUM(AC4:AC7) -> 42461955 | AD8: =SUM(AD4:AD7) -> 42461955 | AF8: =SUM(AF4:AF7) -> 45174235 | AG8: =SUM(AG4:AG7) -> 45174235
A11: *LK Stok Kapital untuk based tahun 2005

Sheet Stok Kapital
A2: Kegiatan Ekonomi | B2: =J2-1 -> 2014 | J2: ='PDB ADHB'!C1 -> 2015 | R2: ='PDB ADHB'!D1 -> 2016 | Z2: ='PDB ADHB'!E1 -> 2017 | AH2: ='PDB ADHB'!F1 -> 2018 | AP2: ='PDB ADHB'!G1 -> 2019 | AX2: ='PDB ADHB'!H1 -> 2020 | BF2: ='PDB ADHB'!I1 -> 2021 | BN2: ='PDB ADHB'!J1 -> 2022 | BV2: ='PDB ADHB'!K1 -> 2023* | CD2: ='PDB ADHB'!L1 -> 2024**
B3: 1. Stok Awal | C3: 2. Total penyediaan | D3: 3. Total Penggunaan | E3: 4. Produk Domestik Bruto | F3: 5. Penyusutan | G3: 6. Produksi Domestik Neto | H3: 7. Revaluasi | I3: 8. Stok Akhir | J3: 1. Stok Awal | K3: 2. Total penyediaan | L3: 3. Total Penggunaan | M3: 4. Produk Domestik Bruto | N3: 5. Penyusutan | O3: 6. Produksi Domestik Neto | P3: 7. Revaluasi | Q3: 8. Stok Akhir | R3: 1. Stok Awal | S3: 2. Total penyediaan | T3: 3. Total Penggunaan | U3: 4. Produk Domestik Bruto | V3: 5. Penyusutan | W3: 6. Produksi Domestik Neto | X3: 7. Revaluasi | Y3: 8. Stok Akhir | Z3: 1. Stok Awal | AA3: 2. Total penyediaan | AB3: 3. Total Penggunaan | AC3: 4. Produk Domestik Bruto | AD3: 5. Penyusutan | AE3: 6. Produksi Domestik Neto | AF3: 7. Revaluasi | AG3: 8. Stok Akhir | AH3: 1. Stok Awal | AI3: 2. Total penyediaan | AJ3: 3. Total Penggunaan | AK3: 4. Produk Domestik Bruto | AL3: 5. Penyusutan | AM3: 6. Produksi Domestik Neto | AN3: 7. Revaluasi | AO3: 8. Stok Akhir | AP3: 1. Stok Awal | AQ3: 2. Total penyediaan | AR3: 3. Total Penggunaan | AS3: 4. Produk Domestik Bruto | AT3: 5. Penyusutan | AU3: 6. Produksi Domestik Neto | AV3: 7. Revaluasi | AW3: 8. Stok Akhir | AX3: 1. Stok Awal | AY3: 2. Total penyediaan | AZ3: 3. Total Penggunaan | BA3: 4. Produk Domestik Bruto | BB3: 5. Penyusutan | BC3: 6. Produksi Domestik Neto | BD3: 7. Revaluasi | BE3: 8. Stok Akhir | BF3: 1. Stok Awal | BG3: 2. Total penyediaan | BH3: 3. Total Penggunaan | BI3: 4. Produk Domestik Bruto | BJ3: 5. Penyusutan | BK3: 6. Produksi Domestik Neto | BL3: 7. Revaluasi | BM3: 8. Stok Akhir | BN3: 1. Stok Awal | BO3: 2. Total penyediaan | BP3: 3. Total Penggunaan | BQ3: 4. Produk Domestik Bruto | BR3: 5. Penyusutan | BS3: 6. Produksi Domestik Neto | BT3: 7. Revaluasi | BU3: 8. Stok Akhir | BV3: 1. Stok Awal | BW3: 2. Total penyediaan | BX3: 3. Total Penggunaan | BY3: 4. Produk Domestik Bruto | BZ3: 5. Penyusutan | CA3: 6. Produksi Domestik Neto | CB3: 7. Revaluasi | CC3: 8. Stok Akhir | CD3: 1. Stok Awal | CE3: 2. Total penyediaan | CF3: 3. Total Penggunaan | CG3: 4. Produk Domestik Bruto | CH3: 5. Penyusutan | CI3: 6. Produksi Domestik Neto | CJ3: 7. Revaluasi | CK3: 8. Stok Akhir
B4: Barang Modal | I4: Barang Modal | J4: Barang Modal | Q4: Barang Modal | R4: Barang Modal | Y4: Barang Modal | Z4: Barang Modal | AG4: Barang Modal | AH4: Barang Modal | AO4: Barang Modal | AP4: Barang Modal | AW4: Barang Modal | AX4: Barang Modal | BE4: Barang Modal | BF4: Barang Modal | BM4: Barang Modal | BN4: Barang Modal | BU4: Barang Modal | BV4: Barang Modal | CC4: Barang Modal | CD4: Barang Modal | CK4: Barang Modal
A5: Industri | C5: =Penyediaan!B4 -> 20186022 | D5: =Penyediaan!C4 -> 9616316.7 | E5: =Penyediaan!D4 -> 10569705 | F5: =Penyusutan!G19 -> 1970519.4 | G5: =E5-F5 -> 8599185.9 | K5: =Penyediaan!E4 -> 22012989 | L5: =Penyediaan!F4 -> 10486656 | M5: =Penyediaan!G4 -> 11526333 | N5: =Penyusutan!M19 -> 2129438.2 | O5: =M5-N5 -> 9396894.6 | S5: =Penyediaan!H4 -> 22781947 | T5: =Penyediaan!I4 -> 10380218 | U5: =Penyediaan!J4 -> 12401728 | V5: =Penyusutan!S19 -> 2035689.4 | W5: =U5-V5 -> 10366039 | AA5: =Penyediaan!K4 -> 24964479 | AB5: =Penyediaan!L4 -> 11374653 | AC5: =Penyediaan!M4 -> 13589826 | AD5: =Penyusutan!Y19 -> 2430937.4 | AE5: =AC5-AD5 -> 11158888 | AI5: =Penyediaan!N4 -> 27258761 | AJ5: =Penyediaan!O4 -> 12420005 | AK5: =Penyediaan!P4 -> 14838756 | AL5: =Penyusutan!AE19 -> 2800030.2 | AM5: =AK5-AL5 -> 12038726 | AQ5: =Penyediaan!Q4 -> 29304285 | AR5: =Penyediaan!R4 -> 13471628 | AS5: =Penyediaan!S4 -> 15832657 | AT5: =Penyusutan!AK19 -> 3168101.1 | AU5: =AS5-AT5 -> 12664556 | AY5: =Penyediaan!T4 -> 28374740 | AZ5: =Penyediaan!U4 -> 12931387 | BA5: =Penyediaan!V4 -> 15443353 | BB5: =Penyusutan!AQ19 -> 2943805 | BC5: =BA5-BB5 -> 12499548 | BG5: =Penyediaan!W4 -> 31179368 | BH5: =Penyediaan!X4 -> 14202617 | BI5: =Penyediaan!Y4 -> 16976751 | BJ5: =Penyusutan!AW19 -> 3146409.1 | BK5: =BI5-BJ5 -> 13830342 | BO5: =Penyediaan!Z4 -> 35976012 | BP5: =Penyediaan!AA4 -> 16387552 | BQ5: =Penyediaan!AB4 -> 19588460 | BR5: =Penyusutan!BC19 -> 3686044.4 | BS5: =BQ5-BR5 -> 15902416 | BW5: =Penyediaan!AC4 -> 38370723 | BX5: =Penyediaan!AD4 -> 17478375 | BY5: =Penyediaan!AE4 -> 20892348 | BZ5: =Penyusutan!BI19 -> 4138304.5 | CA5: =BY5-BZ5 -> 16754044 | CE5: =Penyediaan!AF4 -> 40660248 | CF5: =Penyediaan!AG4 -> 18521284 | CG5: =Penyediaan!AH4 -> 22138964 | CH5: =Penyusutan!BO19 -> 4426259.2 | CI5: =CG5-CH5 -> 17712705
A6: Konsumsi Akhir | D6: =Penyediaan!C5 -> 7035633.7 | L6: =Penyediaan!F5 -> 7745630.1 | T6: =Penyediaan!I5 -> 8353136 | AB6: =Penyediaan!L5 -> 9023120.3 | AJ6: =Penyediaan!O5 -> 9793746.3 | AR6: =Penyediaan!R5 -> 10566547 | AZ6: =Penyediaan!U5 -> 10592541 | BH6: =Penyediaan!X5 -> 11013796 | BP6: =Penyediaan!AA5 -> 11896997 | BX6: =Penyediaan!AD5 -> 12928272 | CF6: =Penyediaan!AG5 -> 13976578
A7: Akumulasi Kapital yang Diproduksi | B7: 33313961 | D7: =Penyediaan!C6 -> 3613154.8 | F7: =-F5 -> -1970519.4 | G7: =D7+F7 -> 1642635.4 | H7: =I7-B7-G7 -> 3145856.7 | I7: 38102453 | J7: =I7 -> 38102453 | L7: =Penyediaan!F6 -> 3736589.3 | N7: =-N5 -> -2129438.2 | O7: =L7+N7 -> 1607151.1 | P7: =Q7-J7-O7 -> 1914113.9 | Q7: 41623718 | R7: =Q7 -> 41623718 | T7: =Penyediaan!I6 -> 3954755.4 | V7: =-V5 -> -2035689.4 | W7: =T7+V7 -> 1919066 | X7: =Y7-R7-W7 -> 1318339.4 | Y7: 44861123 | Z7: =Y7 -> 44861123 | AB7: =Penyediaan!L6 -> 4430927.9 | AD7: =-AD5 -> -2430937.4 | AE7: =AB7+AD7 -> 1999990.5 | AF7: =AG7-Z7-AE7 -> 2311045.3 | AG7: 49172159 | AH7: =AG7 -> 49172159 | AJ7: =Penyediaan!O6 -> 5203608.7 | AL7: =-AL5 -> -2800030.2 | AM7: =AJ7+AL7 -> 2403578.5 | AN7: =AO7-AH7-AM7 -> 2816519.2 | AO7: 54392257 | AP7: =AO7 -> 54392257 | AR7: =Penyediaan!R6 -> 5336521.6 | AT7: =-AT5 -> -3168101.1 | AU7: =AR7+AT7 -> 2168420.4 | AV7: =AW7-AP7-AU7 -> 1617443.7 | AW7: 58178121 | AX7: =AW7 -> 58178121 | AZ7: =Penyediaan!U6 -> 4589794.8 | BB7: =-BB5 -> -2943805 | BC7: =AZ7+BB7 -> 1645989.8 | BD7: =BE7-AX7-BC7 -> 1842694.6 | BE7: 61666805 | BF7: =BE7 -> 61666805 | BH7: =Penyediaan!X6 -> 5516746.8 | BJ7: =-BJ5 -> -3146409.1 | BK7: =BH7+BJ7 -> 2370337.7 | BL7: =BM7-BF7-BK7 -> 3659416.5 | BM7: 67696559 | BN7: =BM7 -> 67696559 | BP7: =Penyediaan!AA6 -> 6997805.3 | BR7: =-BR5 -> -3686044.4 | BS7: =BP7+BR7 -> 3311760.9 | BT7: =BU7-BN7-BS7 -> 3334636.5 | BU7: 74342957 | BV7: =BU7 -> 74342957 | BX7: =Penyediaan!AD6 -> 7510418.7 | BZ7: =-BZ5 -> -4138304.5 | CA7: =BX7+BZ7 -> 3372114.2 | CB7: =CC7-BV7-CA7 -> 2718562.5 | CC7: =BV7+'PDB ADHB'!K18 -> 80433633 | CD7: =CC7 -> 80433633 | CF7: =Penyediaan!AG6 -> 7765217.9 | CH7: =-CH5 -> -4426259.2 | CI7: =CF7+CH7 -> 3338958.7 | CJ7: =CK7-CD7-CI7 -> 3113572 | CK7: =CD7+'PDB ADHB'!L18 -> 86886164
A8: Luar Negeri | C8: =Penyediaan!B7 -> 2580508 | D8: =Penyediaan!C7 -> 2501424.8 | K8: =Penyediaan!E7 -> 2394879.3 | L8: =Penyediaan!F7 -> 2438992.7 | S8: =Penyediaan!H7 -> 2273528 | T8: =Penyediaan!I7 -> 2367365.2 | AA8: =Penyediaan!K7 -> 2606283 | AB8: =Penyediaan!L7 -> 2742060.5 | AI8: =Penyediaan!N7 -> 3275145.3 | AJ8: =Penyediaan!O7 -> 3116546.3 | AQ8: =Penyediaan!Q7 -> 3013944.2 | AR8: =Penyediaan!R7 -> 2943532.9 | AY8: =Penyediaan!T7 -> 2415496 | AZ8: =Penyediaan!U7 -> 2676513.5 | BG8: =Penyediaan!W7 -> 3189626.5 | BH8: =Penyediaan!X7 -> 3635835.4 | BO8: =Penyediaan!Z7 -> 4106085.7 | BP8: =Penyediaan!AA7 -> 4799743 | BW8: =Penyediaan!AC7 -> 4091231.5 | BX8: =Penyediaan!AD7 -> 4544889.6 | CE8: =Penyediaan!AF7 -> 4513987.4 | CF8: =Penyediaan!AG7 -> 4911155.7
A9: Total | C9: =Penyediaan!B8 -> 22766530 | D9: =Penyediaan!C8 -> 22766530 | K9: =Penyediaan!E8 -> 24407868 | L9: =Penyediaan!F8 -> 24407868 | S9: =Penyediaan!H8 -> 25055475 | T9: =Penyediaan!I8 -> 25055475 | AA9: =Penyediaan!K8 -> 27570762 | AB9: =Penyediaan!L8 -> 27570762 | AI9: =Penyediaan!N8 -> 30533906 | AJ9: =Penyediaan!O8 -> 30533906 | AQ9: =Penyediaan!Q8 -> 32318229 | AR9: =Penyediaan!R8 -> 32318229 | AY9: =Penyediaan!T8 -> 30790236 | AZ9: =Penyediaan!U8 -> 30790236 | BG9: =Penyediaan!W8 -> 34368995 | BH9: =Penyediaan!X8 -> 34368995 | BO9: =Penyediaan!Z8 -> 40082097 | BP9: =Penyediaan!AA8 -> 40082097 | BW9: =Penyediaan!AC8 -> 42461955 | BX9: =Penyediaan!AD8 -> 42461955 | CE9: =Penyediaan!AF8 -> 45174235 | CF9: =Penyediaan!AG8 -> 45174235
I10: =B7+'PDB ADHB'!B18 -> 36750884 | Q10: =J7+'PDB ADHB'!C18 -> 41884465 | Y10: =R7+'PDB ADHB'!D18 -> 45663919
A12: Sumber Data :
A13: 1. Stok Awal | CC13: =CC7+'PDB ADHB'!L18 -> 86886164 | CK13: =CK7+'PDB ADHB'!T18 -> 86886164
A14: - Barang Modal | D14: S. Akhir Thn sblmnya | BW14: =BU7-BN7 -> 6646397.4 | CE14: =CC7-BV7 -> 6090676.7
A15: 2. Total penyediaan | B15: Output PDB | E15: Impor
A16: 3. Total Penggunaan | B16: Penyedia - PDB | C16: Konsumsi RT + Pem | D16: PMTB + P. Stok+Deskrepancy | E16: Ekspor
A17: 4. Produk Domestik Bruto | B17: PDB
A18: 5. Penyusutan | B18: PDB(Penyusutan) | D18: - Penyusutan
A19: 6. Produksi Domestik Neto | B19: PDB - Penyusut | D19: Penggunaan + Penyusut
A20: 7. Revaluasi | D20: S.Akhir-S.Awal-PDN
A21: 8. Stok Akhir
A22: - Barang Modal | D22: S. Awal + PMTB
A24: Sumber Data :
A25: 1. Stok Awal
A26: - Barang Modal | D26: S. Akhir Thn sblmnya
A27: 2. Total penyediaan | B27: Output PDB | E27: Impor
A28: 3. Total Penggunaan | B28: Penyedia - PDB | C28: Konsumsi RT + Pem | D28: PMTB + P. Stok+Deskrepancy | E28: Ekspor
A29: 4. Produk Domestik Bruto | B29: PDB
A30: 5. Penyusutan | B30: PDB(Penyusutan) | D30: - Penyusutan
A31: 6. Produksi Domestik Neto | B31: PDB - Penyusut | D31: Penggunaan + Penyusut
A32: 7. Revaluasi | D32: S.Akhir-S.Awal-PDN | F32: Merupakan item balancing yang menunjukkan adanya perubahan harga barang modal di awal dan akhir tahun
A33: 8. Stok Akhir
A34: - Barang Modal | D34: S. Awal + PMTB | F34: Update: dihitungkan dan diberikan secara value oleh DNPeng, tapi karena 2023 belum tersedia makanya estimasi

Sheet Aset Moneter
A1: Aset Moneter dalam satuan miliar rupiah
A2: Hasil Hutan
A3: Rincian/Detail | D3: Tahun / Year
D4: =E4-1 -> 2014 | E4: ='PDB ADHB'!C1 -> 2015 | F4: ='PDB ADHB'!D1 -> 2016 | G4: ='PDB ADHB'!E1 -> 2017 | H4: ='PDB ADHB'!F1 -> 2018 | I4: ='PDB ADHB'!G1 -> 2019 | J4: ='PDB ADHB'!H1 -> 2020 | K4: ='PDB ADHB'!I1 -> 2021 | L4: ='PDB ADHB'!J1 -> 2022 | ... N4: ='PDB ADHB'!L1 -> 2024**
A5: -1 | D5: =A5-1 -> -2 | E5: =D5-1 -> -3 | F5: =E5-1 -> -4 | G5: =F5-1 -> -5 | H5: =G5-1 -> -6 | I5: =H5-1 -> -7 | J5: =I5-1 -> -8 | K5: =J5-1 -> -9 | L5: =J5-1 -> -9 | M5: =K5-1 -> -10 | N5: =L5-1 -> -10
A6: Stok awal tahun/Opening stock | D6: 701661.76 | E6: 719985.09 | F6: 628834.11 | G6: 681499.89 | H6: 749533.49 | I6: 740284 | J6: 818198.38 | K6: 952915.52 | L6: 1100095.7 | M6: 1173971.8 | N6: 1390349.6
A7: Penambahan stok/Additions to stock
A8: Pertumbuhan alami/Natural growth | D8: 4013.4808 | E8: 3927.0238 | F8: 4254.0726 | G8: 4901.6472 | H8: 5087.0422 | I8: 6109.567 | J8: 7281.4543 | K8: 7365.4623 | L8: 9402.4752 | M8: 12119.482 | N8: 11982.625
A9: Reklasifikasi/Reclassifications | D9: 1626.2872 | E9: 2284.5052 | F9: 2856.7213 | G9: 1401.2454 | H9: 1773.0106 | I9: 3075.1912 | J9: 3032.543 | K9: 1343.8434 | L9: 2447.6811 | M9: 2087.0909 | N9: 3715.5351
A10: Total penambahan/Total additions to stock | D10: 5639.768 | E10: 6211.529 | F10: 7110.7939 | G10: 6302.8926 | H10: 6860.0527 | I10: 9184.7582 | J10: 10313.997 | K10: 8709.3058 | L10: 11850.156 | M10: 14206.573 | N10: 15698.16
A11: Pengurangan stok/Reductions in stock
A12: Penebangan/Removals | D12: 6621.4561 | E12: 6545.6817 | F12: 7473.951 | G12: 8951.9533 | H12: 9094.5459 | I12: 11560.738 | J12: 14524.238 | K12: 15185.369 | L12: 20145.685 | M12: 27656.299 | N12: 26332.756
A13: Kerusakan dan Reklasifikasi/Losses and Reclassifiations | D13: 28141.491 | E13: 89344.514 | F13: 32133.043 | G13: 28424.101 | H13: 24829.202 | I13: 76926.656 | J13: 19002.634 | K13: 22902.56 | L13: 20409.484 | M13: 114856.7 | N13: 45836.176
A14: Total pengurangan/Total reductions in stock | D14: 34762.947 | E14: 95890.196 | F14: 39606.994 | G14: 37376.054 | H14: 33923.748 | I14: 88487.394 | J14: 33526.873 | K14: 38087.928 | L14: 40555.169 | M14: 142513 | N14: 72168.932
A15: Revaluasi/Revaluations | D15: 47446.501 | E15: -1472.309 | F15: 85161.98 | G15: 99106.76 | H15: 17814.209 | I15: 157217.01 | J15: 157930.02 | K15: 176558.81 | L15: 102581.11 | M15: 344684.22 | N15: -3840.5881
A16: Stok akhir tahun/Closing stock | D16: 719985.09 | E16: 628834.11 | F16: 681499.89 | G16: 749533.49 | H16: 740284 | I16: 818198.38 | J16: 952915.52 | K16: 1100095.7 | L16: 1173971.8 | M16: 1390349.6 | N16: 1330038.2
A18: Minyak Bumi
A19: Uraian Description | D19: Tahun / Year
D20: =E20-1 -> 2014 | E20: =E4 -> 2015 | F20: =F4 -> 2016 | G20: =G4 -> 2017 | H20: =H4 -> 2018 | I20: =I4 -> 2019 | J20: =J4 -> 2020 | K20: =K4 -> 2021 | L20: =L4 -> 2022 | ... N20: =N4 -> 2024**
A21: -1 | D21: =A21-1 -> -2 | E21: =D21-1 -> -3 | F21: =E21-1 -> -4 | G21: =F21-1 -> -5 | H21: =G21-1 -> -6 | I21: =H21-1 -> -7 | J21: =I21-1 -> -8 | K21: =J21-1 -> -9 | L21: =J21-1 -> -9 | M21: =K21-1 -> -10 | N21: =L21-1 -> -10
A22: Stok awal tahun Opening stock | D22: 2131738 | E22: 1936674 | F22: 1128616.9 | G22: 1038776.4 | H22: 1442786.8 | I22: 1827895.4 | J22: 1650482.1 | K22: 1232797.1 | L22: 1759477.5 | M22: 2275538.7 | N22: 1904383.6
A23: Ekstraksi Extraction | D23: -78448.958 | E23: -59816.752 | F23: -45283.89 | G23: -48952.527 | H23: -61277.109 | I23: -92568.191 | J23: -95012.345 | K23: -89111.472 | L23: -110761.69 | M23: -105018.04 | N23: -89462.611
A24: Perubahan lainnya Other changes in stock | D24: 30720.524 | E24: 45297.101 | F24: 37257.867 | G24: 95647.459 | H24: 57406.243 | I24: -1179312.2 | J24: 239454.88 | K24: 6989.5507 | L24: 223266.08 | M24: 354946.17 | N24: -74368.112
A25: Revaluasi Revaluation | D25: -147335.56 | E25: -793537.46 | F25: -81814.455 | G25: 357315.45 | H25: 388979.48 | I25: 1094467.2 | J25: -562127.59 | K25: 608802.28 | L25: 403556.83 | M25: -621083.24 | N25: 145800.33
A26: Stok akhir tahun Closing stock | D26: 1936674 | E26: 1128616.9 | F26: 1038776.4 | G26: 1442786.8 | H26: 1827895.4 | I26: 1650482.1 | J26: 1232797.1 | K26: 1759477.5 | L26: 2275538.7 | M26: 1904383.6 | N26: 1886353.2
A28: Gas Alam
A29: Uraian Description | D29: Tahun / Year
D30: =D20 -> 2014 | E30: =E20 -> 2015 | F30: =F20 -> 2016 | G30: =G20 -> 2017 | H30: =H20 -> 2018 | I30: =I20 -> 2019 | J30: =J20 -> 2020 | K30: =K20 -> 2021 | ... N30: =N20 -> 2024**
A31: -1 | D31: =A31-1 -> -2 | E31: =D31-1 -> -3 | F31: =E31-1 -> -4 | G31: =F31-1 -> -5 | H31: =G31-1 -> -6 | I31: =H31-1 -> -7 | J31: =I31-1 -> -8 | K31: =J31-1 -> -9 | L31: =J31-1 -> -9 | M31: =K31-1 -> -10 | N31: =L31-1 -> -10
A32: Stok awal tahun Opening stock | D32: 2209651.2 | E32: 1929560.4 | F32: 2092742.2 | G32: 2099174 | H32: 2081924.9 | I32: 1985652.1 | J32: 2088004.1 | K32: 2190729.9 | L32: 2571830.7 | M32: 3019060 | N32: 2672571.9
A33: Ekstraksi Extraction | D33: -43852.885 | E33: -41683.345 | F33: -43598.192 | G33: -40547.829 | H33: -43807.745 | I33: -58529.829 | J33: -75883.739 | K33: -94344.79 | L33: -115553.86 | M33: -125788.22 | N33: -123062.42
A34: Perubahan lainnya Other changes in stock | D34: 28780.916 | E34: 68857.884 | F34: -59637.711 | G34: 21011.296 | H34: -61004.503 | I34: -1155065.3 | J34: -387042.26 | K34: 25415.894 | L34: -166293.53 | M34: 122131.58 | N34: -14280.855
A35: Revaluasi Revaluation | D35: -265018.81 | E35: 136007.26 | F35: 109667.72 | G35: 2287.3592 | H35: 8539.4995 | I35: 1315947.1 | J35: 565651.8 | K35: 450029.71 | L35: 729076.67 | M35: -342831.44 | N35: 67246.415
A36: Stok akhir tahun Closing stock | D36: 1929560.4 | E36: 2092742.2 | F36: 2099174 | G36: 2081924.9 | H36: 1985652.1 | I36: 2088004.1 | J36: 2190729.9 | K36: 2571830.7 | L36: 3019060 | M36: 2672571.9 | N36: 2602475
A38: Batubara
A39: Uraian Description | D39: Tahun / Year
D40: =D30 -> 2014 | E40: =E30 -> 2015 | F40: =F30 -> 2016 | G40: =G30 -> 2017 | H40: =H30 -> 2018 | I40: =I30 -> 2019 | J40: =J30 -> 2020 | K40: =K30 -> 2021 | ... N40: =N30 -> 2024**
A41: -1 | D41: =A41-1 -> -2 | E41: =D41-1 -> -3 | F41: =E41-1 -> -4 | G41: =F41-1 -> -5 | H41: =G41-1 -> -6 | I41: =H41-1 -> -7 | J41: =I41-1 -> -8 | K41: =J41-1 -> -9 | L41: =J41-1 -> -9 | M41: =K41-1 -> -10 | N41: =L41-1 -> -10
A42: Stok awal tahun Opening stock | D42: 3124469.7 | E42: 2374378.3 | F42: 2534793.4 | G42: 2860161.4 | H42: 4126241.8 | I42: 4338434.3 | J42: 4057943.9 | K42: 3608155.4 | L42: 7098820.3 | M42: 15178689 | N42: 13539562
A43: Ekstraksi Extraction | D43: -39616.02 | E43: -35051.958 | F43: -40846.113 | G43: -62437.308 | H43: -79361.018 | I43: -68470.663 | J43: -56624.031 | K43: -88615.492 | L43: -216088.03 | M43: -333305.22 | N43: -306796.88
...

Sheet Neraca Terpadu
A2: Komponen Neraca | C2: =I2-1 -> 2014 | I2: ='PDB ADHB'!C1 -> 2015 | O2: ='PDB ADHB'!D1 -> 2016 | U2: ='PDB ADHB'!E1 -> 2017 | AA2: ='PDB ADHB'!F1 -> 2018 | AG2: ='PDB ADHB'!G1 -> 2019 | AM2: ='PDB ADHB'!H1 -> 2020 | AS2: ='PDB ADHB'!I1 -> 2021 | AY2: ='PDB ADHB'!J1 -> 2022 | BE2: ='PDB ADHB'!K1 -> 2023* | BK2: ='PDB ADHB'!L1 -> 2024**
C3: Kegiatan Ekonomi | H3: Kapital Lingkungan yang Tidak diproduksi | I3: Kegiatan Ekonomi | N3: Kapital Lingkungan yang Tidak diproduksi | O3: Kegiatan Ekonomi | T3: Kapital Lingkungan yang Tidak diproduksi | U3: Kegiatan Ekonomi | Z3: Kapital Lingkungan yang Tidak diproduksi | AA3: Kegiatan Ekonomi | AF3: Kapital Lingkungan yang Tidak diproduksi | AG3: Kegiatan Ekonomi | AL3: Kapital Lingkungan yang Tidak diproduksi | AM3: Kegiatan Ekonomi | AR3: Kapital Lingkungan yang Tidak diproduksi | AS3: Kegiatan Ekonomi | AX3: Kapital Lingkungan yang Tidak diproduksi | AY3: Kegiatan Ekonomi | BD3: Kapital Lingkungan yang Tidak diproduksi | BE3: Kegiatan Ekonomi | BJ3: Kapital Lingkungan yang Tidak diproduksi | BK3: Kegiatan Ekonomi | BP3: Kapital Lingkungan yang Tidak diproduksi
C4: Industri | D4: Konsumsi akhir | E4: Kapital | G4: Luar Negeri | I4: Industri | J4: Konsumsi akhir | K4: Kapital | M4: Luar Negeri | O4: Industri | P4: Konsumsi akhir | Q4: Kapital | S4: Luar Negeri | U4: Industri | V4: Konsumsi akhir | W4: Kapital | Y4: Luar Negeri | AA4: Industri | AB4: Konsumsi akhir | AC4: Kapital | AE4: Luar Negeri | AG4: Industri | AH4: Konsumsi akhir | AI4: Kapital | AK4: Luar Negeri | AM4: Industri | AN4: Konsumsi akhir | AO4: Kapital | AQ4: Luar Negeri | AS4: Industri | AT4: Konsumsi akhir | AU4: Kapital | AW4: Luar Negeri | AY4: Industri | AZ4: Konsumsi akhir | BA4: Kapital | BC4: Luar Negeri | BE4: Industri | BF4: Konsumsi akhir | BG4: Kapital | BI4: Luar Negeri | BK4: Industri | BL4: Konsumsi akhir | BM4: Kapital | BO4: Luar Negeri
E5: Diproduksi (Produced Assets) | F5: Buatan Alam (Non-Produced) | K5: Diproduksi (Produced Assets) | L5: Buatan Alam (Non-Produced) | Q5: Diproduksi (Produced Assets) | R5: Buatan Alam (Non-Produced) | W5: Diproduksi (Produced Assets) | X5: Buatan Alam (Non-Produced) | AC5: Diproduksi (Produced Assets) | AD5: Buatan Alam (Non-Produced) | AI5: Diproduksi (Produced Assets) | AJ5: Buatan Alam (Non-Produced) | AO5: Diproduksi (Produced Assets) | AP5: Buatan Alam (Non-Produced) | AU5: Diproduksi (Produced Assets) | AV5: Buatan Alam (Non-Produced) | BA5: Diproduksi (Produced Assets) | BB5: Buatan Alam (Non-Produced) | BG5: Diproduksi (Produced Assets) | BH5: Buatan Alam (Non-Produced) | BM5: Diproduksi (Produced Assets) | BN5: Buatan Alam (Non-Produced)
A6: (1) | C6: (2) | D6: (4) | E6: (5) | F6: (6) | G6: (3) | H6: (7) | I6: (2) | J6: (4) | K6: (5) | L6: (6) | M6: (3) | N6: (7) | O6: (2) | P6: (4) | Q6: (5) | R6: (6) | S6: (3) | T6: (7) | U6: (2) | V6: (4) | W6: (5) | X6: (6) | Y6: (3) | Z6: (7) | AA6: (2) | AB6: (4) | AC6: (5) | AD6: (6) | AE6: (3) | AF6: (7) | AG6: (2) | AH6: (4) | AI6: (5) | AJ6: (6) | AK6: (3) | AL6: (7) | AM6: (2) | AN6: (4) | AO6: (5) | AP6: (6) | AQ6: (3) | AR6: (7) | AS6: (2) | AT6: (4) | AU6: (5) | AV6: (6) | AW6: (3) | AX6: (7) | AY6: (2) | AZ6: (4) | BA6: (5) | BB6: (6) | BC6: (3) | BD6: (7) | BE6: (2) | BF6: (4) | BG6: (5) | BH6: (6) | BI6: (3) | BJ6: (7) | BK6: (2) | BL6: (4) | BM6: (5) | BN6: (6) | BO6: (3) | BP6: (7)
A8: 1 | B8: Stok Awal
B9: Barang Modal | E9: ='Stok Kapital'!B7 -> 33313961 | K9: ='Stok Kapital'!J7 -> 38102453 | Q9: =K60 -> 41623718 | W9: =Q60 -> 44861123 | AC9: =W60 -> 49172159 | AI9: =AC60 -> 54392257 | AO9: =AI60 -> 58178121 | AU9: =AO60 -> 61666805 | BA9: =AU60 -> 67696559 | BG9: =BA60 -> 74342957 | BM9: =BG60 -> 80433633
B10: a. Hasil Hutan | F10: ='Aset Moneter'!D6 -> 701661.76 | L10: ='Aset Moneter'!E6 -> 719985.09 | R10: ='Aset Moneter'!F6 -> 628834.11 | X10: ='Aset Moneter'!G6 -> 681499.89 | AD10: ='Aset Moneter'!H6 -> 749533.49 | AJ10: ='Aset Moneter'!I6 -> 740284 | AP10: ='Aset Moneter'!J6 -> 818198.38 | AV10: ='Aset Moneter'!K6 -> 952915.52 | BB10: ='Aset Moneter'!L6 -> 1100095.7 | BH10: ='Aset Moneter'!M6 -> 1173971.8 | BN10: ='Aset Moneter'!N6 -> 1390349.6
B11: b. Minyak Bumi | F11: ='Aset Moneter'!D22 -> 2131738 | L11: ='Aset Moneter'!E22 -> 1936674 | R11: ='Aset Moneter'!F22 -> 1128616.9 | X11: ='Aset Moneter'!G22 -> 1038776.4 | AD11: ='Aset Moneter'!H22 -> 1442786.8 | AJ11: ='Aset Moneter'!I22 -> 1827895.4 | AP11: ='Aset Moneter'!J22 -> 1650482.1 | AV11: ='Aset Moneter'!K22 -> 1232797.1 | BB11: ='Aset Moneter'!L22 -> 1759477.5 | BH11: ='Aset Moneter'!M22 -> 2275538.7 | BN11: ='Aset Moneter'!N22 -> 1904383.6
B12: c. Gas Alam | F12: ='Aset Moneter'!D32 -> 2209651.2 | L12: ='Aset Moneter'!E32 -> 1929560.4 | R12: ='Aset Moneter'!F32 -> 2092742.2 | X12: ='Aset Moneter'!G32 -> 2099174 | AD12: ='Aset Moneter'!H32 -> 2081924.9 | AJ12: ='Aset Moneter'!I32 -> 1985652.1 | AP12: ='Aset Moneter'!J32 -> 2088004.1 | AV12: ='Aset Moneter'!K32 -> 2190729.9 | BB12: ='Aset Moneter'!L32 -> 2571830.7 | BH12: ='Aset Moneter'!M32 -> 3019060 | BN12: ='Aset Moneter'!N32 -> 2672571.9
B13: d. Batubara | F13: ='Aset Moneter'!D42 -> 3124469.7 | L13: ='Aset Moneter'!E42 -> 2374378.3 | R13: ='Aset Moneter'!F42 -> 2534793.4 | X13: ='Aset Moneter'!G42 -> 2860161.4 | AD13: ='Aset Moneter'!H42 -> 4126241.8 | AJ13: ='Aset Moneter'!I42 -> 4338434.3 | AP13: ='Aset Moneter'!J42 -> 4057943.9 | AV13: ='Aset Moneter'!K42 -> 3608155.4 | BB13: ='Aset Moneter'!L42 -> 7098820.3 | BH13: ='Aset Moneter'!M42 -> 15178689 | BN13: ='Aset Moneter'!N42 -> 13539562
B14: e. Emas | F14: ='Aset Moneter'!D52 -> 193839.94 | L14: ='Aset Moneter'!E52 -> 200366.45 | R14: ='Aset Moneter'!F52 -> 311024.64 | X14: ='Aset Moneter'!G52 -> 330729.39 | AD14: ='Aset Moneter'!H52 -> 376606.06 | AJ14: ='Aset Moneter'!I52 -> 177537.95 | AP14: ='Aset Moneter'!J52 -> 111404.04 | AV14: ='Aset Moneter'!K52 -> 181971.97 | BB14: ='Aset Moneter'!L52 -> 236975.2 | BH14: ='Aset Moneter'!M52 -> 313647.4 | BN14: ='Aset Moneter'!N52 -> 372761.02
B15: f. Perak | F15: ='Aset Moneter'!D62 -> 14354.02 | L15: ='Aset Moneter'!E62 -> 13473.768 | R15: ='Aset Moneter'!F62 -> 14780.666 | X15: ='Aset Moneter'!G62 -> 17318.011 | AD15: ='Aset Moneter'!H62 -> 12622.997 | AJ15: ='Aset Moneter'!I62 -> 4957.2855 | AP15: ='Aset Moneter'!J62 -> 5269.9371 | AV15: ='Aset Moneter'!K62 -> 5627.0929 | BB15: ='Aset Moneter'!L62 -> 5993.334 | BH15: ='Aset Moneter'!M62 -> 5023.8836 | BN15: ='Aset Moneter'!N62 -> 6092.4315
B16: g. Tembaga | F16: ='Aset Moneter'!D72 -> 369717.06 | L16: ='Aset Moneter'!E72 -> 220254.27 | R16: ='Aset Moneter'!F72 -> 172752.29 | X16: ='Aset Moneter'!G72 -> 195241.87 | AD16: ='Aset Moneter'!H72 -> 228644.7 | AJ16: ='Aset Moneter'!I72 -> 243466.58 | AP16: ='Aset Moneter'!J72 -> 182470.54 | AV16: ='Aset Moneter'!K72 -> 603209.49 | BB16: ='Aset Moneter'!L72 -> 925405.54 | BH16: ='Aset Moneter'!M72 -> 1018188.9 | BN16: ='Aset Moneter'!N72 -> 1137311.4
B17: h. Timah | F17: ='Aset Moneter'!D82 -> 73799.752 | L17: ='Aset Moneter'!E82 -> 33762.4 | R17: ='Aset Moneter'!F82 -> 50123.665 | X17: ='Aset Moneter'!G82 -> 75206.158 | AD17: ='Aset Moneter'!H82 -> 78627.703 | AJ17: ='Aset Moneter'!I82 -> 115623.7 | AP17: ='Aset Moneter'!J82 -> 128560.7 | AV17: ='Aset Moneter'!K82 -> 185956.97 | BB17: ='Aset Moneter'!L82 -> 300256.29 | BH17: ='Aset Moneter'!M82 -> 378436.44 | BN17: ='Aset Moneter'!N82 -> 436324.54
B18: i. Nikel | F18: ='Aset Moneter'!D92 -> 72154.565 | L18: ='Aset Moneter'!E92 -> 97741.009 | R18: ='Aset Moneter'!F92 -> 151551.61 | X18: ='Aset Moneter'!G92 -> 307466.41 | AD18: ='Aset Moneter'!H92 -> 282952.63 | AJ18: ='Aset Moneter'!I92 -> 42142.188 | AP18: ='Aset Moneter'!J92 -> 42808.066 | AV18: ='Aset Moneter'!K92 -> 113056.09 | BB18: ='Aset Moneter'!L92 -> 169831.81 | BH18: ='Aset Moneter'!M92 -> 172030.87 | BN18: ='Aset Moneter'!N92 -> 181377.43
B19: j. Bauksit | F19: ='Aset Moneter'!D102 -> 48504.103 | L19: ='Aset Moneter'!E102 -> 7070.8202 | R19: ='Aset Moneter'!F102 -> 2508.8634 | X19: ='Aset Moneter'!G102 -> 16142.363 | AD19: ='Aset Moneter'!H102 -> 51927.4 | AJ19: ='Aset Moneter'!I102 -> 81961.192 | AP19: ='Aset Moneter'!J102 -> 119374.6 | AV19: ='Aset Moneter'!K102 -> 92499.539 | BB19: ='Aset Moneter'!L102 -> 132212.83 | BH19: ='Aset Moneter'!M102 -> 161189.47 | BN19: ='Aset Moneter'!N102 -> 189178.53
A20: 2 | B20: Penyediaan | C20: ='Stok Kapital'!C5 -> 20186022 | G20: ='Stok Kapital'!C8 -> 2580508 | I20: ='Stok Kapital'!K5 -> 22012989 | M20: ='Stok Kapital'!K8 -> 2394879.3 | O20: ='Stok Kapital'!S5 -> 22781947 | S20: ='Stok Kapital'!S8 -> 2273528 | U20: ='Stok Kapital'!AA5 -> 24964479 | Y20: ='Stok Kapital'!AA8 -> 2606283 | AA20: ='Stok Kapital'!AI5 -> 27258761 | AE20: ='Stok Kapital'!AI8 -> 3275145.3 | AG20: ='Stok Kapital'!AQ5 -> 29304285 | AK20: ='Stok Kapital'!AQ8 -> 3013944.2 | AM20: ='Stok Kapital'!AY5 -> 28374740 | AQ20: ='Stok Kapital'!AY8 -> 2415496 | AS20: ='Stok Kapital'!BG5 -> 31179368 | AW20: ='Stok Kapital'!BG8 -> 3189626.5 | AY20: ='Stok Kapital'!BO5 -> 35976012 | BC20: ='Stok Kapital'!BO8 -> 4106085.7 | BE20: ='Stok Kapital'!BW5 -> 38370723 | BI20: ='Stok Kapital'!BW8 -> 4091231.5 | BK20: ='Stok Kapital'!CE5 -> 40660248 | BO20: ='Stok Kapital'!CE8 -> 4513987.4
A21: 3 | B21: Penggunaan | C21: ='Stok Kapital'!D5 -> 9616316.7 | D21: ='Stok Kapital'!D6 -> 7035633.7 | E21: ='Stok Kapital'!D7 -> 3613154.8 | G21: ='Stok Kapital'!D8 -> 2501424.8 | I21: ='Stok Kapital'!L5 -> 10486656 | J21: ='Stok Kapital'!L6 -> 7745630.1 | K21: ='Stok Kapital'!L7 -> 3736589.3 | M21: ='Stok Kapital'!L8 -> 2438992.7 | O21: ='Stok Kapital'!T5 -> 10380218 | P21: ='Stok Kapital'!T6 -> 8353136 | Q21: ='Stok Kapital'!T7 -> 3954755.4 | S21: ='Stok Kapital'!T8 -> 2367365.2 | U21: ='Stok Kapital'!AB5 -> 11374653 | V21: ='Stok Kapital'!AB6 -> 9023120.3 | W21: ='Stok Kapital'!AB7 -> 4430927.9 | Y21: ='Stok Kapital'!AB8 -> 2742060.5 | AA21: ='Stok Kapital'!AJ5 -> 12420005 | AB21: ='Stok Kapital'!AJ6 -> 9793746.3 | AC21: ='Stok Kapital'!AJ7 -> 5203608.7 | AE21: ='Stok Kapital'!AJ8 -> 3116546.3 | AG21: ='Stok Kapital'!AR5 -> 13471628 | AH21: ='Stok Kapital'!AR6 -> 10566547 | AI21: ='Stok Kapital'!AR7 -> 5336521.6 | AK21: ='Stok Kapital'!AR8 -> 2943532.9 | AM21: ='Stok Kapital'!AZ5 -> 12931387 | AN21: ='Stok Kapital'!AZ6 -> 10592541 | AO21: ='Stok Kapital'!AZ7 -> 4589794.8 | AQ21: ='Stok Kapital'!AZ8 -> 2676513.5 | AS21: ='Stok Kapital'!BH5 -> 14202617 | AT21: ='Stok Kapital'!BH6 -> 11013796 | AU21: ='Stok Kapital'!BH7 -> 5516746.8 | AW21: ='Stok Kapital'!BH8 -> 3635835.4 | AY21: ='Stok Kapital'!BP5 -> 16387552 | AZ21: ='Stok Kapital'!BP6 -> 11896997 | BA21: ='Stok Kapital'!BP7 -> 6997805.3 | BC21: ='Stok Kapital'!BP8 -> 4799743 | BE21: ='Stok Kapital'!BX5 -> 17478375 | BF21: ='Stok Kapital'!BX6 -> 12928272 | BG21: ='Stok Kapital'!BX7 -> 7510418.7 | BI21: ='Stok Kapital'!BX8 -> 4544889.6 | BK21: ='Stok Kapital'!CF5 -> 18521284 | BL21: ='Stok Kapital'!CF6 -> 13976578 | BM21: ='Stok Kapital'!CF7 -> 7765217.9 | BO21: ='Stok Kapital'!CF8 -> 4911155.7
A22: 4 | B22: Penyusutan | C22: ='Stok Kapital'!F5 -> 1970519.4 | E22: =0-C22 -> -1970519.4 | I22: ='Stok Kapital'!N5 -> 2129438.2 | K22: =0-I22 -> -2129438.2 | O22: ='Stok Kapital'!V5 -> 2035689.4 | Q22: =0-O22 -> -2035689.4 | U22: ='Stok Kapital'!AD5 -> 2430937.4 | W22: =0-U22 -> -2430937.4 | AA22: ='Stok Kapital'!AL5 -> 2800030.2 | AC22: =0-AA22 -> -2800030.2 | AG22: ='Stok Kapital'!AT5 -> 3168101.1 | AI22: =0-AG22 -> -3168101.1 | AM22: ='Stok Kapital'!BB5 -> 2943805 | AO22: =0-AM22 -> -2943805 | AS22: ='Stok Kapital'!BJ5 -> 3146409.1 | AU22: =0-AS22 -> -3146409.1 | AY22: ='Stok Kapital'!BR5 -> 3686044.4 | BA22: =0-AY22 -> -3686044.4 | BE22: ='Stok Kapital'!BZ5 -> 4138304.5 | BG22: =0-BE22 -> -4138304.5 | BK22: ='Stok Kapital'!CH5 -> 4426259.2 | BM22: =0-BK22 -> -4426259.2
A23: 5 | B23: PDN | C23: =C20-C21-C22 -> 8599185.9 | D23: =D21 -> 7035633.7 | E23: =E21+E22 -> 1642635.4 | G23: =G21-G20 -> -79083.211 | I23: =I20-I21-I22 -> 9396894.6 | J23: =J21 -> 7745630.1 | K23: =K21+K22 -> 1607151.1 | M23: =M21-M20 -> 44113.382 | O23: =O20-O21-O22 -> 10366039 | P23: =P21 -> 8353136 | Q23: =Q21+Q22 -> 1919066 | S23: =S21-S20 -> 93837.171 | U23: =U20-U21-U22 -> 11158888 | V23: =V21 -> 9023120.3 | W23: =W21+W22 -> 1999990.5 | Y23: =Y21-Y20 -> 135777.55 | AA23: =AA20-AA21-AA22 -> 12038726 | AB23: =AB21 -> 9793746.3 | AC23: =AC21+AC22 -> 2403578.5 | AE23: =AE21-AE20 -> -158598.99 | AG23: =AG20-AG21-AG22 -> 12664556 | AH23: =AH21 -> 10566547 | AI23: =AI21+AI22 -> 2168420.4 | AK23: =AK21-AK20 -> -70411.3 | AM23: =AM20-AM21-AM22 -> 12499548 | AN23: =AN21 -> 10592541 | AO23: =AO21+AO22 -> 1645989.8 | AQ23: =AQ21-AQ20 -> 261017.56 | AS23: =AS20-AS21-AS22 -> 13830342 | AT23: =AT21 -> 11013796 | AU23: =AU21+AU22 -> 2370337.7 | AW23: =AW21-AW20 -> 446208.96 | AY23: =AY20-AY21-AY22 -> 15902416 | AZ23: =AZ21 -> 11896997 | BA23: =BA21+BA22 -> 3311760.9 | BC23: =BC21-BC20 -> 693657.37 | BE23: =BE20-BE21-BE22 -> 16754044 | BF23: =BF21 -> 12928272 | BG23: =BG21+BG22 -> 3372114.2 | BI23: =BI21-BI20 -> 453658.03 | BK23: =BK20-BK21-BK22 -> 17712705 | BL23: =BL21 -> 13976578 | BM23: =BM21+BM22 -> 3338958.7 | BO23: =BO21-BO20 -> 397168.24
A24: 6 | B24: Deplesi | C24: =SUM(C25:C34) -> 225532.93 | F24: =0-C24 -> -225532.93 | I24: =SUM(I25:I34) -> 256352.15 | L24: =0-I24 -> -256352.15 | O24: =SUM(O25:O34) -> 193579.77 | R24: =0-O24 -> -193579.77 | U24: =SUM(U25:U34) -> 218010.01 | X24: =0-U24 -> -218010.01 | AA24: =SUM(AA25:AA34) -> 245697.33 | AD24: =0-AA24 -> -245697.33 | AG24: =SUM(AG25:AG34) -> 323473.01 | AJ24: =0-AG24 -> -323473.01 | AM24: =SUM(AM25:AM34) -> 281808.55 | AP24: =0-AM24 -> -281808.55 | AS24: =SUM(AS25:AS34) -> 355425.88 | AV24: =0-AS24 -> -355425.88 | AY24: =SUM(AY25:AY34) -> 577815.02 | BB24: =0-AY24 -> -577815.02 | BE24: =SUM(BE25:BE34) -> 816417.99 | BH24: =0-BE24 -> -816417.99 | BK24: =SUM(BK25:BK34) -> 707021.45 | BN24: =0-BK24 -> -707021.45
B25: a. Hasil Hutan | C25: ='Aset Moneter'!D14 -> 34762.947 | F25: =0-C25 -> -34762.947 | I25: ='Aset Moneter'!E14 -> 95890.196 | L25: =0-I25 -> -95890.196 | O25: ='Aset Moneter'!F14 -> 39606.994 | R25: =0-O25 -> -39606.994 | U25: ='Aset Moneter'!G14 -> 37376.054 | X25: =0-U25 -> -37376.054 | AA25: ='Aset Moneter'!H14 -> 33923.748 | AD25: =0-AA25 -> -33923.748 | AG25: ='Aset Moneter'!I14 -> 88487.394 | AJ25: =0-AG25 -> -88487.394 | AM25: ='Aset Moneter'!J14 -> 33526.873 | AP25: =0-AM25 -> -33526.873 | AS25: ='Aset Moneter'!K14 -> 38087.928 | AV25: =0-AS25 -> -38087.928 | AY25: ='Aset Moneter'!L14 -> 40555.169 | BB25: =0-AY25 -> -40555.169 | BE25: ='Aset Moneter'!M14 -> 142513 | BH25: =0-BE25 -> -142513 | BK25: ='Aset Moneter'!N14 -> 72168.932 | BN25: =0-BK25 -> -72168.932
B26: b. Minyak Bumi | C26: =-'Aset Moneter'!D23 -> 78448.958 | F26: =0-C26 -> -78448.958 | I26: =-'Aset Moneter'!E23 -> 59816.752 | L26: =0-I26 -> -59816.752 | O26: =-'Aset Moneter'!F23 -> 45283.89 | R26: =0-O26 -> -45283.89 | U26: =-'Aset Moneter'!G23 -> 48952.527 | X26: =0-U26 -> -48952.527 | AA26: =-'Aset Moneter'!H23 -> 61277.109 | AD26: =0-AA26 -> -61277.109 | AG26: =-'Aset Moneter'!I23 -> 92568.191 | AJ26: =0-AG26 -> -92568.191 | AM26: =-'Aset Moneter'!J23 -> 95012.345 | AP26: =0-AM26 -> -95012.345 | AS26: =-'Aset Moneter'!K23 -> 89111.472 | AV26: =0-AS26 -> -89111.472 | AY26: =-'Aset Moneter'!L23 -> 110761.69 | BB26: =0-AY26 -> -110761.69 | BE26: =-'Aset Moneter'!M23 -> 105018.04 | BH26: =0-BE26 -> -105018.04 | BK26: =-'Aset Moneter'!N23 -> 89462.611 | BN26: =0-BK26 -> -89462.611
B27: c. Gas Alam | C27: =-'Aset Moneter'!D33 -> 43852.885 | F27: =0-C27 -> -43852.885 | I27: =-'Aset Moneter'!E33 -> 41683.345 | L27: =0-I27 -> -41683.345 | O27: =-'Aset Moneter'!F33 -> 43598.192 | R27: =0-O27 -> -43598.192 | U27: =-'Aset Moneter'!G33 -> 40547.829 | X27: =0-U27 -> -40547.829 | AA27: =-'Aset Moneter'!H33 -> 43807.745 | AD27: =0-AA27 -> -43807.745 | AG27: =-'Aset Moneter'!I33 -> 58529.829 | AJ27: =0-AG27 -> -58529.829 | AM27: =-'Aset Moneter'!J33 -> 75883.739 | AP27: =0-AM27 -> -75883.739 | AS27: =-'Aset Moneter'!K33 -> 94344.79 | AV27: =0-AS27 -> -94344.79 | AY27: =-'Aset Moneter'!L33 -> 115553.86 | BB27: =0-AY27 -> -115553.86 | BE27: =-'Aset Moneter'!M33 -> 125788.22 | BH27: =0-BE27 -> -125788.22 | BK27: =-'Aset Moneter'!N33 -> 123062.42 | BN27: =0-BK27 -> -123062.42
B28: d. Batubara | C28: =-'Aset Moneter'!D43 -> 39616.02 | F28: =0-C28 -> -39616.02 | I28: =-'Aset Moneter'!E43 -> 35051.958 | L28: =0-I28 -> -35051.958 | O28: =-'Aset Moneter'!F43 -> 40846.113 | R28: =0-O28 -> -40846.113 | U28: =-'Aset Moneter'!G43 -> 62437.308 | X28: =0-U28 -> -62437.308 | AA28: =-'Aset Moneter'!H43 -> 79361.018 | AD28: =0-AA28 -> -79361.018 | AG28: =-'Aset Moneter'!I43 -> 68470.663 | AJ28: =0-AG28 -> -68470.663 | AM28: =-'Aset Moneter'!J43 -> 56624.031 | AP28: =0-AM28 -> -56624.031 | AS28: =-'Aset Moneter'!K43 -> 88615.492 | AV28: =0-AS28 -> -88615.492 | AY28: =-'Aset Moneter'!L43 -> 216088.03 | BB28: =0-AY28 -> -216088.03 | BE28: =-'Aset Moneter'!M43 -> 333305.22 | BH28: =0-BE28 -> -333305.22 | BK28: =-'Aset Moneter'!N43 -> 306796.88 | BN28: =0-BK28 -> -306796.88
B29: e. Emas | C29: =-'Aset Moneter'!D53 -> 5059.7905 | F29: =0-C29 -> -5059.7905 | I29: =-'Aset Moneter'!E53 -> 9273.2681 | L29: =0-I29 -> -9273.2681 | O29: =-'Aset Moneter'!F53 -> 10760.668 | R29: =0-O29 -> -10760.668 | U29: =-'Aset Moneter'!G53 -> 11196.82 | X29: =0-U29 -> -11196.82 | AA29: =-'Aset Moneter'!H53 -> 11043.246 | AD29: =0-AA29 -> -11043.246 | AG29: =-'Aset Moneter'!I53 -> 4937.9047 | AJ29: =0-AG29 -> -4937.9047 | AM29: =-'Aset Moneter'!J53 -> 3478.345 | AP29: =0-AM29 -> -3478.345 | AS29: =-'Aset Moneter'!K53 -> 7950.6586 | AV29: =0-AS29 -> -7950.6586 | AY29: =-'Aset Moneter'!L53 -> 11260.468 | BB29: =0-AY29 -> -11260.468 | BE29: =-'Aset Moneter'!M53 -> 10682.966 | BH29: =0-BE29 -> -10682.966 | BK29: =-'Aset Moneter'!N53 -> 7392.9116 | BN29: =0-BK29 -> -7392.9116
B30: f. Perak | C30: =-'Aset Moneter'!D63 -> 250.22465 | F30: =0-C30 -> -250.22465 | I30: =-'Aset Moneter'!E63 -> 334.54615 | L30: =0-I30 -> -334.54615 | O30: =-'Aset Moneter'!F63 -> 385.03321 | R30: =0-O30 -> -385.03321 | U30: =-'Aset Moneter'!G63 -> 571.09266 | X30: =0-U30 -> -571.09266 | AA30: =-'Aset Moneter'!H63 -> 400.903 | AD30: =0-AA30 -> -400.903 | AG30: =-'Aset Moneter'!I63 -> 189.63674 | AJ30: =0-AG30 -> -189.63674 | AM30: =-'Aset Moneter'!J63 -> 154.80963 | AP30: =0-AM30 -> -154.80963 | AS30: =-'Aset Moneter'!K63 -> 194.87779 | AV30: =0-AS30 -> -194.87779 | AY30: =-'Aset Moneter'!L63 -> 144.34519 | BB30: =0-AY30 -> -144.34519 | BE30: =-'Aset Moneter'!M63 -> 38.460002 | BH30: =0-BE30 -> -38.460002 | BK30: =-'Aset Moneter'!N63 -> 97.735409 | BN30: =0-BK30 -> -97.735409
B31: g. Tembaga | C31: =-'Aset Moneter'!D73 -> 11086.795 | F31: =0-C31 -> -11086.795 | I31: =-'Aset Moneter'!E73 -> 6631.2044 | L31: =0-I31 -> -6631.2044 | O31: =-'Aset Moneter'!F73 -> 6970.8953 | R31: =0-O31 -> -6970.8953 | U31: =-'Aset Moneter'!G73 -> 7788.1186 | X31: =0-U31 -> -7788.1186 | AA31: =-'Aset Moneter'!H73 -> 7258.6491 | AD31: =0-AA31 -> -7258.6491 | AG31: =-'Aset Moneter'!I73 -> 4866.3659 | AJ31: =0-AG31 -> -4866.3659 | AM31: =-'Aset Moneter'!J73 -> 10871.394 | AP31: =0-AM31 -> -10871.394 | AS31: =-'Aset Moneter'!K73 -> 28116.166 | AV31: =0-AS31 -> -28116.166 | AY31: =-'Aset Moneter'!L73 -> 66743.604 | BB31: =0-AY31 -> -66743.604 | BE31: =-'Aset Moneter'!M73 -> 68937.059 | BH31: =0-BE31 -> -68937.059 | BK31: =-'Aset Moneter'!N73 -> 81347.171 | BN31: =0-BK31 -> -81347.171
B32: h. Timah | C32: =-'Aset Moneter'!D83 -> 11714.077 | F32: =0-C32 -> -11714.077 | I32: =-'Aset Moneter'!E83 -> 7263.6783 | L32: =0-I32 -> -7263.6783 | O32: =-'Aset Moneter'!F83 -> 5407.5495 | R32: =0-O32 -> -5407.5495 | U32: =-'Aset Moneter'!G83 -> 7830.3711 | X32: =0-U32 -> -7830.3711 | AA32: =-'Aset Moneter'!H83 -> 6773.7646 | AD32: =0-AA32 -> -6773.7646 | AG32: =-'Aset Moneter'!I83 -> 3994.7881 | AJ32: =0-AG32 -> -3994.7881 | AM32: =-'Aset Moneter'!J83 -> 3417.0025 | AP32: =0-AM32 -> -3417.0025 | AS32: =-'Aset Moneter'!K83 -> 3599.1709 | AV32: =0-AS32 -> -3599.1709 | AY32: =-'Aset Moneter'!L83 -> 8616.7529 | BB32: =0-AY32 -> -8616.7529 | BE32: =-'Aset Moneter'!M83 -> 17415.351 | BH32: =0-BE32 -> -17415.351 | BK32: =-'Aset Moneter'!N83 -> 13740.702 | BN32: =0-BK32 -> -13740.702
B33: i. Nikel | C33: =-'Aset Moneter'!D93 -> 672.84247 | F33: =0-C33 -> -672.84247 | I33: =-'Aset Moneter'!E93 -> 405.97464 | L33: =0-I33 -> -405.97464 | O33: =-'Aset Moneter'!F93 -> 713.28495 | R33: =0-O33 -> -713.28495 | U33: =-'Aset Moneter'!G93 -> 1253.0937 | X33: =0-U33 -> -1253.0937 | AA33: =-'Aset Moneter'!H93 -> 1547.1992 | AD33: =0-AA33 -> -1547.1992 | AG33: =-'Aset Moneter'!I93 -> 844.89467 | AJ33: =0-AG33 -> -844.89467 | AM33: =-'Aset Moneter'!J93 -> 2044.0283 | AP33: =0-AM33 -> -2044.0283 | AS33: =-'Aset Moneter'!K93 -> 4341.6139 | AV33: =0-AS33 -> -4341.6139 | AY33: =-'Aset Moneter'!L93 -> 6415.4283 | BB33: =0-AY33 -> -6415.4283 | BE33: =-'Aset Moneter'!M93 -> 11822.489 | BH33: =0-BE33 -> -11822.489 | BK33: =-'Aset Moneter'!N93 -> 12341.886 | BN33: =0-BK33 -> -12341.886
